Workbook

Sheet PL-CPL
A1: No | B1: Kode PL | C1: Profil Lulusan (PL) | F1: No | G1: Kode CPL | H1: Deskripsi CPL | I1: Kategori | K1: CPL/PL | L1: PL01 | M1: PL02 | N1: PL03 | O1: PL04 | P1: PL05 | Q1: PL06
A2: 1 | B2: PL01 | C2: Lulusan memiliki kemampuan pengembangan, implementasi, evaluasi, mengintegrasikan solusi berbasis komputasi yang sesuai dengan perkembangan teknologi informasi cerdas untuk mendukung layanan publik dan ekonomi digital | F2: 1 | G2: CPL01 | H2: Mampu bekerja secara mandiri ataupun dalam tim, serta menunjukkan sikap profesional dan etis dalam menjalankan tugas dan tanggung jawab untuk menyelesaikan proyek-proyek terkait teknologi informasi cerdas dalam pengembangan layanan publik dan ekonomi digital | I2: Sikap (S) | K2: CPL01 | M2: V
A3: 2 | B3: PL02 | C3: Lulusan memiliki kemampuan membangun dan diseminasi pengetahuan, merencanakan, bekerjasama, memimpin, berpikir kritis, kreatif, komunikasi dan interpersonal yang baik serta berkontribusi dalam peningkatan mutu kehidupan bermasyarakat, berbangsa dan bernegara berdasarkan Pancasila untuk mendukung layanan publik dan ekonomi digital | F3: 2 | G3: CPL02 | H3: Mampu mengembangkan kemampuan berkomunikasi lisan secara efektif, berpikir kritis, kreatif, dan profesional serta dapat menghasilkan karya ilmiah yang orisinal dalam menyelesaikan permasalahan terkait teknologi informasi cerdas melalui pemanfaatan penelitian teknologi informasi dengan berbagai pihak terkait. | K3: CPL02 | M3: V
A4: 3 | B4: PL03 | C4: Lulusan memiliki kemampuan menganalisis dan mengevaluasi penerapan teknologi informasi termasuk sistem basis data, keamanan informasi, manajemen proyek pada layanan publik dan ekonomi digital | F4: 3 | G4: CPL03 | H4: Memiliki kemampuan menganalisis, mengevaluasi, dan membuat keputusan berdasarkan pengetahuan di bidang teknologi informasi cerdas dalam konteks dukungan terhadap pengembangan layanan publik dan ekonomi digital | I4: Keterampilan Umum (KU) | K4: CPL03 | L4: V | P4: V
A5: 4 | B5: PL04 | C5: Lulusan memiliki kemampuan mengembangkan teknologi informasi cerdas, mengkaji isu-isu teknologi dan pengembangan dan pelaksanaan rencana strategis | F5: 4 | G5: CPL04 | H5: Mampu mengevaluasi, membuat kesimpulan, dan membuat keputusan berdasarkan pengetahuan teknologi informasi khususnya teknologi informasi cerdas terbaru berkaitan dengan manajemen pengembangan layanan publik dan ekonomi digital | K5: CPL04 | O5: V | P5: V
A6: 5 | B6: PL05 | C6: Lulusan mampu mengidentifikasi, menganalisis, meneliti literatur, mengevaluasi, dan memformulasi solusi-solusi algoritmik untuk masalah komputasi yang kompleks, dengan menggunakan prinsip matematika, komputasi, dan disiplin ilmu yang relevan. | D6: Kompetensi Utama bidang Informatika | F6: 5 | G6: CPL05 | H6: Memiliki kemampuan menganalisa, mengevaluasi, dan membuat keputusan berbasis kinerja solusi komputasi cerdas untuk mendukung layanan publik dan ekonomi digital | I6: Keterampilan Khusus (KK) | K6: CPL05 | N6: V | P6: V | Q6: V
A7: 6 | B7: PL06 | C7: Lulusan mampu memodelkan sistem yang kompleks dan membangun solusi berbasis komputasi yang efektif dan efisien. | D7: Kompetensi Utama bidang Informatika | F7: 6 | G7: CPL06 | H7: Memiliki pemahaman yang mendalam, menganalisis, dan mengevaluasi tentang solusi komputasi cerdas dengan sistem dan infrastruktur yang ada termasuk pertimbangan keamanan sistem informasi untuk mendukung layanan publik dan ekonomi digital | K7: CPL06 | N7: V | P7: V | Q7: V
F8: 7 | G8: CPL07 | H8: Mampu menganalisis, mengembangkan, dan mengevaluasi kebutuhan sistem antarmuka pengguna yang efektif dan memahami kebutuhan serta preferensi pengguna dalam pengembangan teknologi informasi berbasis komputasi cerdas untuk mendukung layanan publik dan ekonomi digital. | I8: Pengetahuan (P) | K8: CPL07 | L8: V | P8: V
F9: 8 | G9: CPL08 | H9: Mampu mengevaluasi, mengembangkan dan mengimplementasikan solusi komputasi cerdas dengan menggunakan teknologi terkini dalam mendukung pengembangan kota cerdas dan sistem pemerintahan berbasis elektronik | K9: CPL08 | O9: V | P9: V | Q9: V
F10: 9 | G10: CPL09 | H10: Mampu mengidentifikasi, menganalisis, meneliti literatur, mengevaluasi, dan memformulasi solusi-solusi algoritmik untuk masalah computing yang kompleks | I10: Kompetensi Utama (KT) | K10: CPL09 | P10: V
F11: 10 | G11: CPL10 | H11: Mampu menerapkan prinsip-prinsip matematika, computing, dan disiplin ilmu yang relevan untuk merumuskan solusi bagi persoalan computing yang kompleks | K11: CPL10 | P11: V | Q11: V
F12: 11 | G12: CPL11 | H12: Mampu memodelkan sistem yang kompleks dan membangun solusi berbasis computing yang efektif dan efisien | K12: CPL11 | Q12: V
A16: Kode | B16: Kategori / Sumber | C16: Deskripsi | F16: No | G16: Kode CPL Prodi | H16: Deskripsi CPL Prodi | I16: Kategori | J16: Kode Utama | K16: Kode Turunan | L16: Sumber
A17: SIKAP | F17: 1 | G17: CPL01 | H17: Mampu bekerja secara mandiri ataupun dalam tim, serta menunjukkan sikap profesional dan etis dalam menjalankan tugas dan tanggung jawab untuk menyelesaikan proyek-proyek terkait teknologi informasi cerdas dalam pengembangan layanan publik dan ekonomi digital | I17: Sikap (S) | J17: S6, S9, S10 | K17: S1, S2, S3, S4, S5, S7, S8 | L17: SNDIKTI
A18: S1 | B18: SNDIKTI | C18: Bertakwa kepada Tuhan Yang Maha Esa dan mampu menunjukkan sikap religius. | F18: 2 | G18: CPL02 | H18: Mampu mengembangkan kemampuan berkomunikasi lisan secara efektif, berpikir kritis, kreatif, dan profesional serta dapat menghasilkan karya ilmiah yang orisinal dalam menyelesaikan permasalahan terkait teknologi informasi cerdas melalui pemanfaatan penelitian teknologi informasi dengan berbagai pihak terkait. | I18: Keterampilan Umum (KU) | J18: KU1, KU3, KU4, KU6 | K18: KU2, KU8, KU9 | L18: SNDIKTI
A19: S2 | C19: Menjunjung tinggi nilai kemanusiaan dalam menjalankan tugas berdasarkan agama,moral, dan etika. | F19: 3 | G19: CPL03 | H19: Memiliki kemampuan menganalisis, mengevaluasi, dan membuat keputusan berdasarkan pengetahuan di bidang teknologi informasi cerdas dalam konteks dukungan terhadap pengembangan layanan publik dan ekonomi digital | I19: Keterampilan Umum (KU) | J19: KU1, KU5 | K19: KU2, KU6, KU7, KU8 | L19: SNDIKTI
A20: S3 | C20: Berkontribusi dalam peningkatan mutu kehidupan bermasyarakat, berbangsa, ernegara, dan kemajuan peradaban berdasarkan Pancasila. | F20: 4 | G20: CPL04 | H20: Mampu mengevaluasi, membuat kesimpulan, dan membuat keputusan berdasarkan pengetahuan teknologi informasi khususnya teknologi informasi cerdas terbaru berkaitan dengan manajemen pengembangan layanan publik dan ekonomi digital | I20: Keterampilan Khusus (KK) | J20: KK1, KK6 | K20: KU5 | L20: IT2017, Seoul Accord, SNDIKTI
A21: S4 | C21: Berperan sebagai warga negara yang bangga dan cinta tanah air, memiliki asionalisme serta rasa tanggungjawab pada negara dan bangsa. | F21: 5 | G21: CPL05 | H21: Memiliki kemampuan menganalisis, mengevaluasi, dan membuat keputusan berbasis kinerja solusi komputasi cerdas untuk mendukung layanan publik dan ekonomi digital | I21: Keterampilan Khusus (KK) | J21: KK1, KK5 | K21: KK7, KU5 | L21: IT2017, CC2020, SNDIKTI
A22: S5 | C22: Menghargai keanekaragaman budaya, pandangan, agama, dan kepercayaan, serta pendapat atau temuan orisinal orang lain. | F22: 6 | G22: CPL06 | H22: Memiliki pemahaman yang mendalam, menganalisis, dan mengevaluasi tentang solusi komputasi cerdas dengan sistem dan infrastruktur yang ada termasuk pertimbangan keamanan sistem informasi untuk mendukung layanan publik dan ekonomi digital | I22: Pengetahuan (P) | J22: P3, P5, P6 | K22: KK2, KK3, KU9 | L22: IT2017, Seoul Accord, CC2020, SNDIKTI
A23: S6 | C23: Bekerja sama dan memiliki kepekaan sosial serta kepedulian terhadap masyarakat dan lingkungan. | F23: 7 | G23: CPL07 | H23: Mampu menganalisis, mengembangkan, dan mengevaluasi kebutuhan sistem antarmuka pengguna yang efektif dan memahami kebutuhan serta preferensi pengguna dalam pengembangan teknologi informasi berbasis komputasi cerdas untuk mendukung layanan publik dan ekonomi digital | I23: Pengetahuan (P) | J23: P2, P7 | K23: KK4, KU3, KU6 | L23: IT2017, Seoul Accord, CC2020, SNDIKTI
A24: S7 | C24: Taat hukum dan disiplin dalam kehidupan bermasyarakat dan bernegara. | F24: 8 | G24: CPL08 | H24: Mampu mengevaluasi, mengembangkan dan mengimplementasikan solusi komputasi cerdas dengan menggunakan teknologi terkini dalam mendukung pengembangan kota cerdas dan sistem pemerintahan berbasis elektronik | I24: Pengetahuan (P) | J24: KK2, KK6, P4 | K24: P5, KU5, KU8 | L24: IT2017, Seoul Accord, SNDIKTI
A25: S8 | C25: Menginternalisasi nilai, norma, dan etika akademik. | F25: 9 | G25: CPL09 | H25: Mampu mengidentifikasi, menganalisis, meneliti literatur, mengevaluasi, dan memformulasi solusi-solusi algoritmik untuk masalah computing yang kompleks | I25: Kompetensi Utama (KT) | J25: P2, P7 | K25: KU1, KU3, KU9 | L25: IT2017, Seoul Accord, SNDIKTI
A26: S9 | C26: Menunjukan sikap bertanggungjawab atas pekerjaan di bidang keahliannya secara mandiri. | F26: 10 | G26: CPL10 | H26: Mampu menerapkan prinsip-prinsip matematika, computing, dan disiplin ilmu yang relevan untuk merumuskan solusi bagi persoalan computing yang kompleks | I26: Kompetensi Utama (KT) | J26: P1, P4 | K26: KU5 | L26: IT2017, Seoul Accord, SNDIKTI
A27: S10 | C27: Menginternalisasi semangat kemandirian, kejuangan dan kewirausahaan. | F27: 11 | G27: CPL11 | H27: Mampu memodelkan sistem yang kompleks dan membangun solusi berbasis computing yang efektif dan efisien | I27: Kompetensi Utama (KT) | J27: KK5, KK6 | K27: P3, P6 | L27: CC2020, Seoul Accord, IT2017
A28: Ketrampilan Umum
A29: KU1 | B29: SNDIKTI | C29: Mampu menerapkan pemikiran logis, kritis, sistematis, dan inovatif dalam konteks pengembangan atau implementasi ilmu pengetahuan dan teknologi yang emperhatikan dan menerapkan nilai humaniora yang sesuai dengan bidang keahliannya.
A30: KU2 | C30: Mampu menunjukan kinerja mandiri, bermutu, dan terukur.
A31: KU3 | C31: Mampu mengkaji implikasi pengembangan atau implementasi ilmu pengetahuan teknologi yang memperhatikan dan menerapkan nilai humaniora sesuai dengan keahliannya berdasarkan kaidah, tata cara dan etika ilmiah dalam rangka menghasilkan solusi, gagasan, desain atau kritik seni.
A32: KU4 | C32: Menyusun deskripsi saintifik hasil kajian tersebut di atas dalam bentuk skripsi atau laporan tugas akhir, dan mengunggahnya dalam laman perguruan tinggi.
A33: KU5 | C33: Mampu mengambil keputusan secara tepat dalam konteks penyelesaian masalah di bidang keahliannya, berdasarkan hasil analisis informasi dan data.
A34: KU6 | C34: Mampu memelihara dan mengembangkan jaringan kerja dengan pembimbing, kolega, sejawat baik di dalam maupun di luar lembaganya.
A35: KU7 | C35: Mampu bertanggungjawab atas pencapaian hasil kerja kelompok dan melakukan supervisi dan evaluasi terhadap penyelesaian pekerjaan yang ditugaskan kepada pekerja yang berada di bawah tanggungjawabnya.
A36: KU8 | C36: mampu melakukan proses evaluasi diri terhadap kelompok kerja yang berada dibawah tanggung jawabnya, dan mampumengelola pembelajaran secara mandiri.
A37: KU9 | C37: Mampu mendokumentasikan, menyimpan, mengamankan, dan menemukan kembali data untuk menjamin kesahihan dan mencegah plagiasi.
A38: Pengetahuan
A39: P1 | B39: IT2017, | C39: Mempunyai pengetahuan matematika, komputasi, dan ilmu pengetahuan lain yang relevan untuk menyelesaikan permasalahan komputasi yang kompleks dengan pendekatan teknologi informasi.
B40: Seoul Accord
A41: P2 | B41: IT2017, | C41: Mampu menganalisis, mengidentifikasi, dan mendefinisikan permasalahan komputasi yang kompleks, dan memberikan pendekatan teknologi informasi sebagai solusi penyelesaian permasalah tersebut.
B42: Seoul Accord
A43: P3 | B43: IT2017, | C43: Mampu mengembangkan solusi permasalahan komputasi yang kompleks dan memberikan pendekatan teknologi informasi sebagai solusi penyelesaian permasalahan tersebut.
...

Sheet CPL-BK
A1: No | B1: Kode BK | C1: Bahan Kajian | D1: Deskripsi | E1: Kategori | F1: Referensi | H1: No | I1: Kode CPL | J1: Deskripsi CPL | K1: Kategori | M1: CPL/BK | N1: CPL01 | O1: CPL02 | P1: CPL03 | Q1: CPL04 | R1: CPL05 | S1: CPL06 | T1: CPL07 | U1: CPL08 | V1: CPL09 | W1: CPL10 | X1: CPL11 | Y1: Total
A2: 1 | B2: BK01 | C2: Skalabilitas dan Analitik Data | D2: Bahan kajian ini membahas tentang analitik data, yang mencakup beberapa topik seperti teknologi utama yang digunakan dalam mengumpulkan, membersihkan, memanipulasi, menyimpan, menganalisis, memvisualisasikan, dan mengekstraksi informasi berguna dari kumpulan data yang besar dan beragam, algoritma penambangan data dan pembelajaran mesin untuk menganalisis sekumpulan besar data terstruktur dan tidak terstruktur, serta tantangan analitik data skalabilitas data | E2: Penciri Pendukung | F2: IT-2017 | H2: 1 | I2: CPL01 | J2: Mampu bekerja secara mandiri ataupun dalam tim, serta menunjukkan sikap profesional dan etis dalam menjalankan tugas dan tanggung jawab untuk menyelesaikan proyek-proyek terkait teknologi informasi cerdas dalam pengembangan layanan publik dan ekonomi digital | K2: Sikap (S) | M2: BK01 | R2: v | V2: V | W2: V | Y2: =COUNTIF(N2:X2,"v") -> 3
A3: 2 | B3: BK02 | C3: Prinsip-prinsip Keamanan Siber | D3: Bahan kajian ini membahas tentang disiplin berbasis computing yang melibatkan teknologi, manusia, informasi, dan proses untuk memungkinkan operasi yang terjamin. Terdapat fokus pada implementasi, operasi, analisis, dan pengujian keamanan teknologi computing. Selain itu, juga terdapat pembahasan mengenai pengakuan sifat interdisipliner dari penerapan cybersecurity termasuk aspek hukum, kebijakan, faktor manusia, etika, dan manajemen risiko dalam konteks musuh. Praktik untuk memastikan informasi dan mengelola risiko yang terkait dengan penggunaan, pemrosesan, penyimpanan, dan pengiriman informasi atau data serta sistem dan proses yang digunakan untuk tujuan tersebut juga turut dibahas. Tindakan yang melindungi dan mempertahankan informasi dan sistem informasi dengan memastikan ketersediaannya juga menjadi topik yang dibahas. | E3: Penciri Pendukung | F3: IT-2017 | H3: 2 | I3: CPL02 | J3: Mampu mengembangkan kemampuan berkomunikasi lisan secara efektif, berpikir kritis, kreatif, dan profesional serta dapat menghasilkan karya ilmiah yang orisinal dalam menyelesaikan permasalahan terkait teknologi informasi cerdas melalui pemanfaatan penelitian teknologi informasi dengan berbagai pihak terkait. | M3: BK02 | S3: v | V3: V | W3: V | Y3: =COUNTIF(N3:X3,"v") -> 3
A4: 3 | B4: BK03 | C4: Manajemen Data dan Informasi | D4: Bahan kajian ini membahas tentang alat dan teknik untuk pemodelan, pengumpulan, pengorganisasian, pengambilan, dan pengelolaan data yang efisien, mengekstrak informasi dari data untuk membuat data bermakna bagi organisasi. Selain itu melakukan mengembangkan, menyebarkan, mengelola, dan mengintegrasikan sistem data dan informasi untuk mendukung organisasi serta memberikan solusi dari masalah keselamatan dan keamanan yang terkait dengan data dan informasi. Pembahasan mengenai alat dan teknik untuk menghasilkan pengetahuan yang bermanfaat dari informasi. | E4: Penciri Utama | F4: IT-2017 | H4: 3 | I4: CPL03 | J4: Memiliki kemampuan menganalisis, mengevaluasi, dan membuat keputusan berdasarkan pengetahuan di bidang teknologi informasi cerdas dalam konteks dukungan terhadap pengembangan layanan publik dan ekonomi digital | K4: Keterampilan Umum (KU) | M4: BK03 | P4: v | Q4: v | X4: V | Y4: =COUNTIF(N4:X4,"v") -> 3
A5: 4 | B5: BK04 | C5: Desain User Experience | D5: Bahan kajian ini membahas tentang pengembangan aplikasi dan sistem TI dengan fokus pada pengguna, yang mencakup pemahaman desain bagi pengguna, pengembangan pola pikir yang mengakui pentingnya pengguna, metodologi berpusat pada pengguna, penerapan kriteria evaluasi dan standar, serta analisis pengguna dan tugas, faktor manusia, ergonomi, aksesibilitas standar, desain pengalaman, dan psikologi kognitif. | E5: Penciri Utama | F5: IT-2017 | H5: 4 | I5: CPL04 | J5: Mampu mengevaluasi, membuat kesimpulan, dan membuat keputusan berdasarkan pengetahuan teknologi informasi khususnya teknologi informasi cerdas terbaru berkaitan dengan manajemen pengembangan layanan publik dan ekonomi digital | M5: BK04 | T5: v | X5: V | Y5: =COUNTIF(N5:X5,"v") -> 2
A6: 5 | B6: BK05 | C6: Pengembangan dan Manajemen Perangkat Lunak | D6: Bahan kajian ini mencakup model proses implementasi perangkat lunak dan manajemen proyek perangkat lunak yang meliputi analisis, desain dan konstruksi, pengujian, penyebaran, operasi, dan pemeliharaan, PMBOK dan siklus hidup proyek, elemen utama manajemen untuk tim proyek kecil, aspek-aspek manajerial dalam tim proyek kecil, pengembangan dan implementasi rencana pengukuran proses perangkat lunak, serta kerja efektif dengan anggota tim lainnya dalam kegiatan manajemen proyek. | E6: Penciri Pendukung | F6: IT-2017, CC-2020 | H6: 5 | I6: CPL05 | J6: Memiliki kemampuan menganalisa, mengevaluasi, dan membuat keputusan berbasis kinerja solusi komputasi cerdas untuk mendukung layanan publik dan ekonomi digital | K6: Keterampilan Khusus (KK) | M6: BK05 | U6: v | X6: V | Y6: =COUNTIF(N6:X6,"v") -> 2
A7: 6 | B7: BK06 | C7: Pengembangan E-Goverment berbasis Teknologi Informasi | D7: Bahan kajian ini mencakup Konsep dan Teori e-Government,Manajemen Proyek dan Implementasi e-Government, Arsitektur dan Infrastruktur e-Government, Kebijakan dan Regulasi e-Government, Keamanan Informasi dan Privasi Data, Analisis Data dan Business Intelligence, Partisipasi Publik dan Layanan e-Government | E7: Penciri Utama | F7: CC-2020, IT-2017 | H7: 6 | I7: CPL06 | J7: Memiliki pemahaman yang mendalam, menganalisis, dan mengevaluasi tentang solusi komputasi cerdas dengan sistem dan infrastruktur yang ada termasuk pertimbangan keamanan sistem informasi untuk mendukung layanan publik dan ekonomi digital | M7: BK06 | S7: v | U7: v | W7: V | X7: V | Y7: =COUNTIF(N7:X7,"v") -> 4
A8: 7 | B8: BK07 | C8: Ekonomi Digital | D8: Pengantar FinTech, Big Data Analytics in Finance, Cybersecurity in Finance, Cybersecurity in Finance | E8: Penciri Utama | F8: CC-2020, IT-2017 | H8: 7 | I8: CPL07 | J8: Mampu menganalisis, mengembangkan, dan mengevaluasi kebutuhan sistem antarmuka pengguna yang efektif dan memahami kebutuhan serta preferensi pengguna dalam pengembangan teknologi informasi berbasis komputasi cerdas untuk mendukung layanan publik dan ekonomi digital. | K8: Pengetahuan (P) | M8: BK07 | R8: v | V8: V | Y8: =COUNTIF(N8:X8,"v") -> 2
A9: 8 | B9: BK08 | C9: Praktek Profesional Global | D9: Bahan kajian ini membahas pentingnya mengidentifikasi dan memahami keterampilan penting yang diperlukan untuk karier yang sukses dalam industri, termasuk keterampilan komunikasi lisan dan tertulis profesional. mengidentifikasikan cara kerja tim terintegrasi di seluruh TI dan cara TI mendukung organisasi serta konteks sosial dan profesional teknologi informasi dan computing, dan kepatuhan terhadap kode etik perilaku. | E9: Penciri Pendukung | F9: IT-2017 | H9: 8 | I9: CPL08 | J9: Mampu mengevaluasi, mengembangkan dan mengimplementasikan solusi komputasi cerdas dengan menggunakan teknologi terkini dalam mendukung pengembangan kota cerdas dan sistem pemerintahan berbasis elektronik | M9: BK08 | N9: v | O9: v | V9: V | Y9: =COUNTIF(N9:X9,"v") -> 3
A10: 9 | B10: BK09 | C10: Penelitian dan Pengembangan | D10: Bahan kajian ini memberikan peluang kepada mahasiswa untuk berlatih melakukan penelitian dan pengembangan melalui penugasan proyek. Metode Penelitian dan pengembangan teknologi informasi bertujuan mengoptimalkan penggunaan komputer dan alat digital lain untuk mengumpulkan, menganalisis, memproses data, dan membuat laporan dalam bentuk tesis. Implementasi penelitian dan pengembangan meliputi problem solving, survei, eksperimen, dan observasi. | E10: Penciri Pendukung | F10: Permen Ristek DIKTI no. 44/2015 | H10: 9 | I10: CPL09 | J10: Mampu mengidentifikasi, menganalisis, meneliti literatur, mengevaluasi, dan memformulasi solusi-solusi algoritmik untuk masalah computing yang kompleks | K10: Kompetensi Utama (KT) | M10: BK09 | O10: v | X10: V | Y10: =COUNTIF(N10:X10,"v") -> 2
H11: 10 | I11: CPL10 | J11: Mampu menerapkan prinsip-prinsip matematika, computing, dan disiplin ilmu yang relevan untuk merumuskan solusi bagi persoalan computing yang kompleks | M11: Total | N11: =COUNTIF(N2:N10, "V") -> 1 | O11: =COUNTIF(O2:O10, "V") -> 2 | P11: =COUNTIF(P2:P10, "V") -> 1 | Q11: =COUNTIF(Q2:Q10, "V") -> 1 | R11: =COUNTIF(R2:R10, "V") -> 2 | S11: =COUNTIF(S2:S10, "V") -> 2 | T11: =COUNTIF(T2:T10, "V") -> 1 | U11: =COUNTIF(U2:U10, "V") -> 2 | ... X11: =COUNTIF(X2:X10, "V") -> 5
H12: 11 | I12: CPL11 | J12: Mampu memodelkan sistem yang kompleks dan membangun solusi berbasis computing yang efektif dan efisien

Sheet BK-MK
A1: Kode MK | B1: Nama MK | D1: No | E1: Kode BK | F1: Bahan Kajian | H1: KODE MK | I1: NAMA MK | J1: BK01 | K1: BK02 | L1: BK03 | M1: BK04 | N1: BK05 | O1: BK06 | P1: BK07 | Q1: BK08 | R1: BK09
A2: P.24.01.85.1.01 | B2: MATRIKULASI | D2: 1 | E2: BK01 | F2: Skalabilitas dan Analitik Data | H2: P.24.01.85.1.02 | I2: PERMODELAN STATISTIK UNTUK BISNIS | J2: V
A3: P.24.01.85.1.02 | B3: PERMODELAN STATISTIK UNTUK BISNIS | D3: 2 | E3: BK02 | F3: Prinsip-prinsip Keamanan Siber | H3: P.24.01.85.1.03 | I3: MESIN PEMBELAJARAN UNTUK BISNIS | J3: V | N3: V
A4: P.24.01.85.1.03 | B4: MESIN PEMBELAJARAN UNTUK BISNIS | D4: 3 | E4: BK03 | F4: Manajemen Data dan Informasi | H4: P.24.01.85.1.04 | I4: ANALISIS DATA BESAR | J4: V | N4: V
A5: P.24.01.85.1.04 | B5: ANALISIS DATA BESAR | D5: 4 | E5: BK04 | F5: Desain User Experience | H5: P.24.01.85.1.05 | I5: MANAJEMEN STRATEGIS SISTEM INFORMASI | L5: V | N5: V
A6: P.24.01.85.1.05 | B6: MANAJEMEN STRATEGIS SISTEM INFORMASI | D6: 5 | E6: BK05 | F6: Pengembangan dan Manajemen Perangkat Lunak | H6: P.24.01.85.1.06 | I6: REKAYASA PERANGKAT LUNAK LANJUT | N6: V | R6: V
A7: P.24.01.85.1.06 | B7: REKAYASA PERANGKAT LUNAK LANJUT | D7: 6 | E7: BK06 | F7: Pengembangan E-Goverment berbasis Teknologi Informasi | H7: P.24.01.85.2.07 | I7: METODOLOGI PENELITIAN DAN PENULISAN ILMIAH | R7: V
A8: P.24.01.85.2.07 | B8: METODOLOGI PENELITIAN DAN PENULISAN ILMIAH | D8: 7 | E8: BK07 | F8: Ekonomi Digital | H8: P.24.01.85.2.08 | I8: REKAYASA KEBUTUHAN SISTEM | N8: V | O8: V
A9: P.24.01.85.2.08 | B9: REKAYASA KEBUTUHAN SISTEM | D9: 8 | E9: BK08 | F9: Praktek Profesional Global | H9: P.24.01.85.2.09 | I9: INTERAKSI MANUSIA DAN KOMPUTER | L9: V | M9: V
A10: P.24.01.85.2.09 | B10: INTERAKSI MANUSIA DAN KOMPUTER | D10: 9 | E10: BK09 | F10: Penelitian dan Pengembangan | H10: P.24.01.85.2.10 | I10: KEAMANAN SIBER | K10: V
A11: P.24.01.85.2.10 | B11: KEAMANAN SIBER | H11: P.24.01.85.2.11 | I11: SISTEM PENDUKUNG KEPUTUSAN CERDAS | J11: V
A12: P.24.01.85.2.11 | B12: SISTEM PENDUKUNG KEPUTUSAN CERDAS | H12: P.24.01.85.3.12 | I12: ARSITEKTUR ENTERPRISE UNTUK TEKNOLOGI INFORMASI | M12: V
A13: P.24.01.85.3.12 | B13: ARSITEKTUR ENTERPRISE UNTUK TEKNOLOGI INFORMASI | H13: P.24.01.85.3.13 | I13: TESIS | Q13: V | R13: V
A14: P.24.01.85.3.13 | B14: TESIS | I14: Pilihan 1 - Teknologi Keuangan ( FinTech )
B15: Pilihan 1 - Teknologi Keuangan ( FinTech ) | H15: P.24.01.85.3.14 | I15: TEKNOLOGI KEUANGAN ( FINTECH ) DAN RESIKO | P15: V
A16: P.24.01.85.3.14 | B16: TEKNOLOGI KEUANGAN ( FINTECH ) DAN RESIKO | H16: P.24.01.85.3.15 | I16: KECERDASAN BISNIS | L16: V
A17: P.24.01.85.3.15 | B17: KECERDASAN BISNIS | H17: P.24.01.85.3.16 | I17: TATA KELOLA DAN AUDIT BISNIS DIGITAL | K17: V | L17: V
A18: P.24.01.85.3.16 | B18: TATA KELOLA DAN AUDIT BISNIS DIGITAL | I18: Pilihan 2 - Layanan Publik
B19: Pilihan 2 - Layanan Publik | H19: P.24.01.85.3.17 | I19: SISTEM PEMERINTAHAN BERBASIS ELEKTRONIK | K19: V | O19: V
A20: P.24.01.85.3.17 | B20: SISTEM PEMERINTAHAN BERBASIS ELEKTRONIK | H20: P.24.01.85.3.18 | I20: MANAJEMEN PROYEK TEKNOLOGI INFORMASI | J20: V | O20: V
A21: P.24.01.85.3.18 | B21: MANAJEMEN PROYEK TEKNOLOGI INFORMASI | H21: P.24.01.85.3.19 | I21: KOTA CERDAS | J21: V | L21: V
A22: P.24.01.85.3.19 | B22: KOTA CERDAS | H22: P.24.01.85.4.20 | I22: PUBLIKASI | Q22: V | R22: V
A23: P.24.01.85.4.20 | B23: PUBLIKASI | H23: P.24.01.85.4.21 | I23: STRATEGI TEKNOPRENEURSHIP DAN INOVASI DIGITAL | Q23: V
A24: P.24.01.85.4.21 | B24: STRATEGI TEKNOPRENEURSHIP DAN INOVASI DIGITAL

Sheet CPL-MK
A1: Kode MK | B1: Nama MK | D1: No | E1: Kode CPL | F1: Deskripsi CPL | G1: Kategori | I1: KODE MK | J1: NAMA MK | K1: CPL01 | L1: CPL02 | M1: CPL03 | N1: CPL04 | O1: CPL05 | P1: CPL06 | Q1: CPL07 | R1: CPL08 | S1: CPL09 | T1: CPL10 | U1: CPL11
A2: P.24.01.85.1.01 | B2: MATRIKULASI | D2: 1 | E2: CPL01 | F2: Mampu bekerja secara mandiri ataupun dalam tim, serta menunjukkan sikap profesional dan etis dalam menjalankan tugas dan tanggung jawab untuk menyelesaikan proyek-proyek terkait teknologi informasi cerdas dalam pengembangan layanan publik dan ekonomi digital | G2: Sikap (S) | I2: P.24.01.85.1.02 | J2: PERMODELAN STATISTIK UNTUK BISNIS | O2: A | T2: A | V2: =COUNTIF(K2:U2,"A") -> 2 | W2: =(V2/$V$25) -> 0.040816327
A3: P.24.01.85.1.02 | B3: PERMODELAN STATISTIK UNTUK BISNIS | D3: 2 | E3: CPL02 | F3: Mampu mengembangkan kemampuan berkomunikasi lisan secara efektif, berpikir kritis, kreatif, dan profesional serta dapat menghasilkan karya ilmiah yang orisinal dalam menyelesaikan permasalahan terkait teknologi informasi cerdas melalui pemanfaatan penelitian teknologi informasi dengan berbagai pihak terkait. | I3: P.24.01.85.1.03 | J3: MESIN PEMBELAJARAN UNTUK BISNIS | O3: A | T3: A | V3: =COUNTIF(K3:U3,"A") -> 2 | W3: =(V3/$V$25) -> 0.040816327
A4: P.24.01.85.1.03 | B4: MESIN PEMBELAJARAN UNTUK BISNIS | D4: 3 | E4: CPL03 | F4: Memiliki kemampuan menganalisis, mengevaluasi, dan membuat keputusan berdasarkan pengetahuan di bidang teknologi informasi cerdas dalam konteks dukungan terhadap pengembangan layanan publik dan ekonomi digital | G4: Keterampilan Umum (KU) | I4: P.24.01.85.1.04 | J4: ANALISIS DATA BESAR | O4: A | T4: A | V4: =COUNTIF(K4:U4,"A") -> 2 | W4: =(V4/$V$25) -> 0.040816327
A5: P.24.01.85.1.04 | B5: ANALISIS DATA BESAR | D5: 4 | E5: CPL04 | F5: Mampu mengevaluasi, membuat kesimpulan, dan membuat keputusan berdasarkan pengetahuan teknologi informasi khususnya teknologi informasi cerdas terbaru berkaitan dengan manajemen pengembangan layanan publik dan ekonomi digital | I5: P.24.01.85.1.05 | J5: MANAJEMEN STRATEGIS SISTEM INFORMASI | M5: A | N5: A | U5: A | V5: =COUNTIF(K5:U5,"A") -> 3 | W5: =(V5/$V$25) -> 0.06122449
A6: P.24.01.85.1.05 | B6: MANAJEMEN STRATEGIS SISTEM INFORMASI | D6: 5 | E6: CPL05 | F6: Memiliki kemampuan menganalisa, mengevaluasi, dan membuat keputusan berbasis kinerja solusi komputasi cerdas untuk mendukung layanan publik dan ekonomi digital | G6: Keterampilan Khusus (KK) | I6: P.24.01.85.1.06 | J6: REKAYASA PERANGKAT LUNAK LANJUT | R6: A | U6: A | V6: =COUNTIF(K6:U6,"A") -> 2 | W6: =(V6/$V$25) -> 0.040816327
A7: P.24.01.85.1.06 | B7: REKAYASA PERANGKAT LUNAK LANJUT | D7: 6 | E7: CPL06 | F7: Memiliki pemahaman yang mendalam, menganalisis, dan mengevaluasi tentang solusi komputasi cerdas dengan sistem dan infrastruktur yang ada termasuk pertimbangan keamanan sistem informasi untuk mendukung layanan publik dan ekonomi digital | I7: P.24.01.85.2.07 | J7: METODOLOGI PENELITIAN DAN PENULISAN ILMIAH | M7: A | U7: A | V7: =COUNTIF(K7:U7,"A") -> 2 | W7: =(V7/$V$25) -> 0.040816327
A8: P.24.01.85.2.07 | B8: METODOLOGI PENELITIAN DAN PENULISAN ILMIAH | D8: 7 | E8: CPL07 | F8: Mampu menganalisis, mengembangkan, dan mengevaluasi kebutuhan sistem antarmuka pengguna yang efektif dan memahami kebutuhan serta preferensi pengguna dalam pengembangan teknologi informasi berbasis komputasi cerdas untuk mendukung layanan publik dan ekonomi digital. | G8: Pengetahuan (P) | I8: P.24.01.85.2.08 | J8: REKAYASA KEBUTUHAN SISTEM | P8: A | R8: A | U8: A | V8: =COUNTIF(K8:U8,"A") -> 3 | W8: =(V8/$V$25) -> 0.06122449
A9: P.24.01.85.2.08 | B9: REKAYASA KEBUTUHAN SISTEM | D9: 8 | E9: CPL08 | F9: Mampu mengevaluasi, mengembangkan dan mengimplementasikan solusi komputasi cerdas dengan menggunakan teknologi terkini dalam mendukung pengembangan kota cerdas dan sistem pemerintahan berbasis elektronik | I9: P.24.01.85.2.09 | J9: INTERAKSI MANUSIA DAN KOMPUTER | Q9: A | U9: A | V9: =COUNTIF(K9:U9,"A") -> 2 | W9: =(V9/$V$25) -> 0.040816327
A10: P.24.01.85.2.09 | B10: INTERAKSI MANUSIA DAN KOMPUTER | D10: 9 | E10: CPL09 | F10: Mampu mengidentifikasi, menganalisis, meneliti literatur, mengevaluasi, dan memformulasi solusi-solusi algoritmik untuk masalah computing yang kompleks | G10: Kompetensi Utama (KT) | I10: P.24.01.85.2.10 | J10: KEAMANAN SIBER | P10: A | T10: A | V10: =COUNTIF(K10:U10,"A") -> 2 | W10: =(V10/$V$25) -> 0.040816327
A11: P.24.01.85.2.10 | B11: KEAMANAN SIBER | D11: 10 | E11: CPL10 | F11: Mampu menerapkan prinsip-prinsip matematika, computing, dan disiplin ilmu yang relevan untuk merumuskan solusi bagi persoalan computing yang kompleks | I11: P.24.01.85.2.11 | J11: SISTEM PENDUKUNG KEPUTUSAN CERDAS | O11: A | T11: A | V11: =COUNTIF(K11:U11,"A") -> 2 | W11: =(V11/$V$25) -> 0.040816327
A12: P.24.01.85.2.11 | B12: SISTEM PENDUKUNG KEPUTUSAN CERDAS | D12: 11 | E12: CPL11 | F12: Mampu memodelkan sistem yang kompleks dan membangun solusi berbasis computing yang efektif dan efisien | I12: P.24.01.85.3.12 | J12: ARSITEKTUR ENTERPRISE UNTUK TEKNOLOGI INFORMASI | Q12: A | U12: A | V12: =COUNTIF(K12:U12,"A") -> 2 | W12: =(V12/$V$25) -> 0.040816327
A13: P.24.01.85.3.12 | B13: ARSITEKTUR ENTERPRISE UNTUK TEKNOLOGI INFORMASI | I13: P.24.01.85.3.13 | J13: TESIS | K13: A | L13: A | S13: A | U13: A | V13: =COUNTIF(K13:U13,"A") -> 4 | W13: =(V13/$V$25) -> 0.081632653
A14: P.24.01.85.3.13 | B14: TESIS | J14: Pilihan 1 - Teknologi Keuangan ( FinTech ) | V14: =COUNTIF(K14:U14,"A") -> 0 | W14: =(V14/$V$25) -> 0
B15: Pilihan 1 - Teknologi Keuangan ( FinTech ) | I15: P.24.01.85.3.14 | J15: TEKNOLOGI KEUANGAN ( FINTECH ) DAN RESIKO | O15: A | S15: A | V15: =COUNTIF(K15:U15,"A") -> 2 | W15: =(V15/$V$25) -> 0.040816327
A16: P.24.01.85.3.14 | B16: TEKNOLOGI KEUANGAN ( FINTECH ) DAN RESIKO | I16: P.24.01.85.3.15 | J16: KECERDASAN BISNIS | M16: A | U16: A | V16: =COUNTIF(K16:U16,"A") -> 2 | W16: =(V16/$V$25) -> 0.040816327
A17: P.24.01.85.3.15 | B17: KECERDASAN BISNIS | I17: P.24.01.85.3.16 | J17: TATA KELOLA DAN AUDIT BISNIS DIGITAL | M17: A | P17: A | S17: A | V17: =COUNTIF(K17:U17,"A") -> 3 | W17: =(V17/$V$25) -> 0.06122449
A18: P.24.01.85.3.16 | B18: TATA KELOLA DAN AUDIT BISNIS DIGITAL | J18: Pilihan 2 - Layanan Publik | V18: =COUNTIF(K18:U18,"A") -> 0 | W18: =(V18/$V$25) -> 0
B19: Pilihan 2 - Layanan Publik | I19: P.24.01.85.3.17 | J19: SISTEM PEMERINTAHAN BERBASIS ELEKTRONIK | R19: A | S19: A | T19: A | U19: A | V19: =COUNTIF(K19:U19,"A") -> 4 | W19: =(V19/$V$25) -> 0.081632653
A20: P.24.01.85.3.17 | B20: SISTEM PEMERINTAHAN BERBASIS ELEKTRONIK | I20: P.24.01.85.3.18 | J20: MANAJEMEN PROYEK TEKNOLOGI INFORMASI | O20: A | P20: A | S20: A | V20: =COUNTIF(K20:U20,"A") -> 3 | W20: =(V20/$V$25) -> 0.06122449
A21: P.24.01.85.3.18 | B21: MANAJEMEN PROYEK TEKNOLOGI INFORMASI | I21: P.24.01.85.3.19 | J21: KOTA CERDAS | M21: A | S21: A | V21: =COUNTIF(K21:U21,"A") -> 2 | W21: =(V21/$V$25) -> 0.040816327
A22: P.24.01.85.3.19 | B22: KOTA CERDAS | I22: P.24.01.85.4.20 | J22: PUBLIKASI | K22: A | L22: A | S22: A | V22: =COUNTIF(K22:U22,"A") -> 3 | W22: =(V22/$V$25) -> 0.06122449
A23: P.24.01.85.4.20 | B23: PUBLIKASI | I23: P.24.01.85.4.21 | J23: STRATEGI TEKNOPRENEURSHIP DAN INOVASI DIGITAL | K23: A | L23: A | V23: =COUNTIF(K23:U23,"A") -> 2 | W23: =(V23/$V$25) -> 0.040816327
A24: P.24.01.85.4.21 | B24: STRATEGI TEKNOPRENEURSHIP DAN INOVASI DIGITAL | K24: =COUNTIF(K2:K23,"A") -> 3 | L24: =COUNTIF(L2:L23,"A") -> 3 | M24: =COUNTIF(M2:M23,"A") -> 5 | N24: =COUNTIF(N2:N23,"A") -> 1 | O24: =COUNTIF(O2:O23,"A") -> 6 | P24: =COUNTIF(P2:P23,"A") -> 4 | Q24: =COUNTIF(Q2:Q23,"A") -> 2 | R24: =COUNTIF(R2:R23,"A") -> 3 | ... U24: =COUNTIF(U2:U23,"A") -> 9
U25: =SUM(K24:U24) -> 49 | V25: =SUM(V2:V23) -> 49
K26: =(K24/$U$25) -> 0.06122449 | L26: =(L24/$U$25) -> 0.06122449 | M26: =(M24/$U$25) -> 0.10204082 | N26: =(N24/$U$25) -> 0.020408163 | O26: =(O24/$U$25) -> 0.12244898 | P26: =(P24/$U$25) -> 0.081632653 | Q26: =(Q24/$U$25) -> 0.040816327 | R26: =(R24/$U$25) -> 0.06122449 | ... U26: =(U24/$U$25) -> 0.18367347
U27: =SUM(K26:U26) -> 1

Sheet CPL-MK-BK
A1: Kode MK | B1: Nama MK | D1: No | E1: Kode CPL | F1: Deskripsi CPL | G1: Kategori | I1: No | J1: Kode BK | K1: Bahan Kajian | M1: Kode BK | N1: CPL01 | O1: CPL02 | P1: CPL03 | Q1: CPL04 | R1: CPL05 | S1: CPL06 | T1: CPL07 | U1: CPL08 | V1: CPL09 | W1: CPL10 | X1: CPL11 | Z1: Kode BK | AA1: CPL01 | AB1: CPL02 | AC1: CPL03 | AD1: CPL04 | AE1: CPL05 | AF1: CPL06 | AG1: CPL07 | AH1: CPL08 | AI1: CPL09 | AJ1: CPL10 | AK1: CPL11
A2: P.24.01.85.1.01 | B2: MATRIKULASI | D2: 1 | E2: CPL01 | F2: Mampu bekerja secara mandiri ataupun dalam tim, serta menunjukkan sikap profesional dan etis dalam menjalankan tugas dan tanggung jawab untuk menyelesaikan proyek-proyek terkait teknologi informasi cerdas dalam pengembangan layanan publik dan ekonomi digital | G2: Sikap (S) | I2: 1 | J2: BK01 | K2: Skalabilitas dan Analitik Data | M2: BK01 | R2: P.24.01.85.1.02; | W2: P.24.01.85.1.02 | Z2: BK01 | AE2: =VLOOKUP(R2,$A$2:$B$24,2) -> PERMODELAN STATISTIK UNTUK BISNIS | AI2: =VLOOKUP(V2,$A$2:$B$24,2) -> #N/A | AJ2: =VLOOKUP(W2,$A$2:$B$24,2) -> PERMODELAN STATISTIK UNTUK BISNIS
A3: P.24.01.85.1.02 | B3: PERMODELAN STATISTIK UNTUK BISNIS | D3: 2 | E3: CPL02 | F3: Mampu mengembangkan kemampuan berkomunikasi lisan secara efektif, berpikir kritis, kreatif, dan profesional serta dapat menghasilkan karya ilmiah yang orisinal dalam menyelesaikan permasalahan terkait teknologi informasi cerdas melalui pemanfaatan penelitian teknologi informasi dengan berbagai pihak terkait. | I3: 2 | J3: BK02 | K3: Prinsip-prinsip Keamanan Siber | R3: P.24.01.85.1.03 | W3: P.24.01.85.1.03 | AE3: =VLOOKUP(R3,$A$2:$B$24,2) -> MESIN PEMBELAJARAN UNTUK BISNIS | AH3: =VLOOKUP(U3,$A$2:$B$24,2) -> #N/A | AI3: =VLOOKUP(V3,$A$2:$B$24,2) -> #N/A | AJ3: =VLOOKUP(W3,$A$2:$B$24,2) -> MESIN PEMBELAJARAN UNTUK BISNIS | AK3: =VLOOKUP(X3,$A$2:$B$24,2) -> #N/A
A4: P.24.01.85.1.03 | B4: MESIN PEMBELAJARAN UNTUK BISNIS | D4: 3 | E4: CPL03 | F4: Memiliki kemampuan menganalisis, mengevaluasi, dan membuat keputusan berdasarkan pengetahuan di bidang teknologi informasi cerdas dalam konteks dukungan terhadap pengembangan layanan publik dan ekonomi digital | G4: Keterampilan Umum (KU) | I4: 3 | J4: BK03 | K4: Manajemen Data dan Informasi | R4: P.24.01.85.1.04 | W4: P.24.01.85.1.04 | AE4: =VLOOKUP(R4,$A$2:$B$24,2) -> ANALISIS DATA BESAR | AH4: =VLOOKUP(U4,$A$2:$B$24,2) -> #N/A | AI4: =VLOOKUP(V4,$A$2:$B$24,2) -> #N/A | AJ4: =VLOOKUP(W4,$A$2:$B$24,2) -> ANALISIS DATA BESAR | AK4: =VLOOKUP(X4,$A$2:$B$24,2) -> #N/A
A5: P.24.01.85.1.04 | B5: ANALISIS DATA BESAR | D5: 4 | E5: CPL04 | F5: Mampu mengevaluasi, membuat kesimpulan, dan membuat keputusan berdasarkan pengetahuan teknologi informasi khususnya teknologi informasi cerdas terbaru berkaitan dengan manajemen pengembangan layanan publik dan ekonomi digital | I5: 4 | J5: BK04 | K5: Desain User Experience | R5: P.24.01.85.2.11 | W5: P.24.01.85.2.11 | AE5: =VLOOKUP(R5,$A$2:$B$24,2) -> SISTEM PENDUKUNG KEPUTUSAN CERDAS | AI5: =VLOOKUP(V5,$A$2:$B$24,2) -> #N/A | AJ5: =VLOOKUP(W5,$A$2:$B$24,2) -> SISTEM PENDUKUNG KEPUTUSAN CERDAS
A6: P.24.01.85.1.05 | B6: MANAJEMEN STRATEGIS SISTEM INFORMASI | D6: 5 | E6: CPL05 | F6: Memiliki kemampuan menganalisa, mengevaluasi, dan membuat keputusan berbasis kinerja solusi komputasi cerdas untuk mendukung layanan publik dan ekonomi digital | G6: Keterampilan Khusus (KK) | I6: 5 | J6: BK05 | K6: Pengembangan dan Manajemen Perangkat Lunak | U6: P.24.01.85.3.18 | V6: P.24.01.85.3.18 | W6: P.24.01.85.3.18 | X6: P.24.01.85.3.18 | AE6: =VLOOKUP(R6,$A$2:$B$24,2) -> #N/A | AF6: =VLOOKUP(S6,$A$2:$B$24,2) -> #N/A | AH6: =VLOOKUP(U6,$A$2:$B$24,2) -> MANAJEMEN PROYEK TEKNOLOGI INFORMASI | AI6: =VLOOKUP(V6,$A$2:$B$24,2) -> MANAJEMEN PROYEK TEKNOLOGI INFORMASI | AJ6: =VLOOKUP(W6,$A$2:$B$24,2) -> MANAJEMEN PROYEK TEKNOLOGI INFORMASI | AK6: =VLOOKUP(X6,$A$2:$B$24,2) -> MANAJEMEN PROYEK TEKNOLOGI INFORMASI
A7: P.24.01.85.1.06 | B7: REKAYASA PERANGKAT LUNAK LANJUT | D7: 6 | E7: CPL06 | F7: Memiliki pemahaman yang mendalam, menganalisis, dan mengevaluasi tentang solusi komputasi cerdas dengan sistem dan infrastruktur yang ada termasuk pertimbangan keamanan sistem informasi untuk mendukung layanan publik dan ekonomi digital | I7: 6 | J7: BK06 | K7: Pengembangan E-Goverment berbasis Teknologi Informasi | P7: P.24.01.85.3.19 | V7: P.24.01.85.3.19 | AC7: =VLOOKUP(P7,$A$2:$B$24,2) -> KOTA CERDAS | AD7: =VLOOKUP(Q7,$A$2:$B$24,2) -> #N/A | AE7: =VLOOKUP(R7,$A$2:$B$24,2) -> #N/A | AI7: =VLOOKUP(V7,$A$2:$B$24,2) -> KOTA CERDAS | AJ7: =VLOOKUP(W7,$A$2:$B$24,2) -> #N/A | AK7: =VLOOKUP(X7,$A$2:$B$24,2) -> #N/A
A8: P.24.01.85.2.07 | B8: METODOLOGI PENELITIAN DAN PENULISAN ILMIAH | D8: 7 | E8: CPL07 | F8: Mampu menganalisis, mengembangkan, dan mengevaluasi kebutuhan sistem antarmuka pengguna yang efektif dan memahami kebutuhan serta preferensi pengguna dalam pengembangan teknologi informasi berbasis komputasi cerdas untuk mendukung layanan publik dan ekonomi digital. | G8: Pengetahuan (P) | I8: 7 | J8: BK07 | K8: Ekonomi Digital | M8: BK02 | S8: P.24.01.85.2.10 | W8: P.24.01.85.2.10 | Z8: BK02 | AF8: =VLOOKUP(S8,$A$2:$B$24,2) -> KEAMANAN SIBER | AI8: =VLOOKUP(V8,$A$2:$B$24,2) -> #N/A | AJ8: =VLOOKUP(W8,$A$2:$B$24,2) -> KEAMANAN SIBER
A9: P.24.01.85.2.08 | B9: REKAYASA KEBUTUHAN SISTEM | D9: 8 | E9: CPL08 | F9: Mampu mengevaluasi, mengembangkan dan mengimplementasikan solusi komputasi cerdas dengan menggunakan teknologi terkini dalam mendukung pengembangan kota cerdas dan sistem pemerintahan berbasis elektronik | I9: 8 | J9: BK08 | K9: Praktek Profesional Global | P9: P.24.01.85.3.16 | S9: P.24.01.85.3.16 | V9: P.24.01.85.3.16 | AC9: =VLOOKUP(P9,$A$2:$B$24,2) -> TATA KELOLA DAN AUDIT BISNIS DIGITAL | AD9: =VLOOKUP(Q9,$A$2:$B$24,2) -> #N/A | AF9: =VLOOKUP(S9,$A$2:$B$24,2) -> TATA KELOLA DAN AUDIT BISNIS DIGITAL | AI9: =VLOOKUP(V9,$A$2:$B$24,2) -> TATA KELOLA DAN AUDIT BISNIS DIGITAL | AJ9: =VLOOKUP(W9,$A$2:$B$24,2) -> #N/A | AK9: =VLOOKUP(X9,$A$2:$B$24,2) -> #N/A
B10: INTERAKSI MANUSIA DAN KOMPUTER | D10: 9 | E10: CPL09 | F10: Mampu mengidentifikasi, menganalisis, meneliti literatur, mengevaluasi, dan memformulasi solusi-solusi algoritmik untuk masalah computing yang kompleks | G10: Kompetensi Utama (KT) | I10: 9 | J10: BK09 | K10: Penelitian dan Pengembangan | U10: P.24.01.85.3.17 | V10: P.24.01.85.3.17 | W10: P.24.01.85.3.17 | X10: P.24.01.85.3.17 | AF10: =VLOOKUP(S10,$A$2:$B$24,2) -> #N/A | AH10: =VLOOKUP(U10,$A$2:$B$24,2) -> SISTEM PEMERINTAHAN BERBASIS ELEKTRONIK | AI10: =VLOOKUP(V10,$A$2:$B$24,2) -> SISTEM PEMERINTAHAN BERBASIS ELEKTRONIK | AJ10: =VLOOKUP(W10,$A$2:$B$24,2) -> SISTEM PEMERINTAHAN BERBASIS ELEKTRONIK | AK10: =VLOOKUP(X10,$A$2:$B$24,2) -> SISTEM PEMERINTAHAN BERBASIS ELEKTRONIK
A11: P.24.01.85.2.10 | B11: KEAMANAN SIBER | D11: 10 | E11: CPL10 | F11: Mampu menerapkan prinsip-prinsip matematika, computing, dan disiplin ilmu yang relevan untuk merumuskan solusi bagi persoalan computing yang kompleks | M11: BK03 | P11: P.24.01.85.1.05 | Q11: P.24.01.85.1.05 | X11: P.24.01.85.1.05 | Z11: BK03 | AC11: =VLOOKUP(P11,$A$2:$B$24,2) -> MANAJEMEN STRATEGIS SISTEM INFORMASI | AD11: =VLOOKUP(Q11,$A$2:$B$24,2) -> MANAJEMEN STRATEGIS SISTEM INFORMASI | AH11: =VLOOKUP(U11,$A$2:$B$24,2) -> #N/A | AK11: =VLOOKUP(X11,$A$2:$B$24,2) -> MANAJEMEN STRATEGIS SISTEM INFORMASI
A12: P.24.01.85.2.11 | B12: SISTEM PENDUKUNG KEPUTUSAN CERDAS | D12: 11 | E12: CPL11 | F12: Mampu memodelkan sistem yang kompleks dan membangun solusi berbasis computing yang efektif dan efisien | T12: P.24.01.85.2.09 | X12: P.24.01.85.2.09 | AC12: =VLOOKUP(P12,$A$2:$B$24,2) -> #N/A | AD12: =VLOOKUP(Q12,$A$2:$B$24,2) -> #N/A | AG12: =VLOOKUP(T12,$A$2:$B$24,2) -> INTERAKSI MANUSIA DAN KOMPUTER | AK12: =VLOOKUP(X12,$A$2:$B$24,2) -> INTERAKSI MANUSIA DAN KOMPUTER
A13: P.24.01.85.3.12 | B13: ARSITEKTUR ENTERPRISE UNTUK TEKNOLOGI INFORMASI | P13: P.24.01.85.3.15 | X13: P.24.01.85.3.15 | AC13: =VLOOKUP(P13,$A$2:$B$24,2) -> KECERDASAN BISNIS | AD13: =VLOOKUP(Q13,$A$2:$B$24,2) -> #N/A | AK13: =VLOOKUP(X13,$A$2:$B$24,2) -> KECERDASAN BISNIS
A14: P.24.01.85.3.13 | B14: TESIS | P14: P.24.01.85.3.16 | S14: P.24.01.85.3.16 | V14: P.24.01.85.3.16 | AC14: =VLOOKUP(P14,$A$2:$B$24,2) -> TATA KELOLA DAN AUDIT BISNIS DIGITAL | AD14: =VLOOKUP(Q14,$A$2:$B$24,2) -> #N/A | AF14: =VLOOKUP(S14,$A$2:$B$24,2) -> TATA KELOLA DAN AUDIT BISNIS DIGITAL | AI14: =VLOOKUP(V14,$A$2:$B$24,2) -> TATA KELOLA DAN AUDIT BISNIS DIGITAL | AJ14: =VLOOKUP(W14,$A$2:$B$24,2) -> #N/A | AK14: =VLOOKUP(X14,$A$2:$B$24,2) -> #N/A
B15: Pilihan 1 - Teknologi Keuangan ( FinTech ) | P15: P.24.01.85.3.19 | V15: P.24.01.85.3.19 | AC15: =VLOOKUP(P15,$A$2:$B$24,2) -> KOTA CERDAS | AD15: =VLOOKUP(Q15,$A$2:$B$24,2) -> #N/A | AE15: =VLOOKUP(R15,$A$2:$B$24,2) -> #N/A | AI15: =VLOOKUP(V15,$A$2:$B$24,2) -> KOTA CERDAS | AJ15: =VLOOKUP(W15,$A$2:$B$24,2) -> #N/A | AK15: =VLOOKUP(X15,$A$2:$B$24,2) -> #N/A
A16: P.24.01.85.3.14 | B16: TEKNOLOGI KEUANGAN ( FINTECH ) DAN RESIKO | M16: BK04 | T16: P.24.01.85.2.09 | X16: P.24.01.85.2.09 | Z16: BK04 | AC16: =VLOOKUP(P16,$A$2:$B$24,2) -> #N/A | AD16: =VLOOKUP(Q16,$A$2:$B$24,2) -> #N/A | AG16: =VLOOKUP(T16,$A$2:$B$24,2) -> INTERAKSI MANUSIA DAN KOMPUTER | AK16: =VLOOKUP(X16,$A$2:$B$24,2) -> INTERAKSI MANUSIA DAN KOMPUTER
A17: P.24.01.85.3.15 | B17: KECERDASAN BISNIS | T17: P.24.01.85.3.12 | X17: P.24.01.85.3.12 | AG17: =VLOOKUP(T17,$A$2:$B$24,2) -> ARSITEKTUR ENTERPRISE UNTUK TEKNOLOGI INFORMASI | AK17: =VLOOKUP(X17,$A$2:$B$24,2) -> ARSITEKTUR ENTERPRISE UNTUK TEKNOLOGI INFORMASI
A18: P.24.01.85.3.16 | B18: TATA KELOLA DAN AUDIT BISNIS DIGITAL | M18: BK05 | R18: P.24.01.85.1.03 | W18: P.24.01.85.1.03 | Z18: BK05 | AE18: =VLOOKUP(R18,$A$2:$B$24,2) -> MESIN PEMBELAJARAN UNTUK BISNIS | AH18: =VLOOKUP(U18,$A$2:$B$24,2) -> #N/A | AI18: =VLOOKUP(V18,$A$2:$B$24,2) -> #N/A | AJ18: =VLOOKUP(W18,$A$2:$B$24,2) -> MESIN PEMBELAJARAN UNTUK BISNIS | AK18: =VLOOKUP(X18,$A$2:$B$24,2) -> #N/A
B19: Pilihan 2 - Layanan Publik | R19: P.24.01.85.1.04 | W19: P.24.01.85.1.04 | AE19: =VLOOKUP(R19,$A$2:$B$24,2) -> ANALISIS DATA BESAR | AH19: =VLOOKUP(U19,$A$2:$B$24,2) -> #N/A | AI19: =VLOOKUP(V19,$A$2:$B$24,2) -> #N/A | AJ19: =VLOOKUP(W19,$A$2:$B$24,2) -> ANALISIS DATA BESAR | AK19: =VLOOKUP(X19,$A$2:$B$24,2) -> #N/A
A20: P.24.01.85.3.17 | B20: SISTEM PEMERINTAHAN BERBASIS ELEKTRONIK | P20: P.24.01.85.1.05 | Q20: P.24.01.85.1.05 | X20: P.24.01.85.1.05 | AC20: =VLOOKUP(P20,$A$2:$B$24,2) -> MANAJEMEN STRATEGIS SISTEM INFORMASI | AD20: =VLOOKUP(Q20,$A$2:$B$24,2) -> MANAJEMEN STRATEGIS SISTEM INFORMASI | AH20: =VLOOKUP(U20,$A$2:$B$24,2) -> #N/A | AK20: =VLOOKUP(X20,$A$2:$B$24,2) -> MANAJEMEN STRATEGIS SISTEM INFORMASI
A21: P.24.01.85.3.18 | B21: MANAJEMEN PROYEK TEKNOLOGI INFORMASI | U21: P.24.01.85.1.06 | X21: P.24.01.85.1.06 | AB21: =VLOOKUP(O21,$A$2:$B$24,2) -> #N/A | AH21: =VLOOKUP(U21,$A$2:$B$24,2) -> REKAYASA PERANGKAT LUNAK LANJUT | AK21: =VLOOKUP(X21,$A$2:$B$24,2) -> REKAYASA PERANGKAT LUNAK LANJUT
A22: P.24.01.85.3.19 | B22: KOTA CERDAS | S22: P.24.01.85.2.08 | U22: P.24.01.85.2.08 | X22: P.24.01.85.2.08 | AF22: =VLOOKUP(S22,$A$2:$B$24,2) -> INTERAKSI MANUSIA DAN KOMPUTER | AH22: =VLOOKUP(U22,$A$2:$B$24,2) -> INTERAKSI MANUSIA DAN KOMPUTER | AJ22: =VLOOKUP(W22,$A$2:$B$24,2) -> #N/A | AK22: =VLOOKUP(X22,$A$2:$B$24,2) -> INTERAKSI MANUSIA DAN KOMPUTER
A23: P.24.01.85.4.20 | B23: PUBLIKASI | M23: BK06 | S23: P.24.01.85.2.08 | U23: P.24.01.85.2.08 | X23: P.24.01.85.2.08 | Z23: BK06 | AF23: =VLOOKUP(S23,$A$2:$B$24,2) -> INTERAKSI MANUSIA DAN KOMPUTER | AH23: =VLOOKUP(U23,$A$2:$B$24,2) -> INTERAKSI MANUSIA DAN KOMPUTER | AJ23: =VLOOKUP(W23,$A$2:$B$24,2) -> #N/A | AK23: =VLOOKUP(X23,$A$2:$B$24,2) -> INTERAKSI MANUSIA DAN KOMPUTER
A24: P.24.01.85.4.21 | B24: STRATEGI TEKNOPRENEURSHIP DAN INOVASI DIGITAL | U24: P.24.01.85.3.17 | V24: P.24.01.85.3.17 | W24: P.24.01.85.3.17 | X24: P.24.01.85.3.17 | AF24: =VLOOKUP(S24,$A$2:$B$24,2) -> #N/A | AH24: =VLOOKUP(U24,$A$2:$B$24,2) -> SISTEM PEMERINTAHAN BERBASIS ELEKTRONIK | AI24: =VLOOKUP(V24,$A$2:$B$24,2) -> SISTEM PEMERINTAHAN BERBASIS ELEKTRONIK | AJ24: =VLOOKUP(W24,$A$2:$B$24,2) -> SISTEM PEMERINTAHAN BERBASIS ELEKTRONIK | AK24: =VLOOKUP(X24,$A$2:$B$24,2) -> SISTEM PEMERINTAHAN BERBASIS ELEKTRONIK
R25: P.24.01.85.3.18 | S25: P.24.01.85.3.18 | V25: P.24.01.85.3.18 | AE25: =VLOOKUP(R25,$A$2:$B$24,2) -> MANAJEMEN PROYEK TEKNOLOGI INFORMASI | AF25: =VLOOKUP(S25,$A$2:$B$24,2) -> MANAJEMEN PROYEK TEKNOLOGI INFORMASI | AH25: =VLOOKUP(U25,$A$2:$B$24,2) -> #N/A | AI25: =VLOOKUP(V25,$A$2:$B$24,2) -> MANAJEMEN PROYEK TEKNOLOGI INFORMASI | AJ25: =VLOOKUP(W25,$A$2:$B$24,2) -> #N/A | AK25: =VLOOKUP(X25,$A$2:$B$24,2) -> #N/A
M26: BK07 | R26: P.24.01.85.3.14 | V26: P.24.01.85.3.14 | Z26: BK07 | AE26: =VLOOKUP(R26,$A$2:$B$24,2) -> TEKNOLOGI KEUANGAN ( FINTECH ) DAN RESIKO | AI26: =VLOOKUP(V26,$A$2:$B$24,2) -> TEKNOLOGI KEUANGAN ( FINTECH ) DAN RESIKO
M27: BK08 | N27: P.24.01.85.3.13 | O27: P.24.01.85.3.13 | V27: P.24.01.85.3.13 | X27: P.24.01.85.3.13 | Z27: BK08 | AA27: =VLOOKUP(N27,$A$2:$B$24,2) -> TESIS | AB27: =VLOOKUP(O27,$A$2:$B$24,2) -> TESIS | AI27: =VLOOKUP(V27,$A$2:$B$24,2) -> TESIS | AK27: =VLOOKUP(X27,$A$2:$B$24,2) -> TESIS
N28: P.24.01.85.4.20 | O28: P.24.01.85.4.20 | V28: P.24.01.85.4.20 | AA28: =VLOOKUP(N28,$A$2:$B$24,2) -> PUBLIKASI | AB28: =VLOOKUP(O28,$A$2:$B$24,2) -> PUBLIKASI | AI28: =VLOOKUP(V28,$A$2:$B$24,2) -> PUBLIKASI | AK28: =VLOOKUP(X28,$A$2:$B$24,2) -> #N/A
N29: P.24.01.85.4.21 | O29: P.24.01.85.4.21 | AA29: =VLOOKUP(N29,$A$2:$B$24,2) -> STRATEGI TEKNOPRENEURSHIP DAN INOVASI DIGITAL | AB29: =VLOOKUP(O29,$A$2:$B$24,2) -> STRATEGI TEKNOPRENEURSHIP DAN INOVASI DIGITAL | AI29: =VLOOKUP(V29,$A$2:$B$24,2) -> #N/A
M30: BK09 | U30: P.24.01.85.1.06 | X30: P.24.01.85.1.06 | Z30: BK09 | AB30: =VLOOKUP(O30,$A$2:$B$24,2) -> #N/A | AH30: =VLOOKUP(U30,$A$2:$B$24,2) -> REKAYASA PERANGKAT LUNAK LANJUT | AK30: =VLOOKUP(X30,$A$2:$B$24,2) -> REKAYASA PERANGKAT LUNAK LANJUT
P31: P.24.01.85.2.07 | X31: P.24.01.85.2.07 | AC31: =VLOOKUP(P31,$A$2:$B$24,2) -> INTERAKSI MANUSIA DAN KOMPUTER | AK31: =VLOOKUP(X31,$A$2:$B$24,2) -> INTERAKSI MANUSIA DAN KOMPUTER
N32: P.24.01.85.3.13 | O32: P.24.01.85.3.13 | V32: P.24.01.85.3.13 | X32: P.24.01.85.3.13 | AA32: =VLOOKUP(N32,$A$2:$B$24,2) -> TESIS | AB32: =VLOOKUP(O32,$A$2:$B$24,2) -> TESIS | AI32: =VLOOKUP(V32,$A$2:$B$24,2) -> TESIS | AK32: =VLOOKUP(X32,$A$2:$B$24,2) -> TESIS
N33: P.24.01.85.4.20 | O33: P.24.01.85.4.20 | V33: P.24.01.85.4.20 | AA33: =VLOOKUP(N33,$A$2:$B$24,2) -> PUBLIKASI | AB33: =VLOOKUP(O33,$A$2:$B$24,2) -> PUBLIKASI | AI33: =VLOOKUP(V33,$A$2:$B$24,2) -> PUBLIKASI | AK33: =VLOOKUP(X33,$A$2:$B$24,2) -> #N/A

Sheet MK-SKS-SMTR
A1: Kode MK | B1: Nama MK | C1: SKS | D1: SMTR | E1: JML SKS | G1: Kode CPL | H1: CPL01 | I1: CPL02 | J1: CPL03 | K1: CPL04 | L1: CPL05 | M1: CPL06 | N1: CPL07 | O1: CPL08 | P1: CPL09 | Q1: CPL10 | R1: CPL11 | T1: Kode CPL | U1: CPL01 | V1: CPL02 | W1: CPL03 | X1: CPL04 | Y1: CPL05 | Z1: CPL06 | AA1: CPL07 | AB1: CPL08 | AC1: CPL09 | AD1: CPL10 | AE1: CPL11
A2: P.24.01.85.1.01 | B2: MATRIKULASI | C2: 0 | D2: 1 | E2: 15
A3: P.24.01.85.1.02 | B3: PERMODELAN STATISTIK UNTUK BISNIS | C3: 3 | G3: SMTR 1 | L3: P.24.01.85.1.02 | Q3: P.24.01.85.1.02 | T3: SMTR 1 | Y3: =VLOOKUP(L3,$A$2:$B$24,2) -> PERMODELAN STATISTIK UNTUK BISNIS | AC3: =VLOOKUP(P3,$A$2:$B$24,2) -> #N/A | AD3: =VLOOKUP(Q3,$A$2:$B$24,2) -> PERMODELAN STATISTIK UNTUK BISNIS
A4: P.24.01.85.1.03 | B4: MESIN PEMBELAJARAN UNTUK BISNIS | C4: 3 | L4: P.24.01.85.1.03 | Q4: P.24.01.85.1.03 | Y4: =VLOOKUP(L4,$A$2:$B$24,2) -> MESIN PEMBELAJARAN UNTUK BISNIS | AB4: =VLOOKUP(O4,$A$2:$B$24,2) -> #N/A | AC4: =VLOOKUP(P4,$A$2:$B$24,2) -> #N/A | AD4: =VLOOKUP(Q4,$A$2:$B$24,2) -> MESIN PEMBELAJARAN UNTUK BISNIS | AE4: =VLOOKUP(R4,$A$2:$B$24,2) -> #N/A
A5: P.24.01.85.1.04 | B5: ANALISIS DATA BESAR | C5: 3 | L5: P.24.01.85.1.04 | Q5: P.24.01.85.1.04 | Y5: =VLOOKUP(L5,$A$2:$B$24,2) -> ANALISIS DATA BESAR | AB5: =VLOOKUP(O5,$A$2:$B$24,2) -> #N/A | AC5: =VLOOKUP(P5,$A$2:$B$24,2) -> #N/A | AD5: =VLOOKUP(Q5,$A$2:$B$24,2) -> ANALISIS DATA BESAR | AE5: =VLOOKUP(R5,$A$2:$B$24,2) -> #N/A
A6: P.24.01.85.1.05 | B6: MANAJEMEN STRATEGIS SISTEM INFORMASI | C6: 3 | J6: P.24.01.85.1.05 | K6: P.24.01.85.1.05 | R6: P.24.01.85.1.05 | W6: =VLOOKUP(J6,$A$2:$B$24,2) -> MANAJEMEN STRATEGIS SISTEM INFORMASI | X6: =VLOOKUP(K6,$A$2:$B$24,2) -> MANAJEMEN STRATEGIS SISTEM INFORMASI | AB6: =VLOOKUP(O6,$A$2:$B$24,2) -> #N/A | AE6: =VLOOKUP(R6,$A$2:$B$24,2) -> MANAJEMEN STRATEGIS SISTEM INFORMASI
A7: P.24.01.85.1.06 | B7: REKAYASA PERANGKAT LUNAK LANJUT | C7: 3 | O7: P.24.01.85.1.06 | R7: P.24.01.85.1.06 | V7: =VLOOKUP(I7,$A$2:$B$24,2) -> #N/A | AB7: =VLOOKUP(O7,$A$2:$B$24,2) -> REKAYASA PERANGKAT LUNAK LANJUT | AE7: =VLOOKUP(R7,$A$2:$B$24,2) -> REKAYASA PERANGKAT LUNAK LANJUT
A8: P.24.01.85.2.07 | B8: METODOLOGI PENELITIAN DAN PENULISAN ILMIAH | C8: 3 | D8: 2 | E8: 15 | G8: SMTR 2 | J8: P.24.01.85.2.07 | R8: P.24.01.85.2.07 | T8: SMTR 2 | W8: =VLOOKUP(J8,$A$2:$B$24,2) -> METODOLOGI PENELITIAN DAN PENULISAN ILMIAH | AE8: =VLOOKUP(R8,$A$2:$B$24,2) -> METODOLOGI PENELITIAN DAN PENULISAN ILMIAH
A9: P.24.01.85.2.08 | B9: REKAYASA KEBUTUHAN SISTEM | C9: 3 | M9: P.24.01.85.2.08 | O9: P.24.01.85.2.08 | R9: P.24.01.85.2.08 | Z9: =VLOOKUP(M9,$A$2:$B$24,2) -> REKAYASA KEBUTUHAN SISTEM | AB9: =VLOOKUP(O9,$A$2:$B$24,2) -> REKAYASA KEBUTUHAN SISTEM | AD9: =VLOOKUP(Q9,$A$2:$B$24,2) -> #N/A | AE9: =VLOOKUP(R9,$A$2:$B$24,2) -> REKAYASA KEBUTUHAN SISTEM
A10: P.24.01.85.2.09 | B10: INTERAKSI MANUSIA DAN KOMPUTER | C10: 3 | N10: P.24.01.85.2.09 | R10: P.24.01.85.2.09 | W10: =VLOOKUP(J10,$A$2:$B$24,2) -> #N/A | X10: =VLOOKUP(K10,$A$2:$B$24,2) -> #N/A | AA10: =VLOOKUP(N10,$A$2:$B$24,2) -> INTERAKSI MANUSIA DAN KOMPUTER | AE10: =VLOOKUP(R10,$A$2:$B$24,2) -> INTERAKSI MANUSIA DAN KOMPUTER
A11: P.24.01.85.2.10 | B11: KEAMANAN SIBER | C11: 3 | M11: P.24.01.85.2.10 | Q11: P.24.01.85.2.10 | Z11: =VLOOKUP(M11,$A$2:$B$24,2) -> KEAMANAN SIBER | AC11: =VLOOKUP(P11,$A$2:$B$24,2) -> #N/A | AD11: =VLOOKUP(Q11,$A$2:$B$24,2) -> KEAMANAN SIBER
A12: P.24.01.85.2.11 | B12: SISTEM PENDUKUNG KEPUTUSAN CERDAS | C12: 3 | L12: P.24.01.85.2.11 | Q12: P.24.01.85.2.11 | Y12: =VLOOKUP(L12,$A$2:$B$24,2) -> SISTEM PENDUKUNG KEPUTUSAN CERDAS | AC12: =VLOOKUP(P12,$A$2:$B$24,2) -> #N/A | AD12: =VLOOKUP(Q12,$A$2:$B$24,2) -> SISTEM PENDUKUNG KEPUTUSAN CERDAS
A13: P.24.01.85.3.12 | B13: ARSITEKTUR ENTERPRISE UNTUK TEKNOLOGI INFORMASI | C13: 3 | D13: 3 | E13: 18 | G13: SMTR 3 | N13: P.24.01.85.3.12 | R13: P.24.01.85.3.12 | T13: SMTR 3 | AA13: =VLOOKUP(N13,$A$2:$B$24,2) -> ARSITEKTUR ENTERPRISE UNTUK TEKNOLOGI INFORMASI | AE13: =VLOOKUP(R13,$A$2:$B$24,2) -> ARSITEKTUR ENTERPRISE UNTUK TEKNOLOGI INFORMASI
A14: P.24.01.85.3.13 | B14: TESIS | C14: 6 | H14: P.24.01.85.3.13 | I14: P.24.01.85.3.13 | P14: P.24.01.85.3.13 | R14: P.24.01.85.3.13 | U14: =VLOOKUP(H14,$A$2:$B$24,2) -> TESIS | V14: =VLOOKUP(I14,$A$2:$B$24,2) -> TESIS | AC14: =VLOOKUP(P14,$A$2:$B$24,2) -> TESIS | AE14: =VLOOKUP(R14,$A$2:$B$24,2) -> TESIS
B15: Pilihan 1 - Teknologi Keuangan ( FinTech )
A16: P.24.01.85.3.14 | B16: TEKNOLOGI KEUANGAN ( FINTECH ) DAN RESIKO | C16: 3 | L16: P.24.01.85.3.14 | P16: P.24.01.85.3.14 | Y16: =VLOOKUP(L16,$A$2:$B$24,2) -> TEKNOLOGI KEUANGAN ( FINTECH ) DAN RESIKO | AC16: =VLOOKUP(P16,$A$2:$B$24,2) -> TEKNOLOGI KEUANGAN ( FINTECH ) DAN RESIKO
A17: P.24.01.85.3.15 | B17: KECERDASAN BISNIS | C17: 3 | J17: P.24.01.85.3.15 | R17: P.24.01.85.3.15 | W17: =VLOOKUP(J17,$A$2:$B$24,2) -> KECERDASAN BISNIS | X17: =VLOOKUP(K17,$A$2:$B$24,2) -> #N/A | AE17: =VLOOKUP(R17,$A$2:$B$24,2) -> KECERDASAN BISNIS
A18: P.24.01.85.3.16 | B18: TATA KELOLA DAN AUDIT BISNIS DIGITAL | C18: 3 | J18: P.24.01.85.3.16 | M18: P.24.01.85.3.16 | P18: P.24.01.85.3.16 | W18: =VLOOKUP(J18,$A$2:$B$24,2) -> TATA KELOLA DAN AUDIT BISNIS DIGITAL | X18: =VLOOKUP(K18,$A$2:$B$24,2) -> #N/A | Z18: =VLOOKUP(M18,$A$2:$B$24,2) -> TATA KELOLA DAN AUDIT BISNIS DIGITAL | AC18: =VLOOKUP(P18,$A$2:$B$24,2) -> TATA KELOLA DAN AUDIT BISNIS DIGITAL | AD18: =VLOOKUP(Q18,$A$2:$B$24,2) -> #N/A | AE18: =VLOOKUP(R18,$A$2:$B$24,2) -> #N/A
B19: Pilihan 2 - Layanan Publik
A20: P.24.01.85.3.17 | B20: SISTEM PEMERINTAHAN BERBASIS ELEKTRONIK | C20: 3 | O20: P.24.01.85.3.17 | P20: P.24.01.85.3.17 | Q20: P.24.01.85.3.17 | R20: P.24.01.85.3.17 | Z20: =VLOOKUP(M20,$A$2:$B$24,2) -> #N/A | AB20: =VLOOKUP(O20,$A$2:$B$24,2) -> SISTEM PEMERINTAHAN BERBASIS ELEKTRONIK | AC20: =VLOOKUP(P20,$A$2:$B$24,2) -> SISTEM PEMERINTAHAN BERBASIS ELEKTRONIK | AD20: =VLOOKUP(Q20,$A$2:$B$24,2) -> SISTEM PEMERINTAHAN BERBASIS ELEKTRONIK | AE20: =VLOOKUP(R20,$A$2:$B$24,2) -> SISTEM PEMERINTAHAN BERBASIS ELEKTRONIK
A21: P.24.01.85.3.18 | B21: MANAJEMEN PROYEK TEKNOLOGI INFORMASI | C21: 3 | L21: P.24.01.85.3.18 | M21: P.24.01.85.3.18 | P21: P.24.01.85.3.18 | Y21: =VLOOKUP(L21,$A$2:$B$24,2) -> MANAJEMEN PROYEK TEKNOLOGI INFORMASI | Z21: =VLOOKUP(M21,$A$2:$B$24,2) -> MANAJEMEN PROYEK TEKNOLOGI INFORMASI | AB21: =VLOOKUP(O21,$A$2:$B$24,2) -> #N/A | AC21: =VLOOKUP(P21,$A$2:$B$24,2) -> MANAJEMEN PROYEK TEKNOLOGI INFORMASI | AD21: =VLOOKUP(Q21,$A$2:$B$24,2) -> #N/A | AE21: =VLOOKUP(R21,$A$2:$B$24,2) -> #N/A
A22: P.24.01.85.3.19 | B22: KOTA CERDAS | C22: 3 | J22: P.24.01.85.3.19 | P22: P.24.01.85.3.19 | W22: =VLOOKUP(J22,$A$2:$B$24,2) -> KOTA CERDAS | X22: =VLOOKUP(K22,$A$2:$B$24,2) -> #N/A | Y22: =VLOOKUP(L22,$A$2:$B$24,2) -> #N/A | AC22: =VLOOKUP(P22,$A$2:$B$24,2) -> KOTA CERDAS | AD22: =VLOOKUP(Q22,$A$2:$B$24,2) -> #N/A | AE22: =VLOOKUP(R22,$A$2:$B$24,2) -> #N/A
A23: P.24.01.85.4.20 | B23: PUBLIKASI | C23: 4 | D23: 4 | E23: 6 | G23: SMTR 4 | H23: P.24.01.85.4.20 | I23: P.24.01.85.4.20 | P23: P.24.01.85.4.20 | T23: SMTR 4 | U23: =VLOOKUP(H23,$A$2:$B$24,2) -> PUBLIKASI | V23: =VLOOKUP(I23,$A$2:$B$24,2) -> PUBLIKASI | AC23: =VLOOKUP(P23,$A$2:$B$24,2) -> PUBLIKASI | AE23: =VLOOKUP(R23,$A$2:$B$24,2) -> #N/A
A24: P.24.01.85.4.21 | B24: STRATEGI TEKNOPRENEURSHIP DAN INOVASI DIGITAL | C24: 2 | H24: P.24.01.85.4.21 | I24: P.24.01.85.4.21 | U24: =VLOOKUP(H24,$A$2:$B$24,2) -> STRATEGI TEKNOPRENEURSHIP DAN INOVASI DIGITAL | V24: =VLOOKUP(I24,$A$2:$B$24,2) -> STRATEGI TEKNOPRENEURSHIP DAN INOVASI DIGITAL | AC24: =VLOOKUP(P24,$A$2:$B$24,2) -> #N/A
C25: =(SUM(C2:C24))-9 -> 54

Sheet PEMENUHAN MATA KULIAH
A1: Kode CPL | B1: SMTR 1 | G1: SMTR 2 | L1: SMTR 3 | V1: SMTR 4
A2: CPL01 | M2: TESIS | V2: PUBLIKASI | W2: STRATEGI TEKNOPRENEURSHIP DAN INOVASI DIGITAL
A3: CPL02 | M3: TESIS | V3: PUBLIKASI | W3: STRATEGI TEKNOPRENEURSHIP DAN INOVASI DIGITAL
A4: CPL03 | E4: MANAJEMEN STRATEGIS SISTEM INFORMASI | G4: METODOLOGI PENELITIAN DAN PENULISAN ILMIAH | P4: KECERDASAN BISNIS | Q4: TATA KELOLA DAN AUDIT BISNIS DIGITAL | U4: KOTA CERDAS
A5: CPL04 | E5: MANAJEMEN STRATEGIS SISTEM INFORMASI
A6: CPL05 | B6: PERMODELAN STATISTIK UNTUK BISNIS | C6: MESIN PEMBELAJARAN UNTUK BISNIS | D6: ANALISIS DATA BESAR | K6: SISTEM PENDUKUNG KEPUTUSAN CERDAS | O6: TEKNOLOGI KEUANGAN ( FINTECH ) DAN RESIKO | T6: MANAJEMEN PROYEK TEKNOLOGI INFORMASI
A7: CPL06 | H7: REKAYASA KEBUTUHAN SISTEM | J7: KEAMANAN SIBER | Q7: TATA KELOLA DAN AUDIT BISNIS DIGITAL | T7: MANAJEMEN PROYEK TEKNOLOGI INFORMASI
A8: CPL07 | I8: INTERAKSI MANUSIA DAN KOMPUTER | L8: ARSITEKTUR ENTERPRISE UNTUK TEKNOLOGI INFORMASI
A9: CPL08 | F9: REKAYASA PERANGKAT LUNAK LANJUT | H9: REKAYASA KEBUTUHAN SISTEM | S9: SISTEM PEMERINTAHAN BERBASIS ELEKTRONIK
A10: CPL09 | M10: TESIS | O10: TEKNOLOGI KEUANGAN ( FINTECH ) DAN RESIKO | Q10: TATA KELOLA DAN AUDIT BISNIS DIGITAL | S10: SISTEM PEMERINTAHAN BERBASIS ELEKTRONIK | T10: MANAJEMEN PROYEK TEKNOLOGI INFORMASI | U10: KOTA CERDAS | V10: PUBLIKASI
A11: CPL10 | B11: PERMODELAN STATISTIK UNTUK BISNIS | C11: MESIN PEMBELAJARAN UNTUK BISNIS | D11: ANALISIS DATA BESAR | J11: KEAMANAN SIBER | K11: SISTEM PENDUKUNG KEPUTUSAN CERDAS | S11: SISTEM PEMERINTAHAN BERBASIS ELEKTRONIK
A12: CPL11 | E12: MANAJEMEN STRATEGIS SISTEM INFORMASI | F12: REKAYASA PERANGKAT LUNAK LANJUT | G12: METODOLOGI PENELITIAN DAN PENULISAN ILMIAH | H12: REKAYASA KEBUTUHAN SISTEM | I12: INTERAKSI MANUSIA DAN KOMPUTER | L12: ARSITEKTUR ENTERPRISE UNTUK TEKNOLOGI INFORMASI | M12: TESIS | P12: KECERDASAN BISNIS | S12: SISTEM PEMERINTAHAN BERBASIS ELEKTRONIK

Sheet CPL-CPMK-MK
A1: No | B1: Kode CPL | C1: Deskripsi CPL | D1: Kode CPMK | E1: Deskripsi CPMK | F1: SMTR 1 | J1: SMTR 2 | M1: SMTR 3 | U1: SMTR 4
A2: 1 | B2: CPL01 | C2: Mampu bekerja secara mandiri ataupun dalam tim, serta menunjukkan sikap profesional dan etis dalam menjalankan tugas dan tanggung jawab untuk menyelesaikan proyek-proyek terkait teknologi informasi cerdas dalam pengembangan layanan publik dan ekonomi digital | D2: CPMK011 | E2: Mampu bekerja secara mandiri ataupun dalam tim dalam menjalankan tugas dan tanggung jawab untuk menyelesaikan proyek-proyek terkait teknologi informasi cerdas dalam pengembangan layanan publik dan ekonomi digital | M2: P.24.01.85.3.13 | U2: P.24.01.85.4.20 | V2: P.24.01.85.4.21
D3: CPMK012 | E3: Profesional dan Etis dalam menjalankan tugas dan tanggung jawab dalam menjalankan tugas dan tanggung jawab untuk menyelesaikan proyek-proyek terkait teknologi informasi cerdas dalam pengembangan layanan publik dan ekonomi digital | M3: =VLOOKUP(M2,'CPL-MK'!$A$2:$B$24,2) -> TESIS | U3: =VLOOKUP(U2,'CPL-MK'!$A$2:$B$24,2) -> PUBLIKASI | V3: =VLOOKUP(V2,'CPL-MK'!$A$2:$B$24,2) -> STRATEGI TEKNOPRENEURSHIP DAN INOVASI DIGITAL
A4: 2 | B4: CPL02 | C4: Mampu mengembangkan kemampuan berkomunikasi lisan secara efektif, berpikir kritis, kreatif, dan profesional serta dapat menghasilkan karya ilmiah yang orisinal dalam menyelesaikan permasalahan terkait teknologi informasi cerdas melalui pemanfaatan penelitian teknologi informasi dengan berbagai pihak terkait. | D4: CPMK021 | E4: Mampu mengembangkan kemampuan berkomunikasi lisan secara efektif, berpikir kritis, kreatif dan profesional dalam menyelesaikan permasalahan terkait teknologi informasi cerdas melalui pemanfaatan penelitian teknologi informasi dengan berbagai pihak terkait | M4: P.24.01.85.3.13 | U4: P.24.01.85.4.20 | V4: P.24.01.85.4.21
D5: CPMK022 | E5: Mampu menghasilkan karya ilmiah yang orisinal dalam menyelesaikan permasalahan terkait teknologi informasi cerdas melalui pemanfaatan penelitian teknologi informasi dengan berbagai pihak terkait | F5: =VLOOKUP(F4,'CPL-MK'!$A$2:$B$24,2) -> #N/A | M5: =VLOOKUP(M4,'CPL-MK'!$A$2:$B$24,2) -> TESIS | U5: =VLOOKUP(U4,'CPL-MK'!$A$2:$B$24,2) -> PUBLIKASI | V5: =VLOOKUP(V4,'CPL-MK'!$A$2:$B$24,2) -> STRATEGI TEKNOPRENEURSHIP DAN INOVASI DIGITAL
A6: 3 | B6: CPL03 | C6: Memiliki kemampuan menganalisis, mengevaluasi, dan membuat keputusan berdasarkan pengetahuan di bidang teknologi informasi cerdas dalam konteks dukungan terhadap pengembangan layanan publik dan ekonomi digital | D6: CPMK031 | E6: Memiliki kemampuan menganalisis berdasarkan pengetahuan di bidang teknologi informasi cerdas dalam konteks dukungan terhadap pengembangan layanan publik dan ekonomi digital | F6: P.24.01.85.1.05 | J6: P.24.01.85.2.07 | M6: P.24.01.85.3.15 | N6: P.24.01.85.3.16 | O6: P.24.01.85.3.19
D7: CPMK032 | E7: Memiliki kemampuan mengevaluasi berdasarkan pengetahuan di bidang teknologi informasi cerdas dalam konteks dukungan terhadap pengembangan layanan publik dan ekonomi digital | F7: =VLOOKUP(F6,'CPL-MK'!$A$2:$B$24,2) -> MANAJEMEN STRATEGIS SISTEM INFORMASI | J7: =VLOOKUP(J6,'CPL-MK'!$A$2:$B$24,2) -> METODOLOGI PENELITIAN DAN PENULISAN ILMIAH | K7: =VLOOKUP(K6,'CPL-MK'!$A$2:$B$24,2) -> #N/A | M7: =VLOOKUP(M6,'CPL-MK'!$A$2:$B$24,2) -> KECERDASAN BISNIS | N7: =VLOOKUP(N6,'CPL-MK'!$A$2:$B$24,2) -> TATA KELOLA DAN AUDIT BISNIS DIGITAL | O7: =VLOOKUP(O6,'CPL-MK'!$A$2:$B$24,2) -> KOTA CERDAS
