Workbook

Sheet Mhsw2024
A1: No | B1: NIM | C1: Nama Mahasiswa
A2: 1 | B2: 24.05.52.0002 | C2: SNEHA JAYA BAIDURI
A3: 2 | B3: 24.05.52.0003 | C3: ALFARIESSA GIFTHA ANDREA PITALOKA
A4: 3 | B4: 24.05.52.0004 | C4: MAHARANI PUTRI RUSTIANTI
A5: 4 | B5: 24.05.52.0005 | C5: FLORA SUCI FERONIKA
A6: 5 | B6: 24.05.52.0006 | C6: AATHIRA AUFA AZ-ZAHRA
A7: 6 | B7: 24.05.52.0007 | C7: SHEILA MONA PUTRI IKSANTI
A8: 7 | B8: 24.05.52.0008 | C8: RAIHAN RIFA MAHARADITYA
A9: 8 | B9: 24.05.52.0009 | C9: MARLINA DWI SAPUTRI
A10: 9 | B10: 24.05.52.0011 | C10: JONATHAN REXY FERDINAN
A11: 10 | B11: 24.05.52.0012 | C11: GITA TEONANDA ARELLIA
A12: 11 | B12: 24.05.52.0013 | C12: MUHAMMAD MAFTUF
A13: 12 | B13: 24.05.52.0014 | C13: ARELIA SALSABILA SAFITRI
... A35: 34 | B35: 24.05.52.3012 | C35: RORO AYU SUKMAWATI

Sheet ListMKSmt-1
A1: No | B1: ID | C1: Smtr | D1: Kode Matakuliah | E1: Nama Matakuliah | F1: Kategori | G1: SKS | H1: 1 | I1: 2 | J1: 3 | K1: 4 | L1: 5 | M1: 6 | N1: 7 | O1: 8 | AF1: No | AH1: Kode Matakuliah | AI1: Nama Matakuliah | AJ1: Kategori | AK1: SKS | AL1: 1 | AM1: 2 | AN1: 3 | AO1: 4 | AP1: 5 | AQ1: 6 | AR1: 7 | AS1: 8
A2: 1 | B2: MK1 | C2: I | D2: P.24.05.52.1.01 | E2: Akuntansi Pengantar 1 | F2: Wajib | G2: 3 | H2: V | AF2: 1 | AG2: MK1 | AH2: P.20.01.55.1.01 | AI2: TEORI MANAJEMEN | AJ2: Wajib | AK2: 2 | AL2: V
A3: 2 | B3: MK2 | C3: I | D3: P.24.05.52.1.02 | E3: Perpajakan 1 | F3: Wajib | G3: 3 | H3: V | AF3: 2 | AG3: MK2 | AH3: P.20.01.55.1.02 | AI3: TEORI ORGANISASI | AJ3: Wajib | AK3: 2 | AL3: V
A4: 3 | B4: MK3 | C4: I | D4: P.24.05.52.1.03 | E4: Etika Bisnis dan Profesi | F4: Wajib | G4: 2 | H4: V | AF4: 3 | AG4: MK3 | AH4: P.20.01.55.1.03 | AI4: KONSEP SISTEM DAN TEKNOLOGI INFORMASI | AJ4: Wajib | AK4: 2 | AL4: V
A5: 4 | B5: MK4 | C5: I | D5: P.24.05.52.1.04 | E5: Teori Ekonomi | F5: Wajib | G5: 3 | H5: V | AF5: 4 | AG5: MK4 | AH5: P.20.01.55.1.04 | AI5: LOGIKA DAN ALGORITMA | AJ5: Wajib | AK5: 3 | AL5: V
A6: 5 | B6: MK5 | C6: I | D6: P.24.05.52.1.05 | E6: Hukum Bisnis dan Perikatan | F6: Wajib | G6: 2 | H6: V | AF6: 5 | AG6: MK5 | AH6: P.20.01.55.1.05 | AI6: BAHASA PEMROGRAMAN | AJ6: Wajib | AK6: 2 | AL6: V
A7: 6 | B7: MK6 | C7: I | D7: U.24.05.52.1.01 | E7: Agama | F7: Wajib | G7: 2 | H7: V | AF7: 6 | AG7: MK6 | AH7: P.20.01.55.1.06 | AI7: LOGIKA MATEMATIKA | AJ7: Wajib | AK7: 3 | AL7: V
A8: 7 | B8: MK7 | C8: I | D8: U.24.05.52.1.02 | E8: Kewarganegaraan | F8: Wajib | G8: 2 | H8: V | AF8: 7 | AG8: MK7 | AH8: P.20.01.55.1.07 | AI8: MANAJEMEN BASIS DATA | AJ8: Wajib | AK8: 3 | AL8: V
A9: 8 | B9: MK8 | C9: I | D9: U.24.05.52.1.03 | E9: English for Business | F9: Wajib | G9: 2 | H9: V | AF9: 8 | AG9: MK8 | AH9: U.20.01.55.1.01 | AI9: BAHASA INGGRIS DASAR | AJ9: Wajib | AK9: 2 | AL9: V
A10: 19 | AF10: 9 | AG10: MK9 | AH10: P.20.01.55.2.08 | AI10: ANALISA SISTEM INFORMASI | AJ10: Wajib | AK10: 3 | AM10: V

Sheet MK1-TM
A1: FORM MONITORING DAN EVALUASI
A2: KETERCAPAIAN CAPAIAN PEMBELAJARAN MATAKULIAH(CPMK) PADA SATU ANGKATAN
A4: Tahun Akademik | C4: : 2024/2025 | E4: Program Studi | F4: : Akuntansi
A5: Kode Matakuliah | C5: : P.24.05.52.1.01 | E5: Fakultas | F5: : Ekonomika dan Bisnis
A6: Nama Matakuliah | C6: : Akuntansi Pengantar 1
A7: SKS Matakuliah | C7: : 3
A8: Semester/ Kelas | C8: : I / A1+DLC
A9: Dosen Pengampu | C9: : 1. YU.2.03.04.059 RR. Tjahjaning Poerwati, SE., M.Si, Ak, CA
C10: : 2. YU.2.20.01.122 Muhammad Ali Ma`Sum, S.E., M.Sc
D12: MK1 | F12: Nilai Akhir MK | G12: Nilai Huruf
D13: P.24.05.52.1.01
D14: Akuntansi Pengantar 1
D15: CPL02 | E15: CPL02
D16: CPMK021 | E16: CPMK023
D17: 50 | E17: 50
A18: No | B18: NIM | C18: Nama Mahasiswa
A19: 1 | B19: 24.05.52.0002 | C19: SNEHA JAYA BAIDURI | D19: 77.5 | E19: 82 | F19: =IFERROR((D19*($D$17/100))+(E19*($E$17/100)),"") -> 79.75 | G19: =IFERROR(VLOOKUP(F19,[1]Sheet1!$AA$1:$AB$10,2),"") -> B+
A20: 2 | B20: 24.05.52.0003 | C20: ALFARIESSA GIFTHA ANDREA PITALOKA | D20: 94 | E20: 99.5 | F20: =IFERROR((D20*($D$17/100))+(E20*($E$17/100)),"") -> 96.75 | G20: =IFERROR(VLOOKUP(F20,[1]Sheet1!$AA$1:$AB$10,2),"") -> A
A21: 3 | B21: 24.05.52.0004 | C21: MAHARANI PUTRI RUSTIANTI | D21: 93 | E21: 98.5 | F21: =IFERROR((D21*($D$17/100))+(E21*($E$17/100)),"") -> 95.75 | G21: =IFERROR(VLOOKUP(F21,[1]Sheet1!$AA$1:$AB$10,2),"") -> A
A22: 4 | B22: 24.05.52.0005 | C22: FLORA SUCI FERONIKA | D22: 77.5 | E22: 82 | F22: =IFERROR((D22*($D$17/100))+(E22*($E$17/100)),"") -> 79.75 | G22: =IFERROR(VLOOKUP(F22,[1]Sheet1!$AA$1:$AB$10,2),"") -> B+
A23: 5 | B23: 24.05.52.0006 | C23: AATHIRA AUFA AZ-ZAHRA | D23: 77.5 | E23: 82.5 | F23: =IFERROR((D23*($D$17/100))+(E23*($E$17/100)),"") -> 80 | G23: =IFERROR(VLOOKUP(F23,[1]Sheet1!$AA$1:$AB$10,2),"") -> B+
A24: 6 | B24: 24.05.52.0007 | C24: SHEILA MONA PUTRI IKSANTI | D24: 76.3 | E24: 80.8 | F24: =IFERROR((D24*($D$17/100))+(E24*($E$17/100)),"") -> 78.55 | G24: =IFERROR(VLOOKUP(F24,[1]Sheet1!$AA$1:$AB$10,2),"") -> B+
A25: 7 | B25: 24.05.52.0008 | C25: RAIHAN RIFA MAHARADITYA | D25: 93 | E25: 99 | F25: =IFERROR((D25*($D$17/100))+(E25*($E$17/100)),"") -> 96 | G25: =IFERROR(VLOOKUP(F25,[1]Sheet1!$AA$1:$AB$10,2),"") -> A
A26: 8 | B26: 24.05.52.0009 | C26: MARLINA DWI SAPUTRI | D26: 77.5 | E26: 82 | F26: =IFERROR((D26*($D$17/100))+(E26*($E$17/100)),"") -> 79.75 | G26: =IFERROR(VLOOKUP(F26,[1]Sheet1!$AA$1:$AB$10,2),"") -> B+
A27: 9 | B27: 24.05.52.0011 | C27: JONATHAN REXY FERDINAN | D27: 77.5 | E27: 81.5 | F27: =IFERROR((D27*($D$17/100))+(E27*($E$17/100)),"") -> 79.5 | G27: =IFERROR(VLOOKUP(F27,[1]Sheet1!$AA$1:$AB$10,2),"") -> B+
A28: 10 | B28: 24.05.52.0012 | C28: GITA TEONANDA ARELLIA | D28: 94 | E28: 99.5 | F28: =IFERROR((D28*($D$17/100))+(E28*($E$17/100)),"") -> 96.75 | G28: =IFERROR(VLOOKUP(F28,[1]Sheet1!$AA$1:$AB$10,2),"") -> A
A29: 11 | B29: 24.05.52.0013 | C29: MUHAMMAD MAFTUF | D29: 82 | E29: 86.5 | F29: =IFERROR((D29*($D$17/100))+(E29*($E$17/100)),"") -> 84.25 | G29: =IFERROR(VLOOKUP(F29,[1]Sheet1!$AA$1:$AB$10,2),"") -> B+
A30: 12 | B30: 24.05.52.0014 | C30: ARELIA SALSABILA SAFITRI | D30: 94 | E30: 99.5 | F30: =IFERROR((D30*($D$17/100))+(E30*($E$17/100)),"") -> 96.75 | G30: =IFERROR(VLOOKUP(F30,[1]Sheet1!$AA$1:$AB$10,2),"") -> A
... A52: 34 | B52: 24.05.52.3012 | C52: RORO AYU SUKMAWATI | D52: 80.25 | E52: 80.25 | F52: =IFERROR((D52*($D$17/100))+(E52*($E$17/100)),"") -> 80.25 | G52: =IFERROR(VLOOKUP(F52,[1]Sheet1!$AA$1:$AB$10,2),"") -> B+
D54: =D16 -> CPMK021 | E54: =E16 -> CPMK023 | F54: =F12 -> Nilai Akhir MK
C55: Tidak KRS/ Tidak Aktif | D55: =IFERROR(COUNTIF(D19:D52,""),"") -> 0 | E55: =IFERROR(COUNTIF(E19:E52,""),"") -> 0 | F55: =IFERROR(COUNTIF(F19:F52,""),"") -> 0
C56: <=65 | D56: =IFERROR(COUNTIF(D19:D52,C56)+COUNTIF(D19:D52,""),"")-D55 -> 0 | E56: =COUNTIF(E19:E52,C56)+COUNTIF(E19:E52,"")-E55 -> 0 | F56: =IFERROR(COUNTIF(F19:F52,C56)+COUNTIF(F19:F52,""),"")-F55 -> 0
C57: <85 | D57: =IFERROR(COUNTIF(D19:D52,C57)-D56,"") -> 24 | E57: =COUNTIF(E19:E52,C57)-E56 -> 19 | F57: =IFERROR(COUNTIF(F19:F52,C57)-F56,"") -> 23
C58: >=85 | D58: =COUNTIF(D19:D52,C58) -> 10 | E58: =COUNTIF(E19:E52,C58) -> 15 | F58: =IFERROR(COUNTIF(F19:F52,C58),"") -> 11
C59: Total | D59: =SUM(D55:D58) -> 34 | E59: =SUM(E55:E58) -> 34 | F59: =SUM(F55:F58) -> 34
C61: Jumlah mhsw yg lulus CPMK | D61: =(D57+D58)/(D59-D55) -> 1 | E61: =(E57+E58)/(E59-E55) -> 1 | F61: =(F57+F58)/(F59-F55) -> 1
C63: Minimal | D63: =MIN(D19:D52) -> 75.6 | E63: =MIN(E19:E52) -> 76.6 | F63: =IFERROR(MIN(F19:F52),"") -> 76.1
C64: Maksimal | D64: =MAX(D19:D37) -> 94 | E64: =MAX(E19:E52) -> 99.5 | F64: =IFERROR(MAX(F19:F52),"") -> 96.75
C65: Rata-Rata | D65: =AVERAGE(D19:D52) -> 83.072059 | E65: =AVERAGE(E19:E52) -> 85.939706 | F65: =IFERROR(AVERAGE(F19:F52),"") -> 84.505882

Sheet MK2-TO
A1: FORM MONITORING DAN EVALUASI
A2: KETERCAPAIAN CAPAIAN PEMBELAJARAN MATAKULIAH(CPMK) PADA SATU ANGKATAN
A4: Tahun Akademik | C4: : 2024/2025 | H4: Program Studi | I4: : Akuntansi
A5: Kode Matakuliah | C5: : P.24.01.52.1.02 | H5: Fakultas | I5: : Ekonomika dan Bisnis
A6: Nama Matakuliah | C6: : Perpajakan 1
A7: SKS Matakuliah | C7: : 2
A8: Semester/ Kelas | C8: : I / A1+DLC
A9: Dosen Pengampu | C9: : 1.Y.2.93.01.090 - Jaeni, S.E., M.Si., Ak., CA
C10: : 2.Y.3.00.10.075 - Rachmawati Meita O, S.E., M.Si., Ak., CA
D12: MK2 | I12: Nilai Akhir MK | J12: Nilai Huruf
D13: =TRIM(MID(C5,3,100)) -> P.24.01.52.1.02
D14: =TRIM(MID(C6,3,100)) -> Perpajakan 1
D15: CPL10 | E15: CPL10 | F15: CPL10 | G15: CPL10 | H15: CPL11
D16: CPMK101 | E16: CPMK102 | F16: CPMK103 | G16: CPMK104 | H16: CPMK111
D17: 16 | E17: 16 | F17: 26 | G17: 21 | H17: 21
A18: No | B18: NIM | C18: Nama Mahasiswa
A19: 1 | B19: 24.05.52.0002 | C19: SNEHA JAYA BAIDURI | D19: 79.25 | E19: 80.5 | F19: 83.38 | G19: 80.86 | H19: 83 | I19: =IFERROR((D19*($D$17/100))+(E19*($E$17/100))+(F19*($F$17/100))+(G19*($G$17/100))+(H19*($H$17/100)),"") -> 81.6494 | J19: =IFERROR(VLOOKUP(I19,[2]Sheet1!$AA$1:$AB$10,2),"") -> B+
A20: 2 | B20: 24.05.52.0003 | C20: ALFARIESSA GIFTHA ANDREA PITALOKA | D20: 76.13 | E20: 78.63 | F20: 86.46 | G20: 78.9 | H20: 86.1 | I20: =IFERROR((D20*($D$17/100))+(E20*($E$17/100))+(F20*($F$17/100))+(G20*($G$17/100))+(H20*($H$17/100)),"") -> 81.8912 | J20: =IFERROR(VLOOKUP(I20,[2]Sheet1!$AA$1:$AB$10,2),"") -> B+
A21: 3 | B21: 24.05.52.0004 | C21: MAHARANI PUTRI RUSTIANTI | D21: 78 | E21: 80.5 | F21: 84.15 | G21: 81.05 | H21: 83.95 | I21: =IFERROR((D21*($D$17/100))+(E21*($E$17/100))+(F21*($F$17/100))+(G21*($G$17/100))+(H21*($H$17/100)),"") -> 81.889 | J21: =IFERROR(VLOOKUP(I21,[2]Sheet1!$AA$1:$AB$10,2),"") -> B+
A22: 4 | B22: 24.05.52.0005 | C22: FLORA SUCI FERONIKA | D22: 78 | E22: 80.5 | F22: 84.15 | G22: 80.86 | H22: 83.95 | I22: =IFERROR((D22*($D$17/100))+(E22*($E$17/100))+(F22*($F$17/100))+(G22*($G$17/100))+(H22*($H$17/100)),"") -> 81.8491 | J22: =IFERROR(VLOOKUP(I22,[2]Sheet1!$AA$1:$AB$10,2),"") -> B+
A23: 5 | B23: 24.05.52.0006 | C23: AATHIRA AUFA AZ-ZAHRA | D23: 78.63 | E23: 81.13 | F23: 80.31 | G23: 81.57 | H23: 80.38 | I23: =IFERROR((D23*($D$17/100))+(E23*($E$17/100))+(F23*($F$17/100))+(G23*($G$17/100))+(H23*($H$17/100)),"") -> 80.4517 | J23: =IFERROR(VLOOKUP(I23,[2]Sheet1!$AA$1:$AB$10,2),"") -> B+
A24: 6 | B24: 24.05.52.0007 | C24: SHEILA MONA PUTRI IKSANTI | D24: 76.75 | E24: 78 | F24: 83.38 | G24: 78 | H24: 83 | I24: =IFERROR((D24*($D$17/100))+(E24*($E$17/100))+(F24*($F$17/100))+(G24*($G$17/100))+(H24*($H$17/100)),"") -> 80.2488 | J24: =IFERROR(VLOOKUP(I24,[2]Sheet1!$AA$1:$AB$10,2),"") -> B+
A25: 7 | B25: 24.05.52.0008 | C25: RAIHAN RIFA MAHARADITYA | D25: 76.13 | E25: 77.38 | F25: 84.15 | G25: 77.29 | H25: 83.71 | I25: =IFERROR((D25*($D$17/100))+(E25*($E$17/100))+(F25*($F$17/100))+(G25*($G$17/100))+(H25*($H$17/100)),"") -> 80.2506 | J25: =IFERROR(VLOOKUP(I25,[2]Sheet1!$AA$1:$AB$10,2),"") -> B+
A26: 8 | B26: 24.05.52.0009 | C26: MARLINA DWI SAPUTRI | D26: 76.75 | E26: 80.5 | F26: 84.15 | G26: 79.43 | H26: 83.95 | I26: =IFERROR((D26*($D$17/100))+(E26*($E$17/100))+(F26*($F$17/100))+(G26*($G$17/100))+(H26*($H$17/100)),"") -> 81.3488 | J26: =IFERROR(VLOOKUP(I26,[2]Sheet1!$AA$1:$AB$10,2),"") -> B+
A27: 9 | B27: 24.05.52.0011 | C27: JONATHAN REXY FERDINAN | D27: 78 | E27: 81.75 | F27: 80.31 | G27: 81.05 | H27: 80.38 | I27: =IFERROR((D27*($D$17/100))+(E27*($E$17/100))+(F27*($F$17/100))+(G27*($G$17/100))+(H27*($H$17/100)),"") -> 80.3409 | J27: =IFERROR(VLOOKUP(I27,[2]Sheet1!$AA$1:$AB$10,2),"") -> B+
A28: 10 | B28: 24.05.52.0012 | C28: GITA TEONANDA ARELLIA | D28: 78 | E28: 80.5 | F28: 84.15 | G28: 80.86 | H28: 83.95 | I28: =IFERROR((D28*($D$17/100))+(E28*($E$17/100))+(F28*($F$17/100))+(G28*($G$17/100))+(H28*($H$17/100)),"") -> 81.8491 | J28: =IFERROR(VLOOKUP(I28,[2]Sheet1!$AA$1:$AB$10,2),"") -> B+
A29: 11 | B29: 24.05.52.0013 | C29: MUHAMMAD MAFTUF | D29: 76.13 | E29: 78.63 | F29: 84.15 | G29: 78.71 | H29: 83.95 | I29: =IFERROR((D29*($D$17/100))+(E29*($E$17/100))+(F29*($F$17/100))+(G29*($G$17/100))+(H29*($H$17/100)),"") -> 80.7992 | J29: =IFERROR(VLOOKUP(I29,[2]Sheet1!$AA$1:$AB$10,2),"") -> B+
A30: 12 | B30: 24.05.52.0014 | C30: ARELIA SALSABILA SAFITRI | D30: 78 | E30: 80.5 | F30: 84.15 | G30: 81.62 | H30: 83.95 | I30: =IFERROR((D30*($D$17/100))+(E30*($E$17/100))+(F30*($F$17/100))+(G30*($G$17/100))+(H30*($H$17/100)),"") -> 82.0087 | J30: =IFERROR(VLOOKUP(I30,[2]Sheet1!$AA$1:$AB$10,2),"") -> B+
... A52: 34 | B52: 24.05.52.3012 | C52: RORO AYU SUKMAWATI | D52: 70.63 | E52: 53.13 | F52: 44.23 | G52: 70.48 | H52: 42.86 | I52: =IFERROR((D52*($D$17/100))+(E52*($E$17/100))+(F52*($F$17/100))+(G52*($G$17/100))+(H52*($H$17/100)),"") -> 55.1028 | J52: =IFERROR(VLOOKUP(I52,[2]Sheet1!$AA$1:$AB$10,2),"") -> C-
D55: =D17 -> 16 | E55: =E17 -> 16 | F55: =F17 -> 26 | G55: =G17 -> 21 | H55: =H17 -> 21 | I55: =I17 -> 0
C56: Tidak KRS/ Tidak Aktif | D56: =IFERROR(COUNTIF(D19:D52,""),"") -> 0 | E56: =IFERROR(COUNTIF(E19:E52,""),"") -> 0 | F56: =IFERROR(COUNTIF(F19:F52,""),"") -> 0 | G56: =IFERROR(COUNTIF(G19:G52,""),"") -> 0 | H56: =IFERROR(COUNTIF(H19:H52,""),"") -> 0 | I56: =IFERROR(COUNTIF(I19:I52,""),"") -> 0
C57: <=65 | D57: =IFERROR(COUNTIF(D19:D52,C57)-D56,"") -> 0 | E57: =IFERROR(COUNTIF(E19:E52,D57)+COUNTIF(E19:E52,""),"")-E56 -> 0 | F57: =IFERROR(COUNTIF(F19:F52,E57)+COUNTIF(F19:F52,""),"")-F56 -> 0 | G57: =IFERROR(COUNTIF(G19:G52,F57)+COUNTIF(G19:G52,""),"")-G56 -> 0 | H57: =IFERROR(COUNTIF(H19:H52,C57)+COUNTIF(H19:H52,""),"")-H56 -> 1 | I57: =IFERROR(COUNTIF(I19:I52,C57)+COUNTIF(I19:I52,""),"")-I56 -> 1
C58: <85 | D58: =IFERROR(COUNTIF(D19:D52,C58)-D57,"") -> 34 | E58: =IFERROR(COUNTIF(E19:E52,C58)-E57,"") -> 34 | F58: =IFERROR(COUNTIF(F19:F52,C58)-F57,"") -> 29 | G58: =IFERROR(COUNTIF(G19:G52,C58)-G57,"") -> 34 | H58: =IFERROR(COUNTIF(H19:H52,C58)-H57,"") -> 28 | I58: =IFERROR(COUNTIF(I19:I52,C58)-I57,"") -> 33
C59: >=85 | D59: =COUNTIF(D20:D53,C59) -> 0 | E59: =COUNTIF(E20:E53,C59) -> 0 | F59: =IFERROR(COUNTIF(F19:F52,C59),"") -> 5 | G59: =IFERROR(COUNTIF(G20:G53,D59),"") -> 0 | H59: =IFERROR(COUNTIF(H19:H52,C59),"") -> 5 | I59: =IFERROR(COUNTIF(I19:I52,C59),"") -> 0
C60: Total | D60: =SUM(D56:D59) -> 34 | E60: =SUM(E56:E59) -> 34 | F60: =SUM(F56:F59) -> 34 | G60: =SUM(G56:G59) -> 34 | H60: =SUM(H56:H59) -> 34 | I60: =SUM(I56:I59) -> 34
C62: Jumlah mhsw yg lulus CPMK | D62: =(D58+D59)/(D60-D56) -> 1 | E62: =(E58+E59)/(E60-E56) -> 1 | F62: =(F58+F59)/(F60-F56) -> 1 | G62: =(G58+G59)/(G60-G56) -> 1 | H62: =(H58+H59)/(H60-H56) -> 0.97058824 | I62: =(I58+I59)/(I60-I56) -> 0.97058824
C64: Minimal | D64: =MIN(D19:D52) -> 69.25 | E64: =MIN(E19:E52) -> 53.13 | F64: =MIN(F19:F52) -> 44.23 | G64: =MIN(G19:G52) -> 63.24 | H64: =MIN(H19:H52) -> 42.86 | I64: =IFERROR(MIN(I19:I52),"") -> 55.1028
C65: Maksimal | D65: =MAX(D19:D52) -> 82.5 | E65: =MAX(E19:E52) -> 84.5 | F65: =MAX(F19:F52) -> 86.46 | G65: =MAX(G19:G52) -> 83.81 | H65: =MAX(H19:H52) -> 86.48 | I65: =IFERROR(MAX(I19:I52),"") -> 84.5597
C66: Rata-Rata | D66: =AVERAGE(D19:D52) -> 77.273824 | E66: =AVERAGE(E19:E52) -> 78.442941 | F66: =AVERAGE(F19:F52) -> 80.710882 | G66: =AVERAGE(G19:G52) -> 78.175588 | H66: =AVERAGE(H19:H52) -> 80.661176 | I66: =IFERROR(AVERAGE(I19:I52),"") -> 79.255232

Sheet MK3-PSTI
A1: FORM MONITORING DAN EVALUASI
A2: KETERCAPAIAN CAPAIAN PEMBELAJARAN MATAKULIAH(CPMK) PADA SATU ANGKATAN
A4: Tahun Akademik | C4: : 2024/2025 | E4: Program Studi | F4: : Akuntansi
A5: Kode Matakuliah | C5: : P.24.05.52.1.03 | E5: Fakultas | F5: : Ekonomika dan Bisnis
A6: Nama Matakuliah | C6: : Etika Bisnis dan Profesi
A7: SKS Matakuliah | C7: : 2
A8: Semester/ Kelas | C8: : I / A1+DLC
A9: Dosen Pengampu | C9: : 1.Y.2.93.01.091 - Dr. Pancawati Hardiningsih, SE, M.Si, Ak, CA, Asean CPA, CSR
C10: : 2.Y.2.00.04.115 - Arief Himmawan Dwi Nugroho, SE, MM, M.Si., Ak, CA, CPA.
D12: MK3 | F12: Nilai Akhir MK | G12: Nilai Huruf
D13: =TRIM(MID(C5,2,20)) -> P.24.05.52.1.03
D14: =TRIM(MID(C6,2,100)) -> Etika Bisnis dan Profesi
D15: CPL08 | E15: CPL09
D16: CPMK81 | E16: CPMK91
D17: 50 | E17: 50
A18: No | B18: NIM | C18: Nama Mahasiswa
A19: 1 | B19: 24.05.52.0002 | C19: SNEHA JAYA BAIDURI | D19: 79 | E19: 82.5 | F19: =IFERROR((D19*($D$17/100))+(E19*($E$17/100)),"") -> 80.75 | G19: =IFERROR(VLOOKUP(F19,[3]Sheet1!$AA$1:$AB$10,2),"") -> B+
A20: 2 | B20: 24.05.52.0003 | C20: ALFARIESSA GIFTHA ANDREA PITALOKA | D20: 86 | E20: 86 | F20: =IFERROR((D20*($D$17/100))+(E20*($E$17/100)),"") -> 86 | G20: =IFERROR(VLOOKUP(F20,[2]Sheet1!$AA$1:$AB$10,2),"") -> A-
A21: 3 | B21: 24.05.52.0004 | C21: MAHARANI PUTRI RUSTIANTI | D21: 84 | E21: 86 | F21: =IFERROR((D21*($D$17/100))+(E21*($E$17/100)),"") -> 85 | G21: =IFERROR(VLOOKUP(F21,[2]Sheet1!$AA$1:$AB$10,2),"") -> A-
A22: 4 | B22: 24.05.52.0005 | C22: FLORA SUCI FERONIKA | D22: 78.4 | E22: 81.9 | F22: =IFERROR((D22*($D$17/100))+(E22*($E$17/100)),"") -> 80.15 | G22: =IFERROR(VLOOKUP(F22,[2]Sheet1!$AA$1:$AB$10,2),"") -> B+
A23: 5 | B23: 24.05.52.0006 | C23: AATHIRA AUFA AZ-ZAHRA | D23: 77 | E23: 82.5 | F23: =IFERROR((D23*($D$17/100))+(E23*($E$17/100)),"") -> 79.75 | G23: =IFERROR(VLOOKUP(F23,[2]Sheet1!$AA$1:$AB$10,2),"") -> B+
A24: 6 | B24: 24.05.52.0007 | C24: SHEILA MONA PUTRI IKSANTI | D24: 76.4 | E24: 81.9 | F24: =IFERROR((D24*($D$17/100))+(E24*($E$17/100)),"") -> 79.15 | G24: =IFERROR(VLOOKUP(F24,[2]Sheet1!$AA$1:$AB$10,2),"") -> B+
A25: 7 | B25: 24.05.52.0008 | C25: RAIHAN RIFA MAHARADITYA | D25: 86 | E25: 89.5 | F25: =IFERROR((D25*($D$17/100))+(E25*($E$17/100)),"") -> 87.75 | G25: =IFERROR(VLOOKUP(F25,[2]Sheet1!$AA$1:$AB$10,2),"") -> A-
A26: 8 | B26: 24.05.52.0009 | C26: MARLINA DWI SAPUTRI | D26: 79 | E26: 82.5 | F26: =IFERROR((D26*($D$17/100))+(E26*($E$17/100)),"") -> 80.75 | G26: =IFERROR(VLOOKUP(F26,[2]Sheet1!$AA$1:$AB$10,2),"") -> B+
A27: 9 | B27: 24.05.52.0011 | C27: JONATHAN REXY FERDINAN | D27: 82.5 | E27: 82.5 | F27: =IFERROR((D27*($D$17/100))+(E27*($E$17/100)),"") -> 82.5 | G27: =IFERROR(VLOOKUP(F27,[2]Sheet1!$AA$1:$AB$10,2),"") -> B+
A28: 10 | B28: 24.05.52.0012 | C28: GITA TEONANDA ARELLIA | D28: 86 | E28: 86 | F28: =IFERROR((D28*($D$17/100))+(E28*($E$17/100)),"") -> 86 | G28: =IFERROR(VLOOKUP(F28,[2]Sheet1!$AA$1:$AB$10,2),"") -> A-
A29: 11 | B29: 24.05.52.0013 | C29: MUHAMMAD MAFTUF | D29: 86 | E29: 86 | F29: =IFERROR((D29*($D$17/100))+(E29*($E$17/100)),"") -> 86 | G29: =IFERROR(VLOOKUP(F29,[2]Sheet1!$AA$1:$AB$10,2),"") -> A-
A30: 12 | B30: 24.05.52.0014 | C30: ARELIA SALSABILA SAFITRI | D30: 89.5 | E30: 89.5 | F30: =IFERROR((D30*($D$17/100))+(E30*($E$17/100)),"") -> 89.5 | G30: =IFERROR(VLOOKUP(F30,[2]Sheet1!$AA$1:$AB$10,2),"") -> A-
A31: 13 | B31: 24.05.52.0015 | C31: JULLER IBEL LAURENTIUS TURNIP | D31: 67.4 | E31: 74.4 | F31: =IFERROR((D31*($D$17/100))+(E31*($E$17/100)),"") -> 70.9 | G31: =IFERROR(VLOOKUP(F31,[2]Sheet1!$AA$1:$AB$10,2),"") -> B
... A52: 34 | B52: 24.05.52.3012 | C52: RORO AYU SUKMAWATI | D52: 10 | E52: 10 | F52: =IFERROR((D52*($D$17/100))+(E52*($E$17/100)),"") -> 10 | G52: =IFERROR(VLOOKUP(F52,[2]Sheet1!$AA$1:$AB$10,2),"") -> E
D54: =D16 -> CPMK81 | E54: =E16 -> CPMK91 | F54: =F12 -> Nilai Akhir MK
C55: Tidak KRS/ Tidak Aktif | D55: =IFERROR(COUNTIF(D19:D52,""),"") -> 0 | E55: =IFERROR(COUNTIF(E19:E52,""),"") -> 0 | F55: =IFERROR(COUNTIF(F19:F52,""),"") -> 0
C56: <=65 | D56: =IFERROR(COUNTIF(D19:D52,C56)+COUNTIF(D19:D52,""),"")-D55 -> 2 | E56: =COUNTIF(E19:E52,C56)+COUNTIF(E19:E52,"")-E55 -> 6 | F56: =IFERROR(COUNTIF(F19:F52,C56)+COUNTIF(F19:F52,""),"")-F55 -> 6
C57: <85 | D57: =IFERROR(COUNTIF(D19:D52,C57)-D56,"") -> 15 | E57: =COUNTIF(E19:E52,C57)-E56 -> 10 | F57: =IFERROR(COUNTIF(F19:F52,C57)-F56,"") -> 10
C58: >=85 | D58: =COUNTIF(D19:D52,C58) -> 17 | E58: =COUNTIF(E19:E52,C58) -> 18 | F58: =IFERROR(COUNTIF(F19:F52,C58),"") -> 18
C59: Total | D59: =SUM(D55:D58) -> 34 | E59: =SUM(E55:E58) -> 34 | F59: =SUM(F55:F58) -> 34
C61: Jumlah mhsw yg lulus CPMK | D61: =(D57+D58)/(D59-D55) -> 0.94117647 | E61: =(E57+E58)/(E59-E55) -> 0.82352941 | F61: =(F57+F58)/(F59-F55) -> 0.82352941
C63: Minimal | D63: =MIN(D19:D52) -> 10 | E63: =MIN(E19:E52) -> 10 | F63: =IFERROR(MIN(F19:F52),"") -> 10
C64: Maksimal | D64: =MAX(D19:D37) -> 89.5 | E64: =MAX(E19:E52) -> 96.5 | F64: =IFERROR(MAX(F19:F52),"") -> 91.25
C65: Rata-Rata | D65: =AVERAGE(D19:D52) -> 77.911765 | E65: =AVERAGE(E19:E52) -> 76.726471 | F65: =IFERROR(AVERAGE(F19:F52),"") -> 77.319118

Sheet MK4-L&A
A1: FORM MONITORING DAN EVALUASI
A2: KETERCAPAIAN CAPAIAN PEMBELAJARAN MATAKULIAH(CPMK) PADA SATU ANGKATAN
A4: Tahun Akademik | C4: : 2024/2025 | E4: Program Studi | F4: : Akuntansi
A5: Kode Matakuliah | C5: : P.24.05.52.1.04 | E5: Fakultas | F5: : Ekonomika dan Bisnis
A6: Nama Matakuliah | C6: : Teori Ekonomi
A7: SKS Matakuliah | C7: : 3
A8: Semester/ Kelas | C8: : I / A1+DLC
A9: Dosen Pengampu | C9: : 1. Y.2.91.10.067 Dr. SRI ISNOWATI, S.E., M.Si
C10: : 2. Y.2.92.07.087 Dr. Drs. AGUS BUDI SANTOSA, M.Si
D12: MK4 | F12: Nilai Akhir MK | G12: Nilai Huruf
D13: =TRIM(MID(C5,2,20)) -> P.24.05.52.1.04
D14: =TRIM(MID(C6,2,100)) -> Teori Ekonomi
D15: CPL05 | E15: CPL05
D16: CPMK55 | E16: CPMK56
D17: 50 | E17: 50
A18: No | B18: NIM | C18: Nama Mahasiswa
A19: 1 | B19: 24.05.52.0002 | C19: SNEHA JAYA BAIDURI | D19: 84.5 | E19: 87 | F19: =IFERROR((D19*($D$17/100))+(E19*($E$17/100)),"") -> 85.75 | G19: =IFERROR(VLOOKUP(F21,[4]Sheet1!$AA$1:$AB$10,2),"") -> A-
A20: 2 | B20: 24.05.52.0003 | C20: ALFARIESSA GIFTHA ANDREA PITALOKA | D20: 88 | E20: 87 | F20: =IFERROR((D20*($D$17/100))+(E20*($E$17/100)),"") -> 87.5 | G20: =IFERROR(VLOOKUP(F20,[4]Sheet1!$AA$1:$AB$10,2),"") -> A-
A21: 3 | B21: 24.05.52.0004 | C21: MAHARANI PUTRI RUSTIANTI | D21: 88 | E21: 87 | F21: =IFERROR((D21*($D$17/100))+(E21*($E$17/100)),"") -> 87.5 | G21: =IFERROR(VLOOKUP(F21,[4]Sheet1!$AA$1:$AB$10,2),"") -> A-
A22: 4 | B22: 24.05.52.0005 | C22: FLORA SUCI FERONIKA | D22: 81 | E22: 87 | F22: =IFERROR((D22*($D$17/100))+(E22*($E$17/100)),"") -> 84 | G22: =IFERROR(VLOOKUP(F22,[4]Sheet1!$AA$1:$AB$10,2),"") -> B+
A23: 5 | B23: 24.05.52.0006 | C23: AATHIRA AUFA AZ-ZAHRA | D23: 81 | E23: 87 | F23: =IFERROR((D23*($D$17/100))+(E23*($E$17/100)),"") -> 84 | G23: =IFERROR(VLOOKUP(F23,[4]Sheet1!$AA$1:$AB$10,2),"") -> B+
A24: 6 | B24: 24.05.52.0007 | C24: SHEILA MONA PUTRI IKSANTI | D24: 85.9 | E24: 87 | F24: =IFERROR((D24*($D$17/100))+(E24*($E$17/100)),"") -> 86.45 | G24: =IFERROR(VLOOKUP(F24,[4]Sheet1!$AA$1:$AB$10,2),"") -> A-
A25: 7 | B25: 24.05.52.0008 | C25: RAIHAN RIFA MAHARADITYA | D25: 84.5 | E25: 90.5 | F25: =IFERROR((D25*($D$17/100))+(E25*($E$17/100)),"") -> 87.5 | G25: =IFERROR(VLOOKUP(F25,[4]Sheet1!$AA$1:$AB$10,2),"") -> A-
A26: 8 | B26: 24.05.52.0009 | C26: MARLINA DWI SAPUTRI | D26: 88 | E26: 87 | F26: =IFERROR((D26*($D$17/100))+(E26*($E$17/100)),"") -> 87.5 | G26: =IFERROR(VLOOKUP(F26,[4]Sheet1!$AA$1:$AB$10,2),"") -> A-
A27: 9 | B27: 24.05.52.0011 | C27: JONATHAN REXY FERDINAN | D27: 84.5 | E27: 83.5 | F27: =IFERROR((D27*($D$17/100))+(E27*($E$17/100)),"") -> 84 | G27: =IFERROR(VLOOKUP(F27,[4]Sheet1!$AA$1:$AB$10,2),"") -> B+
A28: 10 | B28: 24.05.52.0012 | C28: GITA TEONANDA ARELLIA | D28: 88 | E28: 87 | F28: =IFERROR((D28*($D$17/100))+(E28*($E$17/100)),"") -> 87.5 | G28: =IFERROR(VLOOKUP(F28,[4]Sheet1!$AA$1:$AB$10,2),"") -> A-
A29: 11 | B29: 24.05.52.0013 | C29: MUHAMMAD MAFTUF | D29: 84.5 | E29: 83.5 | F29: =IFERROR((D29*($D$17/100))+(E29*($E$17/100)),"") -> 84 | G29: =IFERROR(VLOOKUP(F29,[4]Sheet1!$AA$1:$AB$10,2),"") -> B+
A30: 12 | B30: 24.05.52.0014 | C30: ARELIA SALSABILA SAFITRI | D30: 88 | E30: 87 | F30: =IFERROR((D30*($D$17/100))+(E30*($E$17/100)),"") -> 87.5 | G30: =IFERROR(VLOOKUP(F30,[4]Sheet1!$AA$1:$AB$10,2),"") -> A-
A31: 13 | B31: 24.05.52.0015 | C31: JULLER IBEL LAURENTIUS TURNIP | D31: 81 | E31: 80 | F31: =IFERROR((D31*($D$17/100))+(E31*($E$17/100)),"") -> 80.5 | G31: =IFERROR(VLOOKUP(F31,[4]Sheet1!$AA$1:$AB$10,2),"") -> B+
... A52: 34 | B52: 24.05.52.3012 | C52: RORO AYU SUKMAWATI | D52: 10 | E52: 59 | F52: =IFERROR((D52*($D$17/100))+(E52*($E$17/100)),"") -> 34.5 | G52: =IFERROR(VLOOKUP(F52,[4]Sheet1!$AA$1:$AB$10,2),"") -> E
D54: =D16 -> CPMK55 | E54: =E16 -> CPMK56 | F54: =F12 -> Nilai Akhir MK
C55: Tidak KRS/Tidak Aktif | D55: =IFERROR(COUNTIF(D19:D52,""),"") -> 0 | E55: =IFERROR(COUNTIF(E19:E52,""),"") -> 0 | F55: =IFERROR(COUNTIF(F19:F52,""),"") -> 0
C56: <=65 | D56: =IFERROR(COUNTIF(D19:D52,C56)+COUNTIF(D19:D52,""),"")-D55 -> 2 | E56: =COUNTIF(E19:E52,C56)+COUNTIF(E19:E52,"")-E55 -> 2 | F56: =IFERROR(COUNTIF(F19:F52,C56)+COUNTIF(F19:F52,""),"") -> 2
C57: <85 | D57: =IFERROR(COUNTIF(D19:D52,C57)-D56,"") -> 16 | E57: =COUNTIF(E19:E52,C57)-E56 -> 9 | F57: =IFERROR(COUNTIF(F19:F52,C57)-F56,"") -> 11
C58: >=85 | D58: =COUNTIF(D19:D52,C58) -> 16 | E58: =COUNTIF(E19:E52,C58) -> 23 | F58: =IFERROR(COUNTIF(F19:F52,C58),"") -> 21
C59: Total | D59: =SUM(D55:D58) -> 34 | E59: =SUM(E55:E58) -> 34 | F59: =SUM(F55:F58) -> 34
C61: Jumlah mhsw yg lulus CPMK | D61: =(D57+D58)/(D59-D55) -> 0.94117647 | E61: =(E57+E58)/(E59-E55) -> 0.94117647 | F61: =(F57+F58)/(F59-F55) -> 0.94117647
C63: Minimal | D63: =MIN(D19:D52) -> 10 | E63: =MIN(E19:E52) -> 59 | F63: =IFERROR(MIN(F19:F52),"") -> 34.5
C64: Maksimal | D64: =MAX(D19:D52) -> 88 | E64: =MAX(E19:E52) -> 94.5 | F64: =IFERROR(MAX(F19:F52),"") -> 87.75
C65: Rata-Rata | D65: =AVERAGE(D19:D52) -> 79.123529 | E65: =AVERAGE(E19:E52) -> 84.361765 | F65: =IFERROR(AVERAGE(F19:F52),"") -> 81.742647

Sheet MK5-BP
A1: FORM MONITORING DAN EVALUASI
A2: KETERCAPAIAN CAPAIAN PEMBELAJARAN MATAKULIAH(CPMK) PADA SATU ANGKATAN
A4: Tahun Akademik | C4: : 2024/2025 | E4: Program Studi | F4: : Akuntansi
A5: Kode Matakuliah | C5: : P.24.05.52.1.05 | E5: Fakultas | F5: : Ekonomika dan Bisnis
A6: Nama Matakuliah | C6: : Hukum Bisnis dan Perikatan
A7: SKS Matakuliah | C7: : 2
A8: Semester/ Kelas | C8: : I / A1+DLC
A9: Dosen Pengampu | C9: : 1. Y.2.90.01.052 Dr. TRISTIANA RIJANTI, S.H, M.M.
C10: : 2. Y.2.91.10.069 ADI SULIANTORO, SH., M.H
D12: MK5 | F12: Nilai Akhir MK | G12: Nilai Huruf
D13: =TRIM(MID(C5,2,20)) -> P.24.05.52.1.05
D14: =TRIM(MID(C6,2,100)) -> Hukum Bisnis dan Perikatan
D15: CPL11 | E15: CPL11
D16: CPMK114 | E16: CPMK115
D17: 50 | E17: 50
A18: No | B18: NIM | C18: Nama Mahasiswa
A19: 1 | B19: 24.05.52.0002 | C19: SNEHA JAYA BAIDURI | D19: 75.6 | E19: 68.1 | F19: =IFERROR((D20*($D$17/100))+(E20*($E$17/100)),"") -> 71.85 | G19: =IFERROR(VLOOKUP(F21,[4]Sheet1!$AA$1:$AB$10,2),"") -> B
A20: 2 | B20: 24.05.52.0003 | C20: ALFARIESSA GIFTHA ANDREA PITALOKA | D20: 75.6 | E20: 68.1 | F20: =IFERROR((D20*($D$17/100))+(E20*($E$17/100)),"") -> 71.85 | G20: =IFERROR(VLOOKUP(F20,[5]Sheet1!$AA$1:$AB$10,2),"") -> B
A21: 3 | B21: 24.05.52.0004 | C21: MAHARANI PUTRI RUSTIANTI | D21: 75.6 | E21: 68.1 | F21: =IFERROR((D21*($D$17/100))+(E21*($E$17/100)),"") -> 71.85 | G21: =IFERROR(VLOOKUP(F21,[5]Sheet1!$AA$1:$AB$10,2),"") -> B
A22: 4 | B22: 24.05.52.0005 | C22: FLORA SUCI FERONIKA | D22: 75.6 | E22: 68.1 | F22: =IFERROR((D22*($D$17/100))+(E22*($E$17/100)),"") -> 71.85 | G22: =IFERROR(VLOOKUP(F22,[5]Sheet1!$AA$1:$AB$10,2),"") -> B
A23: 5 | B23: 24.05.52.0006 | C23: AATHIRA AUFA AZ-ZAHRA | D23: 78.4 | E23: 70.9 | F23: =IFERROR((D23*($D$17/100))+(E23*($E$17/100)),"") -> 74.65 | G23: =IFERROR(VLOOKUP(F23,[5]Sheet1!$AA$1:$AB$10,2),"") -> B
A24: 6 | B24: 24.05.52.0007 | C24: SHEILA MONA PUTRI IKSANTI | D24: 75.6 | E24: 68.1 | F24: =IFERROR((D24*($D$17/100))+(E24*($E$17/100)),"") -> 71.85 | G24: =IFERROR(VLOOKUP(F24,[5]Sheet1!$AA$1:$AB$10,2),"") -> B
A25: 7 | B25: 24.05.52.0008 | C25: RAIHAN RIFA MAHARADITYA | D25: 78.4 | E25: 70.9 | F25: =IFERROR((D25*($D$17/100))+(E25*($E$17/100)),"") -> 74.65 | G25: =IFERROR(VLOOKUP(F25,[5]Sheet1!$AA$1:$AB$10,2),"") -> B
A26: 8 | B26: 24.05.52.0009 | C26: MARLINA DWI SAPUTRI | D26: 75.6 | E26: 68.1 | F26: =IFERROR((D26*($D$17/100))+(E26*($E$17/100)),"") -> 71.85 | G26: =IFERROR(VLOOKUP(F26,[5]Sheet1!$AA$1:$AB$10,2),"") -> B
A27: 9 | B27: 24.05.52.0011 | C27: JONATHAN REXY FERDINAN | D27: 75.6 | E27: 68.1 | F27: =IFERROR((D27*($D$17/100))+(E27*($E$17/100)),"") -> 71.85 | G27: =IFERROR(VLOOKUP(F27,[5]Sheet1!$AA$1:$AB$10,2),"") -> B
A28: 10 | B28: 24.05.52.0012 | C28: GITA TEONANDA ARELLIA | D28: 78.4 | E28: 70.9 | F28: =IFERROR((D28*($D$17/100))+(E28*($E$17/100)),"") -> 74.65 | G28: =IFERROR(VLOOKUP(F28,[5]Sheet1!$AA$1:$AB$10,2),"") -> B
A29: 11 | B29: 24.05.52.0013 | C29: MUHAMMAD MAFTUF | D29: 75.6 | E29: 68.1 | F29: =IFERROR((D29*($D$17/100))+(E29*($E$17/100)),"") -> 71.85 | G29: =IFERROR(VLOOKUP(F29,[5]Sheet1!$AA$1:$AB$10,2),"") -> B
A30: 12 | B30: 24.05.52.0014 | C30: ARELIA SALSABILA SAFITRI | D30: 78.4 | E30: 70.9 | F30: =IFERROR((D30*($D$17/100))+(E30*($E$17/100)),"") -> 74.65 | G30: =IFERROR(VLOOKUP(F30,[5]Sheet1!$AA$1:$AB$10,2),"") -> B
A31: 13 | B31: 24.05.52.0015 | C31: JULLER IBEL LAURENTIUS TURNIP | D31: 75.6 | E31: 68.1 | F31: =IFERROR((D31*($D$17/100))+(E31*($E$17/100)),"") -> 71.85 | G31: =IFERROR(VLOOKUP(F31,[5]Sheet1!$AA$1:$AB$10,2),"") -> B
... A52: 34 | B52: 24.05.52.3012 | C52: RORO AYU SUKMAWATI | D52: 95.5 | E52: 95.5 | F52: =IFERROR((D52*($D$17/100))+(E52*($E$17/100)),"") -> 95.5 | G52: =IFERROR(VLOOKUP(F52,[5]Sheet1!$AA$1:$AB$10,2),"") -> A
D54: =D16 -> CPMK114 | E54: =E16 -> CPMK115 | F54: =F12 -> Nilai Akhir MK
C55: Tidak KRS/Tidak Aktif | D55: =IFERROR(COUNTIF(D19:D52,""),"") -> 0 | E55: =IFERROR(COUNTIF(E19:E52,""),"") -> 0 | F55: =IFERROR(COUNTIF(F19:F52,""),"") -> 0
C56: <=65 | D56: =IFERROR(COUNTIF(D19:D52,C56)+COUNTIF(D19:D52,""),"")-D55 -> 0 | E56: =COUNTIF(E19:E52,C56)+COUNTIF(E19:E52,"")-E55 -> 0 | F56: =IFERROR(COUNTIF(F19:F52,C56)+COUNTIF(F19:F52,""),"") -> 0
C57: <85 | D57: =IFERROR(COUNTIF(D19:D52,C57)-D56,"") -> 23 | E57: =COUNTIF(E19:E52,C57)-E56 -> 23 | F57: =IFERROR(COUNTIF(F19:F52,C57)-F56,"") -> 23
C58: >=85 | D58: =COUNTIF(D19:D52,C58) -> 11 | E58: =COUNTIF(E19:E52,C58) -> 11 | F58: =IFERROR(COUNTIF(F19:F52,C58),"") -> 11
C59: Total | D59: =SUM(D55:D58) -> 34 | E59: =SUM(E55:E58) -> 34 | F59: =SUM(F55:F58) -> 34
C61: Jumlah mhsw yg lulus CPMK | D61: =(D57+D58)/(D59-D55) -> 1 | E61: =(E57+E58)/(E59-E55) -> 1 | F61: =(F57+F58)/(F59-F55) -> 1
C63: Minimal | D63: =MIN(D19:D52) -> 75.6 | E63: =MIN(E19:E52) -> 68.1 | F63: =IFERROR(MIN(F19:F52),"") -> 71.85
C64: Maksimal | D64: =MAX(D19:D52) -> 95.5 | E64: =MAX(E19:E52) -> 95.5 | F64: =IFERROR(MAX(F19:F52),"") -> 95.5
C65: Rata-Rata | D65: =AVERAGE(D19:D52) -> 82.035294 | E65: =AVERAGE(E19:E52) -> 76.961765 | F65: =IFERROR(AVERAGE(F19:F52),"") -> 79.498529

Sheet MK7-MBD
A1: FORM MONITORING DAN EVALUASI
A2: KETERCAPAIAN CAPAIAN PEMBELAJARAN MATAKULIAH(CPMK) PADA SATU ANGKATAN
A4: Tahun Akademik | C4: : 2024/2025 | E4: Program Studi | F4: : Akuntansi
A5: Kode Matakuliah | C5: : U.24.05.52.1.01 | E5: Fakultas | F5: : Ekonomika dan Bisnis
A6: Nama Matakuliah | C6: : Agama
A7: SKS Matakuliah | C7: : 2
A8: Semester/ Kelas | C8: : I / A1+DLC
A9: Dosen Pengampu | C9: : 1. L.0329 JUNAIDI, S.Pd.I., M.S.I.
C10: : 2. L.0410 BM. HARRY PUTRANTI, S.FK
C11: : 3. YK.2.06.07.028 Dr. ANTONO ADHI, S.Kom, M.M., M.T.
D12: MK6 | F12: Nilai Akhir MK | G12: Nilai Huruf
D13: =TRIM(MID(C5,2,20)) -> U.24.05.52.1.01
D14: =TRIM(MID(C6,2,100)) -> Agama
D15: CPL01 | E15: CPL1
D16: CPMK11 | E16: CPMK13
D17: 50 | E17: 50
A18: No | B18: NIM | C18: Nama Mahasiswa
A19: 1 | B19: 24.05.52.0002 | C19: SNEHA JAYA BAIDURI | D19: 82.7 | E19: 91.7 | F19: =IFERROR((D19*($D$17/100))+(E19*($E$17/100)),"") -> 87.2 | G19: =IFERROR(VLOOKUP(F21,[4]Sheet1!$AA$1:$AB$10,2),"") -> A-
A20: 2 | B20: 24.05.52.0003 | C20: ALFARIESSA GIFTHA ANDREA PITALOKA | D20: 84.35 | E20: 92.2 | F20: =IFERROR((D20*($D$17/100))+(E20*($E$17/100)),"") -> 88.275 | G20: =IFERROR(VLOOKUP(F20,[6]Sheet1!$AA$1:$AB$10,2),"") -> A-
A21: 3 | B21: 24.05.52.0004 | C21: MAHARANI PUTRI RUSTIANTI | D21: 81.05 | E21: 89.7 | F21: =IFERROR((D21*($D$17/100))+(E21*($E$17/100)),"") -> 85.375 | G21: =IFERROR(VLOOKUP(F21,[6]Sheet1!$AA$1:$AB$10,2),"") -> A-
A22: 4 | B22: 24.05.52.0005 | C22: FLORA SUCI FERONIKA | D22: 82.35 | E22: 91 | F22: =IFERROR((D22*($D$17/100))+(E22*($E$17/100)),"") -> 86.675 | G22: =IFERROR(VLOOKUP(F22,[6]Sheet1!$AA$1:$AB$10,2),"") -> A-
A23: 5 | B23: 24.05.52.0006 | C23: AATHIRA AUFA AZ-ZAHRA | D23: 85.5 | E23: 94.5 | F23: =IFERROR((D23*($D$17/100))+(E23*($E$17/100)),"") -> 90 | G23: =IFERROR(VLOOKUP(F23,[6]Sheet1!$AA$1:$AB$10,2),"") -> A-
A24: 6 | B24: 24.05.52.0007 | C24: SHEILA MONA PUTRI IKSANTI | D24: 87.05 | E24: 95.5 | F24: =IFERROR((D24*($D$17/100))+(E24*($E$17/100)),"") -> 91.275 | G24: =IFERROR(VLOOKUP(F24,[6]Sheet1!$AA$1:$AB$10,2),"") -> A
A25: 7 | B25: 24.05.52.0008 | C25: RAIHAN RIFA MAHARADITYA | D25: 84.4 | E25: 94.4 | F25: =IFERROR((D25*($D$17/100))+(E25*($E$17/100)),"") -> 89.4 | G25: =IFERROR(VLOOKUP(F25,[6]Sheet1!$AA$1:$AB$10,2),"") -> A-
A26: 8 | B26: 24.05.52.0009 | C26: MARLINA DWI SAPUTRI | D26: 81.9 | E26: 90.8 | F26: =IFERROR((D26*($D$17/100))+(E26*($E$17/100)),"") -> 86.35 | G26: =IFERROR(VLOOKUP(F26,[6]Sheet1!$AA$1:$AB$10,2),"") -> A-
A27: 9 | B27: 24.05.52.0011 | C27: JONATHAN REXY FERDINAN | D27: 85.5 | E27: 85 | F27: =IFERROR((D27*($D$17/100))+(E27*($E$17/100)),"") -> 85.25 | G27: =IFERROR(VLOOKUP(F27,[6]Sheet1!$AA$1:$AB$10,2),"") -> A-
A28: 10 | B28: 24.05.52.0012 | C28: GITA TEONANDA ARELLIA | D28: 84.85 | E28: 92.5 | F28: =IFERROR((D28*($D$17/100))+(E28*($E$17/100)),"") -> 88.675 | G28: =IFERROR(VLOOKUP(F28,[6]Sheet1!$AA$1:$AB$10,2),"") -> A-
A29: 11 | B29: 24.05.52.0013 | C29: MUHAMMAD MAFTUF | D29: 83.4 | E29: 93.8 | F29: =IFERROR((D29*($D$17/100))+(E29*($E$17/100)),"") -> 88.6 | G29: =IFERROR(VLOOKUP(F29,[6]Sheet1!$AA$1:$AB$10,2),"") -> A-
A30: 12 | B30: 24.05.52.0014 | C30: ARELIA SALSABILA SAFITRI | D30: 85.95 | E30: 94 | F30: =IFERROR((D30*($D$17/100))+(E30*($E$17/100)),"") -> 89.975 | G30: =IFERROR(VLOOKUP(F30,[6]Sheet1!$AA$1:$AB$10,2),"") -> A-
A31: 13 | B31: 24.05.52.0015 | C31: JULLER IBEL LAURENTIUS TURNIP | D31: 40 | E31: 40 | F31: =IFERROR((D31*($D$17/100))+(E31*($E$17/100)),"") -> 40 | G31: =IFERROR(VLOOKUP(F31,[6]Sheet1!$AA$1:$AB$10,2),"") -> E
... A52: 34 | B52: 24.05.52.3012 | C52: RORO AYU SUKMAWATI | D52: 88 | E52: 88 | F52: =IFERROR((D52*($D$17/100))+(E52*($E$17/100)),"") -> 88 | G52: =IFERROR(VLOOKUP(F52,[6]Sheet1!$AA$1:$AB$10,2),"") -> A-
D54: =D16 -> CPMK11 | E54: =E16 -> CPMK13 | F54: =F12 -> Nilai Akhir MK
C55: Tidak KRS/Tidak Aktif | D55: =IFERROR(COUNTIF(D19:D52,""),"") -> 0 | E55: =IFERROR(COUNTIF(E19:E52,""),"") -> 0 | F55: =IFERROR(COUNTIF(F19:F52,""),"") -> 0
C56: <=65 | D56: =IFERROR(COUNTIF(D19:D52,C56)+COUNTIF(D19:D52,""),"")-D55 -> 1 | E56: =COUNTIF(E19:E52,C56)+COUNTIF(E19:E52,"")-E55 -> 1 | F56: =IFERROR(COUNTIF(F19:F52,C56)+COUNTIF(F19:F52,""),"") -> 1
C57: <85 | D57: =IFERROR(COUNTIF(D19:D52,C57)-D56,"") -> 14 | E57: =COUNTIF(E19:E52,C57)-E56 -> 0 | F57: =IFERROR(COUNTIF(F19:F52,C57)-F56,"") -> 0
C58: >=85 | D58: =COUNTIF(D19:D52,C58) -> 19 | E58: =COUNTIF(E19:E52,C58) -> 33 | F58: =IFERROR(COUNTIF(F19:F52,C58),"") -> 33
C59: Total | D59: =SUM(D55:D58) -> 34 | E59: =SUM(E55:E58) -> 34 | F59: =SUM(F55:F58) -> 34
C61: Jumlah mhsw yg lulus CPMK | D61: =(D57+D58)/(D59-D55) -> 0.97058824 | E61: =(E57+E58)/(E59-E55) -> 0.97058824 | F61: =(F57+F58)/(F59-F55) -> 0.97058824
C63: Minimal | D63: =MIN(D19:D52) -> 40 | E63: =MIN(E19:E52) -> 40 | F63: =IFERROR(MIN(F19:F52),"") -> 40
C64: Maksimal | D64: =MAX(D19:D52) -> 95.55 | E64: =MAX(E19:E52) -> 95.55 | F64: =IFERROR(MAX(F19:F52),"") -> 95.55
...

Sheet MK8_BID
A1: FORM MONITORING DAN EVALUASI
A2: KETERCAPAIAN CAPAIAN PEMBELAJARAN MATAKULIAH(CPMK) PADA SATU ANGKATAN
A4: Tahun Akademik | C4: : 2024/2025 | E4: Program Studi | F4: : Akuntansi
A5: Kode Matakuliah | C5: : U.24.05.52.1.02 | E5: Fakultas | F5: : Ekonomika dan Bisnis
A6: Nama Matakuliah | C6: : Kewarganegaraan
A7: SKS Matakuliah | C7: : 2
A8: Semester/ Kelas | C8: : I / A1+DLC
A9: Dosen Pengampu | C9: : 1.
C10: : 2.
D12: MK7 | F12: Nilai Akhir MK | G12: Nilai Huruf
D13: =TRIM(MID(C5,2,20)) -> U.24.05.52.1.02
D14: =TRIM(MID(C6,2,100)) -> Kewarganegaraan
D15: CPL01 | E15: CPL01
D16: CPMK12 | E16: CPMK13
D17: 50 | E17: 50
A18: No | B18: NIM | C18: Nama Mahasiswa
A19: 1 | B19: 24.05.52.0002 | C19: SNEHA JAYA BAIDURI | D19: 81.4 | E19: 81.4 | F19: =IFERROR((D19*($D$17/100))+(E19*($E$17/100)),"") -> 81.4 | G19: =IFERROR(VLOOKUP(F20,[7]Sheet1!$AA$1:$AB$10,2),"") -> B+
A20: 2 | B20: 24.05.52.0003 | C20: ALFARIESSA GIFTHA ANDREA PITALOKA | D20: 76.9 | E20: 76.9 | F20: =IFERROR((D20*($D$17/100))+(E20*($E$17/100)),"") -> 76.9 | G20: =IFERROR(VLOOKUP(F20,[7]Sheet1!$AA$1:$AB$10,2),"") -> B+
A21: 3 | B21: 24.05.52.0004 | C21: MAHARANI PUTRI RUSTIANTI | D21: 76.9 | E21: 76.9 | F21: =IFERROR((D21*($D$17/100))+(E21*($E$17/100)),"") -> 76.9 | G21: =IFERROR(VLOOKUP(F21,[7]Sheet1!$AA$1:$AB$10,2),"") -> B+
A22: 4 | B22: 24.05.52.0005 | C22: FLORA SUCI FERONIKA | D22: 81.4 | E22: 81.4 | F22: =IFERROR((D22*($D$17/100))+(E22*($E$17/100)),"") -> 81.4 | G22: =IFERROR(VLOOKUP(F22,[7]Sheet1!$AA$1:$AB$10,2),"") -> B+
A23: 5 | B23: 24.05.52.0006 | C23: AATHIRA AUFA AZ-ZAHRA | D23: 76.9 | E23: 76.9 | F23: =IFERROR((D23*($D$17/100))+(E23*($E$17/100)),"") -> 76.9 | G23: =IFERROR(VLOOKUP(F23,[7]Sheet1!$AA$1:$AB$10,2),"") -> B+
A24: 6 | B24: 24.05.52.0007 | C24: SHEILA MONA PUTRI IKSANTI | D24: 85.9 | E24: 85.9 | F24: =IFERROR((D24*($D$17/100))+(E24*($E$17/100)),"") -> 85.9 | G24: =IFERROR(VLOOKUP(F24,[7]Sheet1!$AA$1:$AB$10,2),"") -> A-
A25: 7 | B25: 24.05.52.0008 | C25: RAIHAN RIFA MAHARADITYA | D25: 90.15 | E25: 90.15 | F25: =IFERROR((D25*($D$17/100))+(E25*($E$17/100)),"") -> 90.15 | G25: =IFERROR(VLOOKUP(F25,[7]Sheet1!$AA$1:$AB$10,2),"") -> A-
A26: 8 | B26: 24.05.52.0009 | C26: MARLINA DWI SAPUTRI | D26: 81.4 | E26: 81.4 | F26: =IFERROR((D26*($D$17/100))+(E26*($E$17/100)),"") -> 81.4 | G26: =IFERROR(VLOOKUP(F26,[7]Sheet1!$AA$1:$AB$10,2),"") -> B+
A27: 9 | B27: 24.05.52.0011 | C27: JONATHAN REXY FERDINAN | D27: 81.4 | E27: 81.4 | F27: =IFERROR((D27*($D$17/100))+(E27*($E$17/100)),"") -> 81.4 | G27: =IFERROR(VLOOKUP(F27,[7]Sheet1!$AA$1:$AB$10,2),"") -> B+
A28: 10 | B28: 24.05.52.0012 | C28: GITA TEONANDA ARELLIA | D28: 88.5 | E28: 88.5 | F28: =IFERROR((D28*($D$17/100))+(E28*($E$17/100)),"") -> 88.5 | G28: =IFERROR(VLOOKUP(F28,[7]Sheet1!$AA$1:$AB$10,2),"") -> A-
A29: 11 | B29: 24.05.52.0013 | C29: MUHAMMAD MAFTUF | D29: 81.4 | E29: 81.4 | F29: =IFERROR((D29*($D$17/100))+(E29*($E$17/100)),"") -> 81.4 | G29: =IFERROR(VLOOKUP(F29,[7]Sheet1!$AA$1:$AB$10,2),"") -> B+
A30: 12 | B30: 24.05.52.0014 | C30: ARELIA SALSABILA SAFITRI | D30: 90.4 | E30: 90.4 | F30: =IFERROR((D30*($D$17/100))+(E30*($E$17/100)),"") -> 90.4 | G30: =IFERROR(VLOOKUP(F30,[7]Sheet1!$AA$1:$AB$10,2),"") -> A
A31: 13 | B31: 24.05.52.0015 | C31: JULLER IBEL LAURENTIUS TURNIP | D31: 71.5 | E31: 71.5 | F31: =IFERROR((D31*($D$17/100))+(E31*($E$17/100)),"") -> 71.5 | G31: =IFERROR(VLOOKUP(F31,[7]Sheet1!$AA$1:$AB$10,2),"") -> B
... A52: 34 | B52: 24.05.52.3012 | C52: RORO AYU SUKMAWATI | D52: 47.1 | E52: 47.1 | F52: =IFERROR((D52*($D$17/100))+(E52*($E$17/100)),"") -> 47.1 | G52: =IFERROR(VLOOKUP(F52,[7]Sheet1!$AA$1:$AB$10,2),"") -> D
D54: =D16 -> CPMK12 | E54: =E16 -> CPMK13 | F54: =F12 -> Nilai Akhir MK
C55: Tidak KRS/Tidak Aktif | D55: =IFERROR(COUNTIF(D19:D52,""),"") -> 0 | E55: =IFERROR(COUNTIF(E19:E52,""),"") -> 0 | F55: =IFERROR(COUNTIF(F19:F52,""),"") -> 0
C56: <=65 | D56: =IFERROR(COUNTIF(D19:D52,C56)+COUNTIF(D19:D52,""),"")-D55 -> 2 | E56: =COUNTIF(E19:E52,C56)+COUNTIF(E19:E52,"")-E55 -> 2 | F56: =IFERROR(COUNTIF(F19:F52,C56)+COUNTIF(F19:F52,""),"") -> 2
C57: <85 | D57: =IFERROR(COUNTIF(D19:D52,C57)-D56,"") -> 19 | E57: =COUNTIF(E19:E52,C57)-E56 -> 19 | F57: =IFERROR(COUNTIF(F19:F52,C57)-F56,"") -> 19
C58: >=85 | D58: =COUNTIF(D19:D52,C58) -> 13 | E58: =COUNTIF(E19:E52,C58) -> 13 | F58: =IFERROR(COUNTIF(F19:F52,C58),"") -> 13
C59: Total | D59: =SUM(D55:D58) -> 34 | E59: =SUM(E55:E58) -> 34 | F59: =SUM(F55:F58) -> 34
C61: Jumlah mhsw yg lulus CPMK | D61: =(D57+D58)/(D59-D55) -> 0.94117647 | E61: =(E57+E58)/(E59-E55) -> 0.94117647 | F61: =(F57+F58)/(F59-F55) -> 0.94117647
C63: Minimal | D63: =MIN(D19:D52) -> 47.1 | E63: =MIN(E19:E52) -> 47.1 | F63: =IFERROR(MIN(F19:F52),"") -> 47.1
C64: Maksimal | D64: =MAX(D19:D52) -> 90.4 | E64: =MAX(E19:E52) -> 90.4 | F64: =IFERROR(MAX(F19:F52),"") -> 90.4
C65: Rata-Rata | D65: =AVERAGE(D19:D52) -> 81.225 | E65: =AVERAGE(E19:E52) -> 81.225 | F65: =IFERROR(AVERAGE(F19:F52),"") -> 81.225

Sheet MK16-AGM
A1: FORM MONITORING DAN EVALUASI
A2: KETERCAPAIAN CAPAIAN PEMBELAJARAN MATAKULIAH(CPMK) PADA SATU ANGKATAN
A4: Tahun Akademik | C4: : 2024/2025 | E4: Program Studi | F4: : Akuntansi
A5: Kode Matakuliah | C5: : UU.24.05.52.1.03 | E5: Fakultas | F5: : Ekonomika dan Bisnis
A6: Nama Matakuliah | C6: : English for Business
A7: SKS Matakuliah | C7: : 2
A8: Semester/ Kelas | C8: : I / A1+DLC
A9: Dosen Pengampu | C9: : 1. L.0308 SARAH SUMPONOGATI, S.S, M.Li.
C10: : 2.
D12: MK8 | F12: =CONCATENATE("Nilai Akhir MK"," ",D17+E17) -> Nilai Akhir MK 100 | G12: Nilai Huruf
D13: =TRIM(MID(C5,3,100)) -> UU.24.05.52.1.03
D14: =TRIM(MID(C6,3,100)) -> English for Business
D15: CPL12 | E15: CPL12
D16: CPMK122 | E16: CPMK123
D17: 50 | E17: 50
A18: No | B18: NIM | C18: Nama Mahasiswa
A19: 1 | B19: 24.05.52.0002 | C19: SNEHA JAYA BAIDURI | D19: 93.2 | E19: 97.5 | F19: =IFERROR((D19*($D$17/100))+(E19*($E$17/100)),"") -> 95.35 | G19: =IFERROR(VLOOKUP(F20,[7]Sheet1!$AA$1:$AB$10,2),"") -> A
A20: 2 | B20: 24.05.52.0003 | C20: ALFARIESSA GIFTHA ANDREA PITALOKA | D20: 95.5 | E20: 93.4 | F20: =IFERROR((D20*($D$17/100))+(E20*($E$17/100)),"") -> 94.45 | G20: =IFERROR(VLOOKUP(F20,[8]Sheet1!$AA$1:$AB$10,2),"") -> A
A21: 3 | B21: 24.05.52.0004 | C21: MAHARANI PUTRI RUSTIANTI | D21: 94.7 | E21: 95.9 | F21: =IFERROR((D21*($D$17/100))+(E21*($E$17/100)),"") -> 95.3 | G21: =IFERROR(VLOOKUP(F21,[8]Sheet1!$AA$1:$AB$10,2),"") -> A
A22: 4 | B22: 24.05.52.0005 | C22: FLORA SUCI FERONIKA | D22: 70.5 | E22: 89 | F22: =IFERROR((D22*($D$17/100))+(E22*($E$17/100)),"") -> 79.75 | G22: =IFERROR(VLOOKUP(F22,[8]Sheet1!$AA$1:$AB$10,2),"") -> B+
A23: 5 | B23: 24.05.52.0006 | C23: AATHIRA AUFA AZ-ZAHRA | D23: 70.5 | E23: 89 | F23: =IFERROR((D23*($D$17/100))+(E23*($E$17/100)),"") -> 79.75 | G23: =IFERROR(VLOOKUP(F23,[8]Sheet1!$AA$1:$AB$10,2),"") -> B+
A24: 6 | B24: 24.05.52.0007 | C24: SHEILA MONA PUTRI IKSANTI | D24: 90.4 | E24: 97.5 | F24: =IFERROR((D24*($D$17/100))+(E24*($E$17/100)),"") -> 93.95 | G24: =IFERROR(VLOOKUP(F24,[8]Sheet1!$AA$1:$AB$10,2),"") -> A
A25: 7 | B25: 24.05.52.0008 | C25: RAIHAN RIFA MAHARADITYA | D25: 80.5 | E25: 82.6 | F25: =IFERROR((D25*($D$17/100))+(E25*($E$17/100)),"") -> 81.55 | G25: =IFERROR(VLOOKUP(F25,[8]Sheet1!$AA$1:$AB$10,2),"") -> B+
A26: 8 | B26: 24.05.52.0009 | C26: MARLINA DWI SAPUTRI | D26: 93.2 | E26: 91 | F26: =IFERROR((D26*($D$17/100))+(E26*($E$17/100)),"") -> 92.1 | G26: =IFERROR(VLOOKUP(F26,[8]Sheet1!$AA$1:$AB$10,2),"") -> A
A27: 9 | B27: 24.05.52.0011 | C27: JONATHAN REXY FERDINAN | D27: 91.4 | E27: 91 | F27: =IFERROR((D27*($D$17/100))+(E27*($E$17/100)),"") -> 91.2 | G27: =IFERROR(VLOOKUP(F27,[8]Sheet1!$AA$1:$AB$10,2),"") -> A
A28: 10 | B28: 24.05.52.0012 | C28: GITA TEONANDA ARELLIA | D28: 79.2 | E28: 82.6 | F28: =IFERROR((D28*($D$17/100))+(E28*($E$17/100)),"") -> 80.9 | G28: =IFERROR(VLOOKUP(F28,[8]Sheet1!$AA$1:$AB$10,2),"") -> B+
A29: 11 | B29: 24.05.52.0013 | C29: MUHAMMAD MAFTUF | D29: 92.2 | E29: 95.5 | F29: =IFERROR((D29*($D$17/100))+(E29*($E$17/100)),"") -> 93.85 | G29: =IFERROR(VLOOKUP(F29,[8]Sheet1!$AA$1:$AB$10,2),"") -> A
A30: 12 | B30: 24.05.52.0014 | C30: ARELIA SALSABILA SAFITRI | D30: 90.9 | E30: 95.9 | F30: =IFERROR((D30*($D$17/100))+(E30*($E$17/100)),"") -> 93.4 | G30: =IFERROR(VLOOKUP(F30,[8]Sheet1!$AA$1:$AB$10,2),"") -> A
A31: 13 | B31: 24.05.52.0015 | C31: JULLER IBEL LAURENTIUS TURNIP | D31: 67 | E31: 96 | F31: =IFERROR((D31*($D$17/100))+(E31*($E$17/100)),"") -> 81.5 | G31: =IFERROR(VLOOKUP(F31,[8]Sheet1!$AA$1:$AB$10,2),"") -> B+
... A52: 34 | B52: 24.05.52.3012 | C52: RORO AYU SUKMAWATI | D52: 67.5 | E52: 64 | F52: =IFERROR((D52*($D$17/100))+(E52*($E$17/100)),"") -> 65.75 | G52: =IFERROR(VLOOKUP(F52,[8]Sheet1!$AA$1:$AB$10,2),"") -> B-
D54: =D16 -> CPMK122 | E54: =E16 -> CPMK123 | F54: =F12 -> Nilai Akhir MK 100
C55: Tidak KRS/Tidak Aktif | D55: =IFERROR(COUNTIF(D19:D52,""),"") -> 0 | E55: =IFERROR(COUNTIF(E19:E52,""),"") -> 0 | F55: =IFERROR(COUNTIF(F19:F52,""),"") -> 0
C56: <=65 | D56: =IFERROR(COUNTIF(D19:D52,C56)+COUNTIF(D19:D52,""),"")-D55 -> 0 | E56: =COUNTIF(E19:E52,C56)+COUNTIF(E19:E52,"")-E55 -> 1 | F56: =IFERROR(COUNTIF(F19:F52,C56)+COUNTIF(F19:F52,""),"") -> 0
C57: <85 | D57: =IFERROR(COUNTIF(D19:D52,C57)-D56,"") -> 11 | E57: =COUNTIF(E19:E52,C57)-E56 -> 6 | F57: =IFERROR(COUNTIF(F19:F52,C57)-F56,"") -> 12
C58: >=85 | D58: =COUNTIF(D19:D52,C58) -> 23 | E58: =COUNTIF(E19:E52,C58) -> 27 | F58: =IFERROR(COUNTIF(F19:F52,C58),"") -> 22
C59: Total | D59: =SUM(D55:D58) -> 34 | E59: =SUM(E55:E58) -> 34 | F59: =SUM(F55:F58) -> 34
C61: Jumlah mhsw yg lulus CPMK | D61: =(D57+D58)/(D59-D55) -> 1 | E61: =(E57+E58)/(E59-E55) -> 0.97058824 | F61: =(F57+F58)/(F59-F55) -> 1
C63: Minimal | D63: =MIN(D19:D52) -> 67 | E63: =MIN(E19:E52) -> 64 | F63: =IFERROR(MIN(F19:F52),"") -> 65.75
C64: Maksimal | D64: =MAX(D19:D52) -> 95.5 | E64: =MAX(E19:E52) -> 100 | F64: =IFERROR(MAX(F19:F52),"") -> 95.5
C65: Rata-Rata | D65: =AVERAGE(D19:D52) -> 85.841176 | E65: =AVERAGE(E19:E52) -> 90.432353 | F65: =IFERROR(AVERAGE(F19:F52),"") -> 88.136765

Sheet MK59-KWN
A1: FORM MONITORING DAN EVALUASI
A2: KETERCAPAIAN CAPAIAN PEMBELAJARAN MATAKULIAH(CPMK) PADA SATU ANGKATAN
A4: Tahun Akademik | C4: : 2024/2025 | E4: Program Studi | F4: : Sistem Informasi
A5: Kode Matakuliah | C5: : U.24.01.55.1.03 | E5: Fakultas | F5: : Teknologi Informasi dan Industri
A6: Nama Matakuliah | C6: : KEWARGANEGARAAN
A7: SKS Matakuliah | C7: : 2
A8: Semester/ Kelas | C8: : I / A1+DLC
A9: Dosen Pengampu | C9: : 1.YU.2.03.07.063 - R. SOELISTIJADI, S.SOS, M.Kom.
C10: : 2.
D12: MK59 | G12: =CONCATENATE("Nilai Akhir MK"," ",D17+E17+F17) -> Nilai Akhir MK 100 | H12: Nilai Huruf
D13: =TRIM(MID(C5,3,100)) -> U.24.01.55.1.03
D14: =TRIM(MID(C6,3,100)) -> KEWARGANEGARAAN
D15: CPL10 | E15: CPL12 | F15: CPL14
D16: CPMK101 | E16: CPMK122 | F16: CPMK141
D17: 25 | E17: 45 | F17: 30
A18: No | B18: NIM | C18: Nama Mahasiswa
A19: 1 | B19: 24.01.55.0002 | C19: NADIA SALSABILLA PUTRI
A20: 2 | B20: 24.01.55.0003 | C20: LISA RAHMAWATI | D20: 93.86 | E20: 88.75 | F20: 85 | G20: =IFERROR((D20*($D$17/100))+(E20*($E$17/100))+(F20*($F$17/100)),"") -> 88.9025 | H20: =IFERROR(VLOOKUP(G20,[9]Sheet1!$AA$1:$AB$10,2),"") -> A-
A21: 3 | B21: 24.01.55.0004 | C21: NAZWA FITRI AULIA | D21: 88.21 | E21: 55 | F21: 70 | G21: =IFERROR((D21*($D$17/100))+(E21*($E$17/100))+(F21*($F$17/100)),"") -> 67.8025 | H21: =IFERROR(VLOOKUP(G21,[9]Sheet1!$AA$1:$AB$10,2),"") -> B-
A22: 4 | B22: 24.01.55.0005 | C22: RAFFAEL ANGGARA ARYA DEWA | D22: 87.64 | E22: 69.25 | F22: 59 | G22: =IFERROR((D22*($D$17/100))+(E22*($E$17/100))+(F22*($F$17/100)),"") -> 70.7725 | H22: =IFERROR(VLOOKUP(G22,[9]Sheet1!$AA$1:$AB$10,2),"") -> B
A23: 5 | B23: 24.01.55.0006 | C23: YUMROTUL MUKAROMAH | D23: 91 | E23: 79 | F23: 72 | G23: =IFERROR((D23*($D$17/100))+(E23*($E$17/100))+(F23*($F$17/100)),"") -> 79.9 | H23: =IFERROR(VLOOKUP(G23,[9]Sheet1!$AA$1:$AB$10,2),"") -> B+
A24: 6 | B24: 24.01.55.0007 | C24: USWATUN AULIA PANGESTIKA | D24: 84.64 | E24: 85 | F24: 80 | G24: =IFERROR((D24*($D$17/100))+(E24*($E$17/100))+(F24*($F$17/100)),"") -> 83.41 | H24: =IFERROR(VLOOKUP(G24,[9]Sheet1!$AA$1:$AB$10,2),"") -> B+
A25: 7 | B25: 24.01.55.0008 | C25: VINCENT LISTANEOF SANTOSO | D25: 53.86 | E25: 12.5 | F25: 0 | G25: =IFERROR((D25*($D$17/100))+(E25*($E$17/100))+(F25*($F$17/100)),"") -> 19.09 | H25: =IFERROR(VLOOKUP(G25,[9]Sheet1!$AA$1:$AB$10,2),"") -> E
A26: 8 | B26: 24.01.55.0009 | C26: RETNO AJENG PUSPITASARI | D26: 67.07 | E26: 62.75 | F26: 67 | G26: =IFERROR((D26*($D$17/100))+(E26*($E$17/100))+(F26*($F$17/100)),"") -> 65.105 | H26: =IFERROR(VLOOKUP(G26,[9]Sheet1!$AA$1:$AB$10,2),"") -> C+
A27: 9 | B27: 24.01.55.0010 | C27: IQBAL FAHAR | D27: 85.5 | E27: 86.5 | F27: 82 | G27: =IFERROR((D27*($D$17/100))+(E27*($E$17/100))+(F27*($F$17/100)),"") -> 84.9 | H27: =IFERROR(VLOOKUP(G27,[9]Sheet1!$AA$1:$AB$10,2),"") -> A-
A28: 10 | B28: 24.01.55.0011 | C28: SHABRINA AULIA PUTRI | D28: 78.86 | E28: 86.25 | F28: 85 | G28: =IFERROR((D28*($D$17/100))+(E28*($E$17/100))+(F28*($F$17/100)),"") -> 84.0275 | H28: =IFERROR(VLOOKUP(G28,[9]Sheet1!$AA$1:$AB$10,2),"") -> B+
A29: 11 | B29: 24.01.55.0012 | C29: ADELA PUTRI AJI | D29: 82.64 | E29: 82.5 | F29: 80 | G29: =IFERROR((D29*($D$17/100))+(E29*($E$17/100))+(F29*($F$17/100)),"") -> 81.785 | H29: =IFERROR(VLOOKUP(G29,[9]Sheet1!$AA$1:$AB$10,2),"") -> B+
A30: 12 | B30: 24.01.55.0013 | C30: AMELIA RISKI KURNIAWATI | D30: 75.5 | E30: 79 | F30: 82 | G30: =IFERROR((D30*($D$17/100))+(E30*($E$17/100))+(F30*($F$17/100)),"") -> 79.025 | H30: =IFERROR(VLOOKUP(G30,[9]Sheet1!$AA$1:$AB$10,2),"") -> B+
A31: 13 | B31: 24.01.55.0014 | C31: DAFFA IQBAL MAULANA | D31: 89.93 | E31: 86.5 | F31: 82 | G31: =IFERROR((D31*($D$17/100))+(E31*($E$17/100))+(F31*($F$17/100)),"") -> 86.0075 | H31: =IFERROR(VLOOKUP(G31,[9]Sheet1!$AA$1:$AB$10,2),"") -> A-
... A37: 19 | B37: 24.01.55.3004 | C37: RISTRAWAN WIRAWINELDA | D37: 77.5 | E37: 70.5 | F37: 74 | G37: =IFERROR((D37*($D$17/100))+(E37*($E$17/100))+(F37*($F$17/100)),"") -> 73.3 | H37: =IFERROR(VLOOKUP(G37,[9]Sheet1!$AA$1:$AB$10,2),"") -> B
D39: =D16 -> CPMK101 | E39: =E16 -> CPMK122 | F39: =F16 -> CPMK141 | G39: =G12 -> Nilai Akhir MK 100
C40: Tidak KRS/Tidak Aktif | D40: =IFERROR(COUNTIF(D19:D37,""),"") -> 1 | E40: =IFERROR(COUNTIF(E19:E37,""),"") -> 1 | F40: =IFERROR(COUNTIF(F19:F37,""),"") -> 1 | G40: =IFERROR(COUNTIF(G19:G37,""),"") -> 1
C41: <=65 | D41: =IFERROR(COUNTIF(D19:D37,C41)+COUNTIF(D19:D37,""),"")-D40 -> 1 | E41: =COUNTIF(E19:E37,C41)+COUNTIF(E19:E37,"")-E40 -> 3 | F41: =COUNTIF(F19:F37,C41)+COUNTIF(F19:F37,"")-F40 -> 2 | G41: =IFERROR(COUNTIF(G19:G37,C41)+COUNTIF(G19:G37,""),"") -> 2
C42: <85 | D42: =IFERROR(COUNTIF(D19:D37,C42)-D41,"") -> 11 | E42: =COUNTIF(E19:E37,C42)-E41 -> 10 | F42: =COUNTIF(F19:F37,C42)-F41 -> 14 | G42: =IFERROR(COUNTIF(G19:G37,C42)-G41,"") -> 14
C43: >=85 | D43: =COUNTIF(D19:D37,C43) -> 6 | E43: =COUNTIF(E19:E37,C43) -> 5 | F43: =COUNTIF(F19:F37,C43) -> 2 | G43: =IFERROR(COUNTIF(G19:G37,C43),"") -> 2
C44: Total | D44: =SUM(D40:D43) -> 19 | E44: =SUM(E40:E43) -> 19 | F44: =SUM(F40:F43) -> 19 | G44: =SUM(G40:G43) -> 19
C46: Jumlah mhsw yg lulus CPMK | D46: =(D42+D43)/(D44-D40) -> 0.94444444 | E46: =(E42+E43)/(E44-E40) -> 0.83333333 | F46: =(F42+F43)/(F44-F40) -> 0.88888889 | G46: =(G42+G43)/(G44-G40) -> 0.88888889
C48: Minimal | D48: =MIN(D19:D37) -> 53.86 | E48: =MIN(E19:E37) -> 12.5 | F48: =MIN(F19:F37) -> 0 | G48: =IFERROR(MIN(G19:G37),"") -> 19.09
C49: Maksimal | D49: =MAX(D19:D37) -> 93.86 | E49: =MAX(E19:E37) -> 88.75 | F49: =MAX(F19:F37) -> 85 | G49: =IFERROR(MAX(G19:G37),"") -> 88.9025
C50: Rata-Rata | D50: =AVERAGE(D19:D37) -> 80.412778 | E50: =AVERAGE(E19:E37) -> 73.652778 | F50: =AVERAGE(F19:F37) -> 71.722222 | G50: =IFERROR(AVERAGE(G19:G37),"") -> 74.763611

Sheet Penguk.CPMK-Smt1
A1: Pengukuran CPMK di tingkat mata kuliah pada satu angkatan (2024)
A2: [Mata Kuliah Semester I]
D4: MK1 | F4: Nilai Akhir Matakuliah | G4: MK2 | L4: Nilai Akhir Matakuliah | M4: MK3 | O4: Nilai Akhir Matakuliah | P4: MK4 | R4: Nilai Akhir Matakuliah | S4: MK5 | U4: Nilai Akhir Matakuliah | V4: MK6 | X4: Nilai Akhir Matakuliah | Y4: MK7 | AA4: Nilai Akhir Matakuliah | AB4: MK8 | AD4: Nilai Akhir Matakuliah | AF4: Nilai | AH4: Nilai | AJ4: Nilai | AL4: Nilai | AN4: Nilai | AP4: Nilai | AR4: Nilai | AT4: Nilai | AV4: Nilai | AX4: Nilai | AZ4: Nilai | BB4: Nilai | BD4: Nilai | BF4: Nilai
D5: P.24.05.52.1.01 | G5: P.24.05.52.1.02 | M5: ='ListMKSmt-1'!D4 -> P.24.05.52.1.03 | P5: ='ListMKSmt-1'!D5 -> P.24.05.52.1.04 | S5: ='ListMKSmt-1'!D6 -> P.24.05.52.1.05 | V5: ='ListMKSmt-1'!D7 -> U.24.05.52.1.01 | Y5: ='ListMKSmt-1'!D8 -> U.24.05.52.1.02 | AB5: ='ListMKSmt-1'!D9 -> U.24.05.52.1.03
D6: Akuntansi Pengantar 1 | G6: Perpajakan 1 | M6: ='ListMKSmt-1'!E4 -> Etika Bisnis dan Profesi | P6: ='ListMKSmt-1'!E5 -> Teori Ekonomi | S6: ='ListMKSmt-1'!E6 -> Hukum Bisnis dan Perikatan | V6: ='ListMKSmt-1'!E7 -> Agama | Y6: ='ListMKSmt-1'!E8 -> Kewarganegaraan | AB6: ='ListMKSmt-1'!E9 -> English for Business | AF6: D,G,J,T | AH6: U | AJ6: N,Q | AL6: K | AV6: O,R | AX6: X,AB,AF | BB6: Y,AC,AG | BD6: E,H, L,V | BF6: Z,AD,AH | BJ6: V,W,Y,Z | BP6: U | BX6: N,Q | CD6: K | DX6: O,R | EB6: X,AB,AF | EV6: Y,AC,AG | FF6: E,H,L,V | FJ6: Z,AD,AH
D7: CPL02 | E7: CPL02 | G7: CPL10 | H7: CPL10 | I7: CPL10 | J7: CPL10 | K7: CPL11 | M7: CPL08 | N7: CPL09 | P7: CPL05 | Q7: CPL05 | S7: ='MK5-BP'!D15 -> CPL11 | T7: ='MK5-BP'!E15 -> CPL11 | V7: ='MK7-MBD'!D15 -> CPL01 | W7: ='MK7-MBD'!E15 -> CPL1 | Y7: =MK8_BID!D15 -> CPL01 | Z7: =MK8_BID!E15 -> CPL01 | AB7: ='MK16-AGM'!D15 -> CPL12 | AC7: ='MK16-AGM'!E15 -> CPL12 | AF7: CPL01 | AG7: Capaian (%) | AH7: CPL02 | AI7: Capaian (%) | AJ7: CPL03 | AK7: Capaian (%) | AL7: CPL04 | AM7: Capaian (%) | AN7: CPL05 | AO7: Capaian (%) | AP7: CPL06 | AQ7: Capaian (%) | AR7: CPL07 | AS7: Capaian (%) | AT7: CPL08 | AU7: Capaian (%) | AV7: CPL09 | AW7: Capaian (%) | AX7: CPL10 | AY7: Capaian (%) | AZ7: CPL11 | BA7: Capaian (%) | BB7: CPL12 | BC7: Capaian (%) | BD7: CPL13 | BE7: Capaian (%) | BF7: CPL14 | BG7: Capaian (%) | BJ7: CPL01 | BP7: CPL02 | BX7: CPL03 | CD7: CPL04 | CH7: CPL05 | CX7: CPL06 | DF7: CPL07 | DR7: CPL08 | DX7: CPL09 | EB7: CPL10 | EL7: CPL11 | EV7: CPL12 | FF7: CPL13 | FJ7: CPL14
D8: CPMK021 | E8: CPMK023 | G8: CPMK101 | H8: CPMK102 | I8: CPMK103 | J8: CPMK104 | K8: CPMK111 | M8: CPMK81 | N8: CPMK91 | P8: CPMK55 | Q8: CPMK56 | S8: ='MK5-BP'!D16 -> CPMK114 | T8: ='MK5-BP'!E16 -> CPMK115 | V8: ='MK7-MBD'!D16 -> CPMK11 | W8: ='MK7-MBD'!E16 -> CPMK13 | Y8: =MK8_BID!D16 -> CPMK12 | Z8: =MK8_BID!E16 -> CPMK13 | AB8: ='MK16-AGM'!D16 -> CPMK122 | AC8: ='MK16-AGM'!E16 -> CPMK123 | AE8: SMT-I | AF8: 215 | AH8: =#REF! -> #REF! | AJ8: =P9+S9 -> 100 | AL8: =#REF! -> #REF! | AV8: =Q9+T9 -> 100 | AX8: =Y9+AB9+#REF! -> #REF! | BB8: =#REF!+#REF!+#REF! -> #REF! | BD8: =E9+K9+N9+W9 -> 171 | BF8: =Z9+AC9+#REF! -> #REF! | BJ8: CPMK011 | BK8: % | BL8: CPMK012 | BM8: % | BN8: CPMK013 | BO8: % | BP8: CPMK021 | BQ8: % | BR8: CPMK022 | BS8: % | BT8: CPMK023 | BU8: % | BV8: CPMK024 | BW8: % | BX8: CPMK031 | BY8: % | BZ8: CPMK032 | CA8: % | CB8: CPMK033 | CC8: % | CD8: CPMK041 | CE8: % | CF8: CPMK042 | CG8: % | CH8: CPMK051 | CI8: % | CJ8: CPMK052 | CK8: % | CL8: CPMK053 | CM8: % | CN8: CPMK054 | CO8: % | CP8: CPMK055 | CQ8: % | CR8: CPMK056 | CS8: % | CT8: CPMK057 | CU8: % | CV8: CPMK058 | CW8: % | CX8: CPMK061 | CY8: % | CZ8: CPMK062 | DA8: % | DB8: CPMK063 | DC8: % | DD8: CPMK064 | DE8: % | DF8: CPMK071 | DG8: % | DH8: CPMK072 | DI8: % | DJ8: CPMK073 | DK8: % | DL8: CPMK074 | DM8: % | DN8: CPMK075 | DO8: % | DP8: CPMK076 | DQ8: % | DR8: CPMK081 | DS8: % | DT8: CPMK082 | DU8: % | DV8: CPMK083 | DW8: % | DX8: CPMK091 | DY8: % | DZ8: CPMK092 | EA8: % | EB8: CPMK101 | EC8: % | ED8: CPMK102 | EE8: % | EF8: CPMK103 | EG8: % | EH8: CPMK104 | EI8: % | EJ8: CPMK105 | EK8: % | EL8: CPMK111 | EM8: % | EN8: CPMK112 | EO8: % | EP8: CPMK113 | EQ8: % | ER8: CPMK114 | ES8: % | ET8: CPMK115 | EU8: % | EV8: CPMK121 | EW8: % | EX8: CPMK122 | EY8: % | EZ8: CPMK123 | FA8: % | FB8: CPMK124 | FC8: % | FD8: CPMK125 | FE8: % | FF8: CPMK131 | FG8: % | FH8: CPMK132 | FI8: % | FJ8: CPMK141 | FK8: % | FL8: CPMK142 | FM8: %
C9: =SUM(D9,E9,G9,K9,M9,#REF!,N9,P9,Q9,S9,T9,V9,#REF!,W9,Y9,#REF!,Z9,AB9,#REF!,AC9,#REF!,#REF!,#REF!) -> #REF! | D9: 50 | E9: 50 | G9: 16 | H9: 16 | I9: 26 | J9: 21 | K9: 21 | M9: 50 | N9: 50 | P9: 50 | Q9: 50 | S9: ='MK5-BP'!D17 -> 50 | T9: ='MK5-BP'!E17 -> 50 | V9: ='MK7-MBD'!D17 -> 50 | W9: ='MK7-MBD'!E17 -> 50 | Y9: =MK8_BID!D17 -> 50 | Z9: =MK8_BID!E17 -> 50 | AB9: ='MK16-AGM'!D17 -> 50 | AC9: ='MK16-AGM'!E17 -> 50 | BJ9: =V9 -> 50 | BL9: =Y9 -> 50 | BN9: =Z9 -> 50 | BP9: =D9 -> 50 | BT9: =E9 -> 50 | CP9: =P9 -> 50 | CR9: 50 | DR9: 50 | DX9: =Q9 -> 50 | EB9: 16 | ED9: 16 | EF9: =I9 -> 26 | EH9: =J9 -> 21 | EL9: =K9 -> 21 | ER9: =S9 -> 50 | ET9: =T9 -> 50 | EX9: =AB9 -> 50 | EZ9: =AC9 -> 50 | FF9: =E9+K9+N9+W9 -> 171 | FJ9: =AC9+#REF! -> #REF! | FL9: =Z9 -> 50 | FN9: =SUM(BJ9:FL9) -> #REF!
A10: No | B10: NIM | C10: Nama Mahasiswa
