Workbook

Sheet Mhsw2024
A1: No | B1: NIM | C1: Nama Mahasiswa
A2: 1 | B2: 24.05.52.0002 | C2: SNEHA JAYA BAIDURI
A3: 2 | B3: 24.05.52.0003 | C3: ALFARIESSA GIFTHA ANDREA PITALOKA
A4: 3 | B4: 24.05.52.0004 | C4: MAHARANI PUTRI RUSTIANTI
A5: 4 | B5: 24.05.52.0005 | C5: FLORA SUCI FERONIKA
A6: 5 | B6: 24.05.52.0006 | C6: AATHIRA AUFA AZ-ZAHRA
A7: 6 | B7: 24.05.52.0007 | C7: SHEILA MONA PUTRI IKSANTI
A8: 7 | B8: 24.05.52.0008 | C8: RAIHAN RIFA MAHARADITYA
A9: 8 | B9: 24.05.52.0009 | C9: MARLINA DWI SAPUTRI
A10: 9 | B10: 24.05.52.0011 | C10: JONATHAN REXY FERDINAN
A11: 10 | B11: 24.05.52.0012 | C11: GITA TEONANDA ARELLIA
A12: 11 | B12: 24.05.52.0013 | C12: MUHAMMAD MAFTUF
A13: 12 | B13: 24.05.52.0014 | C13: ARELIA SALSABILA SAFITRI
... A37: 36 | B37: 24.05.52.3012 | C37: RORO AYU SUKMAWATI

Sheet ListMKSmt-1
A1: No | B1: ID | C1: Smtr | D1: Kode Matakuliah | E1: Nama Matakuliah | F1: Kategori | G1: SKS | H1: 1 | I1: 2 | J1: 3 | K1: 4 | L1: 5 | M1: 6 | N1: 7 | O1: 8 | AF1: No | AH1: Kode Matakuliah | AI1: Nama Matakuliah | AJ1: Kategori | AK1: SKS | AL1: 1 | AM1: 2 | AN1: 3 | AO1: 4 | AP1: 5 | AQ1: 6 | AR1: 7 | AS1: 8
A2: 1 | B2: MK9 | C2: 2 | D2: P.24.05.52.2.06 | E2: Akuntansi Pengantar 2 | F2: Wajib | G2: 3 | H2: V | AF2: 1 | AG2: MK1 | AH2: P.20.01.55.1.01 | AI2: TEORI MANAJEMEN | AJ2: Wajib | AK2: 2 | AL2: V
A3: 2 | B3: MK10 | C3: 2 | D3: P.24.05.52.2.07 | E3: Perpajakan 2 | F3: Wajib | G3: 3 | H3: V | AF3: 2 | AG3: MK2 | AH3: P.20.01.55.1.02 | AI3: TEORI ORGANISASI | AJ3: Wajib | AK3: 2 | AL3: V
A4: 3 | B4: MK11 | C4: 2 | D4: P.24.05.52.2.08 | E4: Akuntansi Sektor Publik | F4: Wajib | G4: 3 | H4: V | AF4: 3 | AG4: MK3 | AH4: P.20.01.55.1.03 | AI4: KONSEP SISTEM DAN TEKNOLOGI INFORMASI | AJ4: Wajib | AK4: 2 | AL4: V
A5: 4 | B5: MK12 | C5: 2 | D5: P.24.05.52.2.09 | E5: Akuntansi Perbankan | F5: Wajib | G5: 3 | H5: V | AF5: 4 | AG5: MK4 | AH5: P.20.01.55.1.04 | AI5: LOGIKA DAN ALGORITMA | AJ5: Wajib | AK5: 3 | AL5: V
A6: 5 | B6: MK13 | C6: 2 | D6: P.24.05.52.2.10 | E6: Akuntansi Biaya | F6: Wajib | G6: 3 | H6: V | AF6: 5 | AG6: MK5 | AH6: P.20.01.55.1.05 | AI6: BAHASA PEMROGRAMAN | AJ6: Wajib | AK6: 2 | AL6: V
A7: 6 | B7: MK14 | C7: 2 | D7: U.24.05.52.2.04 | E7: Pancasila | F7: Wajib | G7: 2 | H7: V | AF7: 6 | AG7: MK6 | AH7: P.20.01.55.1.06 | AI7: LOGIKA MATEMATIKA | AJ7: Wajib | AK7: 3 | AL7: V
A8: 7 | B8: MK15 | C8: 2 | D8: U.24.05.52.2.05 | E8: Bahasa Indonesia | F8: Wajib | G8: 2 | H8: V | AF8: 7 | AG8: MK7 | AH8: P.20.01.55.1.07 | AI8: MANAJEMEN BASIS DATA | AJ8: Wajib | AK8: 3 | AL8: V
AF9: 8 | AG9: MK8 | AH9: U.20.01.55.1.01 | AI9: BAHASA INGGRIS DASAR | AJ9: Wajib | AK9: 2 | AL9: V
A10: =SUM(G2:G8) -> 19 | AF10: 9 | AG10: MK9 | AH10: P.20.01.55.2.08 | AI10: ANALISA SISTEM INFORMASI | AJ10: Wajib | AK10: 3 | AM10: V

Sheet MK1-TM
A1: FORM MONITORING DAN EVALUASI
A2: KETERCAPAIAN CAPAIAN PEMBELAJARAN MATAKULIAH(CPMK) PADA SATU ANGKATAN
A4: Tahun Akademik | C4: : 2024/2025 | G4: Program Studi | I4: : Akuntansi
A5: Kode Matakuliah | C5: : P.24.05.52.2.06 | G5: Fakultas | I5: : Ekonomika dan Bisnis
A6: Nama Matakuliah | C6: : Akuntansi Pengantar 2
A7: SKS Matakuliah | C7: : 3
A8: Semester/ Kelas | C8: : I / A1+DLC
A9: Dosen Pengampu | C9: : 1. Y.2.00.04.114 CAHYANI NUSWANDARI, SE., M.Si., Ak CA
C10: : 2.Y.2.92.07.083 Dr. CEACILIA SRIMINDARTI, S.Pd, M.Si
D12: MK9 | I12: Nilai Akhir MK | J12: Nilai Huruf
D13: P.24.05.52.1.06
D14: Akuntansi Pengantar 2
D15: CPL02 | E15: =D15 -> CPL02 | F15: CPL02 | G15: CPL02 | H15: CPL02
D16: CPMK021 | E16: CPMK022 | F16: CPMK023 | G16: CPMK024 | H16: CPMK025
D17: 21 | E17: 22 | F17: 23 | G17: 24 | H17: 25
A18: No | B18: NIM | C18: Nama Mahasiswa
A19: 1 | B19: 24.05.52.0002 | C19: SNEHA JAYA BAIDURI | D19: 89.75 | E19: 89.73 | F19: 90.3 | G19: 60.95 | H19: 61.96 | I19: =IFERROR((D19*($D$17/100))+(E19*($E$17/100))+(F19*($F$17/100))+(G19*($G$17/100))+(H19*($H$17/100)),"") -> 89.4751 | J19: =IFERROR(VLOOKUP(I19,[1]Sheet1!$AA$1:$AB$10,2),"") -> A-
A20: 2 | B20: 24.05.52.0003 | C20: ALFARIESSA GIFTHA ANDREA PITALOKA | D20: 92.5 | E20: 93 | F20: 92.25 | G20: 80.91 | H20: 82.96 | I20: =IFERROR((D20*($D$17/100))+(E20*($E$17/100))+(F20*($F$17/100))+(G20*($G$17/100))+(H20*($H$17/100)),"") -> 101.2609 | J20: =IFERROR(VLOOKUP(I20,[1]Sheet1!$AA$1:$AB$10,2),"") -> A
A21: 3 | B21: 24.05.52.0004 | C21: MAHARANI PUTRI RUSTIANTI | D21: 75.63 | E21: 74.67 | F21: 72.25 | G21: 66.82 | H21: 67.59 | I21: =IFERROR((D21*($D$17/100))+(E21*($E$17/100))+(F21*($F$17/100))+(G21*($G$17/100))+(H21*($H$17/100)),"") -> 81.8615 | J21: =IFERROR(VLOOKUP(I21,[1]Sheet1!$AA$1:$AB$10,2),"") -> B+
A22: 4 | B22: 24.05.52.0005 | C22: FLORA SUCI FERONIKA | D22: 62.88 | E22: 61.4 | F22: 58.3 | G22: 65.95 | H22: 67.33 | I22: =IFERROR((D22*($D$17/100))+(E22*($E$17/100))+(F22*($F$17/100))+(G22*($G$17/100))+(H22*($H$17/100)),"") -> 72.7823 | J22: =IFERROR(VLOOKUP(I22,[1]Sheet1!$AA$1:$AB$10,2),"") -> B
A23: 5 | B23: 24.05.52.0006 | C23: AATHIRA AUFA AZ-ZAHRA | D23: 76.88 | E23: 76 | F23: 74.25 | G23: 65.45 | H23: 66.11 | I23: =IFERROR((D23*($D$17/100))+(E23*($E$17/100))+(F23*($F$17/100))+(G23*($G$17/100))+(H23*($H$17/100)),"") -> 82.1778 | J23: =IFERROR(VLOOKUP(I23,[1]Sheet1!$AA$1:$AB$10,2),"") -> B+
A24: 6 | B24: 24.05.52.0007 | C24: SHEILA MONA PUTRI IKSANTI | D24: 45.38 | E24: 42.4 | F24: 37.05 | G24: 54.14 | H24: 54.56 | I24: =IFERROR((D24*($D$17/100))+(E24*($E$17/100))+(F24*($F$17/100))+(G24*($G$17/100))+(H24*($H$17/100)),"") -> 54.0129 | J24: =IFERROR(VLOOKUP(I24,[1]Sheet1!$AA$1:$AB$10,2),"") -> C-
A25: 7 | B25: 24.05.52.0008 | C25: RAIHAN RIFA MAHARADITYA | D25: 89.38 | E25: 89.33 | F25: 89.25 | G25: 78.18 | H25: 80 | I25: =IFERROR((D25*($D$17/100))+(E25*($E$17/100))+(F25*($F$17/100))+(G25*($G$17/100))+(H25*($H$17/100)),"") -> 97.7131 | J25: =IFERROR(VLOOKUP(I25,[1]Sheet1!$AA$1:$AB$10,2),"") -> A
A26: 8 | B26: 24.05.52.0009 | C26: MARLINA DWI SAPUTRI | D26: 70.38 | E26: 69.07 | F26: 65.15 | G26: 62.05 | H26: 62.41 | I26: =IFERROR((D26*($D$17/100))+(E26*($E$17/100))+(F26*($F$17/100))+(G26*($G$17/100))+(H26*($H$17/100)),"") -> 75.4542 | J26: =IFERROR(VLOOKUP(I26,[1]Sheet1!$AA$1:$AB$10,2),"") -> B+
A27: 9 | B27: 24.05.52.0011 | C27: JONATHAN REXY FERDINAN | D27: 53 | E27: 50.2 | F27: 45.65 | G27: 48.32 | H27: 47.93 | I27: =IFERROR((D27*($D$17/100))+(E27*($E$17/100))+(F27*($F$17/100))+(G27*($G$17/100))+(H27*($H$17/100)),"") -> 56.2528 | J27: =IFERROR(VLOOKUP(I27,[1]Sheet1!$AA$1:$AB$10,2),"") -> C
A28: 10 | B28: 24.05.52.0012 | C28: GITA TEONANDA ARELLIA | D28: 85.63 | E28: 85.67 | F28: 83.5 | G28: 55.68 | H28: 55.56 | I28: =IFERROR((D28*($D$17/100))+(E28*($E$17/100))+(F28*($F$17/100))+(G28*($G$17/100))+(H28*($H$17/100)),"") -> 83.2879 | J28: =IFERROR(VLOOKUP(I28,[1]Sheet1!$AA$1:$AB$10,2),"") -> B+
A29: 11 | B29: 24.05.52.0013 | C29: MUHAMMAD MAFTUF | D29: 18.88 | E29: 20.13 | F29: 10.35 | G29: 5.09 | H29: 2.07 | I29: =IFERROR((D29*($D$17/100))+(E29*($E$17/100))+(F29*($F$17/100))+(G29*($G$17/100))+(H29*($H$17/100)),"") -> 12.513 | J29: =IFERROR(VLOOKUP(I29,[1]Sheet1!$AA$1:$AB$10,2),"") -> E
A30: 12 | B30: 24.05.52.0014 | C30: ARELIA SALSABILA SAFITRI | D30: 89.13 | E30: 89.07 | F30: 87.65 | G30: 62.5 | H30: 62.96 | I30: =IFERROR((D30*($D$17/100))+(E30*($E$17/100))+(F30*($F$17/100))+(G30*($G$17/100))+(H30*($H$17/100)),"") -> 89.2122 | J30: =IFERROR(VLOOKUP(I30,[1]Sheet1!$AA$1:$AB$10,2),"") -> A-
... A52: 34 | B52: 24.05.52.3010 | C52: PUTRY MEINERS ELISABET FAHIK | D52: 80.25 | E52: 80.47 | F52: 80.27 | G52: 80.55 | H52: 79.44 | I52: =IFERROR((D52*($D$17/100))+(E52*($E$17/100))+(F52*($F$17/100))+(G52*($G$17/100))+(H52*($H$17/100)),"") -> 92.21 | J52: =IFERROR(VLOOKUP(I52,[1]Sheet1!$AA$1:$AB$10,2),"") -> A
A53: 35 | B53: 24.05.52.3011 | C53: AMINATUL AROFAH
A54: 36 | B54: 24.05.52.3012 | C54: RORO AYU SUKMAWATI
D56: =D16 -> CPMK021 | E56: =E16 -> CPMK022 | F56: =F16 -> CPMK023 | G56: =G16 -> CPMK024 | H56: =H16 -> CPMK025 | I56: =I12 -> Nilai Akhir MK
C57: Tidak KRS/ Tidak Aktif | D57: =IFERROR(COUNTIF(D19:D54,""),"") -> 2 | E57: =IFERROR(COUNTIF(E19:E54,""),"") -> 2 | F57: =IFERROR(COUNTIF(F19:F54,""),"") -> 2 | G57: =IFERROR(COUNTIF(G19:G54,""),"") -> 2 | H57: =IFERROR(COUNTIF(H19:H54,""),"") -> 2 | I57: =IFERROR(COUNTIF(I19:I54,""),"") -> 2
C58: <=65 | D58: =IFERROR(COUNTIF(D19:D54,C58)+COUNTIF(D19:D54,""),"")-D57 -> 8 | E58: =IFERROR(COUNTIF(E19:E54,C58)+COUNTIF(E19:E54,""),"")-E57 -> 8 | F58: =IFERROR(COUNTIF(F19:F54,C58)+COUNTIF(F19:F54,""),"")-F57 -> 9 | G58: =IFERROR(COUNTIF(G19:G54,C58)+COUNTIF(G19:G54,""),"")-G57 -> 18 | H58: =IFERROR(COUNTIF(H19:H54,C58)+COUNTIF(H19:H54,""),"")-H57 -> 18 | I58: =IFERROR(COUNTIF(I19:I54,C58)+COUNTIF(I19:I54,""),"")-I57 -> 7
C59: <85 | D59: =IFERROR(COUNTIF(D19:D54,C59)-D58,"") -> 14 | E59: =IFERROR(COUNTIF(E19:E54,C59)-E58,"") -> 14 | F59: =IFERROR(COUNTIF(F19:F54,$C$59)-F58,"") -> 16 | G59: =IFERROR(COUNTIF(G19:G54,$C$59)-G58,"") -> 13 | H59: =IFERROR(COUNTIF(H19:H54,$C$59)-H58,"") -> 13 | I59: =IFERROR(COUNTIF(I19:I54,C59)-I58,"") -> 13
C60: >=85 | D60: =COUNTIF(D19:D54,$C$60) -> 12 | E60: =COUNTIF(E19:E54,$C$60) -> 12 | F60: =COUNTIF(F19:F54,$C$60) -> 9 | G60: =COUNTIF(G19:G54,$C$60) -> 3 | H60: =COUNTIF(H19:H54,$C$60) -> 3 | I60: =IFERROR(COUNTIF(I19:I54,C60),"") -> 14
C61: Total | D61: =SUM(D57:D60) -> 36 | E61: =SUM(E57:E60) -> 36 | F61: =SUM(F57:F60) -> 36 | G61: =SUM(G57:G60) -> 36 | H61: =SUM(H57:H60) -> 36 | I61: =SUM(I57:I60) -> 36
C63: Jumlah mhsw yg lulus CPMK | D63: =(D59+D60)/(D61-D57) -> 0.76470588 | H63: =(H59+H60)/(H61-H57) -> 0.47058824 | I63: =(I59+I60)/(I61-I57) -> 0.79411765
C65: Minimal | D65: =MIN(D19:D54) -> 12.5 | H65: =MIN(H19:H54) -> 2.07 | I65: =IFERROR(MIN(I19:I54),"") -> 12.513
C66: Maksimal | D66: =MAX(D19:D37) -> 92.5 | H66: =MAX(H19:H54) -> 90.04 | I66: =IFERROR(MAX(I19:I54),"") -> 105.2124
...

Sheet MK2-TO
A1: FORM MONITORING DAN EVALUASI
A2: KETERCAPAIAN CAPAIAN PEMBELAJARAN MATAKULIAH(CPMK) PADA SATU ANGKATAN
A4: Tahun Akademik | C4: : 2024/2025 | F4: Program Studi | G4: : Akuntansi
A5: Kode Matakuliah | C5: : P.24.01.52.2.07 | F5: Fakultas | G5: : Ekonomika dan Bisnis
A6: Nama Matakuliah | C6: : Perpajakan 2
A7: SKS Matakuliah | C7: : 2
A8: Semester/ Kelas | C8: : I / A1+DLC
A9: Dosen Pengampu | C9: : 1. YU.2.16.05.101 SARTIKA WULANDARI, S.Pd., M.Si
C10: : 2.Y.2.93.01.090 - JAENI, S.E., M.Si., Ak., CA
D12: MK10 | G12: Nilai Akhir MK | H12: Nilai Huruf
D13: =TRIM(MID(C5,3,100)) -> P.24.01.52.2.07
D14: =TRIM(MID(C6,3,100)) -> Perpajakan 2
D15: CPL10 | E15: CPL10 | F15: CPL11
D16: CPMK101 | E16: CPMK104 | F16: CPMK111
D17: 16 | E17: 45 | F17: 39
A18: No | B18: NIM | C18: Nama Mahasiswa
A19: 1 | B19: 24.05.52.0002 | C19: SNEHA JAYA BAIDURI | D19: 71.88 | E19: 70.56 | F19: 75.64 | G19: =IFERROR((D19*($D$17/100))+(E19*($E$17/100))+(F19*($F$17/100)),"") -> 72.7524 | H19: =IFERROR(VLOOKUP(G19,[2]Sheet1!$AA$1:$AB$10,2),"") -> B
A20: 2 | B20: 24.05.52.0003 | C20: ALFARIESSA GIFTHA ANDREA PITALOKA | D20: 83.75 | E20: 80.22 | F20: 74.62 | G20: =IFERROR((D20*($D$17/100))+(E20*($E$17/100))+(F20*($F$17/100)),"") -> 78.6008 | H20: =IFERROR(VLOOKUP(G20,[2]Sheet1!$AA$1:$AB$10,2),"") -> B+
A21: 3 | B21: 24.05.52.0004 | C21: MAHARANI PUTRI RUSTIANTI | D21: 68.75 | E21: 65.56 | F21: 67.95 | G21: =IFERROR((D21*($D$17/100))+(E21*($E$17/100))+(F21*($F$17/100)),"") -> 67.0025 | H21: =IFERROR(VLOOKUP(G21,[2]Sheet1!$AA$1:$AB$10,2),"") -> B-
A22: 4 | B22: 24.05.52.0005 | C22: FLORA SUCI FERONIKA | D22: 67.5 | E22: 64.89 | F22: 67.95 | G22: =IFERROR((D22*($D$17/100))+(E22*($E$17/100))+(F22*($F$17/100)),"") -> 66.501 | H22: =IFERROR(VLOOKUP(G22,[2]Sheet1!$AA$1:$AB$10,2),"") -> B-
A23: 5 | B23: 24.05.52.0006 | C23: AATHIRA AUFA AZ-ZAHRA | D23: 68.75 | E23: 65.56 | F23: 67.95 | G23: =IFERROR((D23*($D$17/100))+(E23*($E$17/100))+(F23*($F$17/100)),"") -> 67.0025 | H23: =IFERROR(VLOOKUP(G23,[2]Sheet1!$AA$1:$AB$10,2),"") -> B-
A24: 6 | B24: 24.05.52.0007 | C24: SHEILA MONA PUTRI IKSANTI | D24: 80 | E24: 75.56 | F24: 68.21 | G24: =IFERROR((D24*($D$17/100))+(E24*($E$17/100))+(F24*($F$17/100)),"") -> 73.4039 | H24: =IFERROR(VLOOKUP(G24,[2]Sheet1!$AA$1:$AB$10,2),"") -> B
A25: 7 | B25: 24.05.52.0008 | C25: RAIHAN RIFA MAHARADITYA | D25: 85.63 | E25: 86.78 | F25: 88.46 | G25: =IFERROR((D25*($D$17/100))+(E25*($E$17/100))+(F25*($F$17/100)),"") -> 87.2512 | H25: =IFERROR(VLOOKUP(G25,[2]Sheet1!$AA$1:$AB$10,2),"") -> A-
A26: 8 | B26: 24.05.52.0009 | C26: MARLINA DWI SAPUTRI | D26: 75 | E26: 71.11 | F26: 68.21 | G26: =IFERROR((D26*($D$17/100))+(E26*($E$17/100))+(F26*($F$17/100)),"") -> 70.6014 | H26: =IFERROR(VLOOKUP(G26,[2]Sheet1!$AA$1:$AB$10,2),"") -> B
A27: 9 | B27: 24.05.52.0011 | C27: JONATHAN REXY FERDINAN | D27: 78.13 | E27: 76.11 | F27: 74.36 | G27: =IFERROR((D27*($D$17/100))+(E27*($E$17/100))+(F27*($F$17/100)),"") -> 75.7507 | H27: =IFERROR(VLOOKUP(G27,[2]Sheet1!$AA$1:$AB$10,2),"") -> B+
A28: 10 | B28: 24.05.52.0012 | C28: GITA TEONANDA ARELLIA | D28: 82.5 | E28: 81.78 | F28: 85.26 | G28: =IFERROR((D28*($D$17/100))+(E28*($E$17/100))+(F28*($F$17/100)),"") -> 83.2524 | H28: =IFERROR(VLOOKUP(G28,[2]Sheet1!$AA$1:$AB$10,2),"") -> B+
A29: 11 | B29: 24.05.52.0013 | C29: MUHAMMAD MAFTUF | D29: 71.88 | E29: 55 | F29: 10.26 | G29: =IFERROR((D29*($D$17/100))+(E29*($E$17/100))+(F29*($F$17/100)),"") -> 40.2522 | H29: =IFERROR(VLOOKUP(G29,[2]Sheet1!$AA$1:$AB$10,2),"") -> E
A30: 12 | B30: 24.05.52.0014 | C30: ARELIA SALSABILA SAFITRI | D30: 82.5 | E30: 81.78 | F30: 85.26 | G30: =IFERROR((D30*($D$17/100))+(E30*($E$17/100))+(F30*($F$17/100)),"") -> 83.2524 | H30: =IFERROR(VLOOKUP(G30,[2]Sheet1!$AA$1:$AB$10,2),"") -> B+
... A52: 34 | B52: 24.05.52.3010 | C52: PUTRY MEINERS ELISABET FAHIK | D52: 90 | E52: 90.29 | F52: 82.69 | G52: =IFERROR((D52*($D$17/100))+(E52*($E$17/100))+(F52*($F$17/100)),"") -> 87.2796 | H52: =IFERROR(VLOOKUP(G52,[2]Sheet1!$AA$1:$AB$10,2),"") -> A-
A53: 35 | B53: 24.05.52.3011 | C53: AMINATUL AROFAH
A54: 36 | B54: 24.05.52.3012 | C54: RORO AYU SUKMAWATI
D57: =D16 -> CPMK101 | E57: =E16 -> CPMK104 | F57: =F16 -> CPMK111 | G57: Nilai Akhir
C58: Tidak KRS/ Tidak Aktif | D58: =IFERROR(COUNTIF(D19:D54,""),"") -> 2 | E58: =IFERROR(COUNTIF(E19:E54,""),"") -> 2 | F58: =IFERROR(COUNTIF(F19:F54,""),"") -> 2 | G58: =IFERROR(COUNTIF(G19:G54,""),"") -> 2
C59: <=65 | D59: =IFERROR(COUNTIF(D19:D54,C59)+COUNTIF(D19:D54,""),"")-F58 -> 1 | E59: =IFERROR(COUNTIF(E19:E54,C59)+COUNTIF(E19:E54,""),"")-G58 -> 3 | F59: =IFERROR(COUNTIF(F19:F54,C59)+COUNTIF(F19:F54,""),"")-F58 -> 4 | G59: =IFERROR(COUNTIF(G19:G54,C59)+COUNTIF(G19:G54,""),"")-G58 -> 2
C60: <85 | D60: =IFERROR(COUNTIF(D19:D54,C60)-D59,"") -> 25 | E60: =IFERROR(COUNTIF(E19:E54,C60)-E59,"") -> 23 | F60: =IFERROR(COUNTIF(F19:F54,C60)-F59,"") -> 27 | G60: =IFERROR(COUNTIF(G19:G54,C60)-G59,"") -> 25
C61: >=85 | D61: =COUNTIF(D19:D54,C61) -> 8 | E61: =COUNTIF(D19:D54,C61) -> 8 | F61: =IFERROR(COUNTIF(F19:F54,C61),"") -> 3 | G61: =IFERROR(COUNTIF(G19:G54,C61),"") -> 7
C62: Total | D62: =SUM(D58:D61) -> 36 | E62: =SUM(E58:E61) -> 36 | F62: =SUM(F58:F61) -> 36 | G62: =SUM(G58:G61) -> 36
C64: Jumlah mhsw yg lulus CPMK | D64: =(D60+D61)/(D62-D58) -> 0.97058824 | E64: =(E60+E61)/(E62-E58) -> 0.91176471 | F64: =(F60+F61)/(F62-F58) -> 0.88235294 | G64: =(G60+G61)/(G62-G58) -> 0.94117647
C66: Minimal | D66: =MIN(D19:D54) -> 56.13 | E66: =MIN(E19:E54) -> 53.69 | F66: =MIN(F19:F54) -> 10.26 | G66: =IFERROR(MIN(G19:G54),"") -> 40.2522
C67: Maksimal | D67: =MAX(D19:D54) -> 90 | E67: =MAX(E19:E54) -> 90.29 | F67: =MAX(F19:F54) -> 88.46 | G67: =IFERROR(MAX(G19:G54),"") -> 87.2796
...

Sheet MK3-PSTI
A1: FORM MONITORING DAN EVALUASI
A2: KETERCAPAIAN CAPAIAN PEMBELAJARAN MATAKULIAH(CPMK) PADA SATU ANGKATAN
A4: Tahun Akademik | C4: : 2024/2025 | F4: Program Studi | G4: : Akuntansi
A5: Kode Matakuliah | C5: : P.24.05.52.2.08 | F5: Fakultas | G5: : Ekonomika dan Bisnis
A6: Nama Matakuliah | C6: : Akuntansi Sektor Publik
A7: SKS Matakuliah | C7: : 2
A8: Semester/ Kelas | C8: : I / A1+DLC
A9: Dosen Pengampu | C9: : 1.YU.2.16.05.101 SARTIKA WULANDARI, S.Pd., M.Si
C10: : 2.Y.2.87.01.040 - MARYONO, S.E., A.KP, M.M., Ak. CA
D12: MK11 | G12: Nilai Akhir MK | H12: Nilai Huruf
D13: =TRIM(MID(C5,2,20)) -> P.24.05.52.2.08
D14: =TRIM(MID(C6,2,100)) -> Akuntansi Sektor Publik
D15: CPL02 | E15: CPL02 | F15: CPL02
D16: CPMK21 | E16: CPMK24 | F16: CPMK25
D17: 17 | E17: 34 | F17: 49
A18: No | B18: NIM | C18: Nama Mahasiswa
A19: 1 | B19: 24.05.52.0002 | C19: SNEHA JAYA BAIDURI | D19: 80.59 | E19: 78.09 | F19: 78.06 | G19: =IFERROR((D19*($D$17/100))+(E19*($E$17/100))+(F19*($F$17/100)),"") -> 78.5003 | H19: =IFERROR(VLOOKUP(G19,[3]Sheet1!$AA$1:$AB$10,2),"") -> B+
A20: 2 | B20: 24.05.52.0003 | C20: ALFARIESSA GIFTHA ANDREA PITALOKA | D20: 77.06 | E20: 73.97 | F20: 79.18 | G20: =IFERROR((D20*($D$17/100))+(E20*($E$17/100))+(F20*($F$17/100)),"") -> 77.0482 | H20: =IFERROR(VLOOKUP(G20,[2]Sheet1!$AA$1:$AB$10,2),"") -> B+
A21: 3 | B21: 24.05.52.0004 | C21: MAHARANI PUTRI RUSTIANTI | D21: 76.47 | E21: 73.53 | F21: 74.08 | G21: =IFERROR((D21*($D$17/100))+(E21*($E$17/100))+(F21*($F$17/100)),"") -> 74.2993 | H21: =IFERROR(VLOOKUP(G21,[2]Sheet1!$AA$1:$AB$10,2),"") -> B
A22: 4 | B22: 24.05.52.0005 | C22: FLORA SUCI FERONIKA | D22: 64.47 | E22: 58.65 | F22: 73.47 | G22: =IFERROR((D22*($D$17/100))+(E22*($E$17/100))+(F22*($F$17/100)),"") -> 66.9012 | H22: =IFERROR(VLOOKUP(G22,[2]Sheet1!$AA$1:$AB$10,2),"") -> B-
A23: 5 | B23: 24.05.52.0006 | C23: AATHIRA AUFA AZ-ZAHRA | D23: 70.59 | E23: 66.18 | F23: 79.39 | G23: =IFERROR((D23*($D$17/100))+(E23*($E$17/100))+(F23*($F$17/100)),"") -> 73.4026 | H23: =IFERROR(VLOOKUP(G23,[2]Sheet1!$AA$1:$AB$10,2),"") -> B
A24: 6 | B24: 24.05.52.0007 | C24: SHEILA MONA PUTRI IKSANTI | D24: 74.12 | E24: 70.29 | F24: 75.1 | G24: =IFERROR((D24*($D$17/100))+(E24*($E$17/100))+(F24*($F$17/100)),"") -> 73.298 | H24: =IFERROR(VLOOKUP(G24,[2]Sheet1!$AA$1:$AB$10,2),"") -> B
A25: 7 | B25: 24.05.52.0008 | C25: RAIHAN RIFA MAHARADITYA | D25: 86.71 | E25: 85.62 | F25: 82.35 | G25: =IFERROR((D25*($D$17/100))+(E25*($E$17/100))+(F25*($F$17/100)),"") -> 84.203 | H25: =IFERROR(VLOOKUP(G25,[2]Sheet1!$AA$1:$AB$10,2),"") -> B+
A26: 8 | B26: 24.05.52.0009 | C26: MARLINA DWI SAPUTRI | D26: 80.94 | E26: 79.24 | F26: 74.59 | G26: =IFERROR((D26*($D$17/100))+(E26*($E$17/100))+(F26*($F$17/100)),"") -> 77.2505 | H26: =IFERROR(VLOOKUP(G26,[2]Sheet1!$AA$1:$AB$10,2),"") -> B+
A27: 9 | B27: 24.05.52.0011 | C27: JONATHAN REXY FERDINAN | D27: 78.47 | E27: 75.03 | F27: 74.18 | G27: =IFERROR((D27*($D$17/100))+(E27*($E$17/100))+(F27*($F$17/100)),"") -> 75.1983 | H27: =IFERROR(VLOOKUP(G27,[2]Sheet1!$AA$1:$AB$10,2),"") -> B
A28: 10 | B28: 24.05.52.0012 | C28: GITA TEONANDA ARELLIA | D28: 86.12 | E28: 83.71 | F28: 80.92 | G28: =IFERROR((D28*($D$17/100))+(E28*($E$17/100))+(F28*($F$17/100)),"") -> 82.7526 | H28: =IFERROR(VLOOKUP(G28,[2]Sheet1!$AA$1:$AB$10,2),"") -> B+
A29: 11 | B29: 24.05.52.0013 | C29: MUHAMMAD MAFTUF | D29: 70.59 | E29: 66.18 | F29: 15.82 | G29: =IFERROR((D29*($D$17/100))+(E29*($E$17/100))+(F29*($F$17/100)),"") -> 42.2533 | H29: =IFERROR(VLOOKUP(G29,[2]Sheet1!$AA$1:$AB$10,2),"") -> E
A30: 12 | B30: 24.05.52.0014 | C30: ARELIA SALSABILA SAFITRI | D30: 89.06 | E30: 87.38 | F30: 87.35 | G30: =IFERROR((D30*($D$17/100))+(E30*($E$17/100))+(F30*($F$17/100)),"") -> 87.6509 | H30: =IFERROR(VLOOKUP(G30,[2]Sheet1!$AA$1:$AB$10,2),"") -> A-
A31: 13 | B31: 24.05.52.0015 | C31: JULLER IBEL LAURENTIUS TURNIP | D31: 63.76 | E31: 58.12 | F31: 43.88 | G31: =IFERROR((D31*($D$17/100))+(E31*($E$17/100))+(F31*($F$17/100)),"") -> 52.1012 | H31: =IFERROR(VLOOKUP(G31,[2]Sheet1!$AA$1:$AB$10,2),"") -> C-
... A52: 34 | B52: 24.05.52.3010 | C52: PUTRY MEINERS ELISABET FAHIK | D52: 90 | E52: 90.29 | F52: 82.69 | G52: =IFERROR((D52*($D$17/100))+(E52*($E$17/100))+(F52*($F$17/100)),"") -> 86.5167 | H52: =IFERROR(VLOOKUP(G52,[2]Sheet1!$AA$1:$AB$10,2),"") -> A-
A53: 35 | B53: 24.05.52.3011 | C53: AMINATUL AROFAH
A54: 36 | B54: 24.05.52.3012 | C54: RORO AYU SUKMAWATI
D56: =D16 -> CPMK21 | E56: =E16 -> CPMK24 | F56: =F16 -> CPMK25 | G56: =G12 -> Nilai Akhir MK
C57: Tidak KRS/ Tidak Aktif | D57: =IFERROR(COUNTIF(D19:D54,""),"") -> 2 | E57: =IFERROR(COUNTIF(E19:E54,""),"") -> 2 | F57: =IFERROR(COUNTIF(F19:F54,""),"") -> 2 | G57: =IFERROR(COUNTIF(G19:G54,""),"") -> 2
C58: <=65 | D58: =IFERROR(COUNTIF(D19:D54,$C$58)+COUNTIF(D19:D54,""),"")-D57 -> 2 | E58: =IFERROR(COUNTIF(E19:E54,$C$58)+COUNTIF(E19:E54,""),"")-E57 -> 2 | F58: =IFERROR(COUNTIF(F19:F54,$C$58)+COUNTIF(F19:F54,""),"")-F57 -> 4 | G58: =IFERROR(COUNTIF(G19:G54,C58)+COUNTIF(G19:G54,""),"")-G57 -> 3
C59: <85 | D59: =IFERROR(COUNTIF(D19:D54,$C$59)-D58,"") -> 21 | E59: =IFERROR(COUNTIF(E19:E54,$C$59)-E58,"") -> 23 | F59: =IFERROR(COUNTIF(F19:F54,$C$59)-F58,"") -> 28 | G59: =IFERROR(COUNTIF(G19:G54,C59)-G58,"") -> 23
C60: >=85 | D60: =COUNTIF(D19:D54,$C$60) -> 11 | E60: =COUNTIF(E19:E54,$C$60) -> 9 | F60: =COUNTIF(F19:F54,$C$60) -> 2 | G60: =IFERROR(COUNTIF(G19:G54,C60),"") -> 8
C61: Total | D61: =SUM(D57:D60) -> 36 | F61: =SUM(F57:F60) -> 36 | G61: =SUM(G57:G60) -> 36
C63: Jumlah mhsw yg lulus CPMK | D63: =(D59+D60)/(D61-D57) -> 0.94117647 | F63: =(F59+F60)/(F61-F57) -> 0.88235294 | G63: =(G59+G60)/(G61-G57) -> 0.91176471
C65: Minimal | D65: =MIN(D19:D54) -> 63.76 | F65: =MIN(F19:F54) -> 15.82 | G65: =IFERROR(MIN(G19:G54),"") -> 42.2533
...

Sheet MK4-L&A
A1: FORM MONITORING DAN EVALUASI
A2: KETERCAPAIAN CAPAIAN PEMBELAJARAN MATAKULIAH(CPMK) PADA SATU ANGKATAN
A4: Tahun Akademik | C4: : 2024/2025 | E4: Program Studi | G4: : Akuntansi
A5: Kode Matakuliah | C5: : P.24.05.52.2.09 | E5: Fakultas | G5: : Ekonomika dan Bisnis
A6: Nama Matakuliah | C6: : Akuntansi Perbankan
A7: SKS Matakuliah | C7: : 3
A8: Semester/ Kelas | C8: : I / A1+DLC
A9: Dosen Pengampu | C9: : 1. Y.2.87.01.040 - MARYONO, S.E., A.KP, M.M., Ak. CA
C10: : 2. YU.2.03.04.059 RR. TJAHJANING POERWATI, SE., M.Si, Ak, CA
D12: MK12 | G12: Nilai Akhir MK | H12: Nilai Huruf
D13: =TRIM(MID(C5,2,20)) -> P.24.05.52.2.09
D14: =TRIM(MID(C6,2,100)) -> Akuntansi Perbankan
D15: CPL02 | E15: CPL02 | F15: CPL02
D16: CPMK23 | E16: CPMK24 | F16: CPMK25
D17: 18 | E17: 33 | F17: 49
A18: No | B18: NIM | C18: Nama Mahasiswa
A19: 1 | B19: 24.05.52.0002 | C19: SNEHA JAYA BAIDURI | D19: 86.11 | E19: 83.33 | F19: 83.67 | G19: =IFERROR((D19*($D$17/100))+(E19*($E$17/100))+(F19*($F$17/100)),"") -> 83.997 | H19: =IFERROR(VLOOKUP(G21,[4]Sheet1!$AA$1:$AB$10,2),"") -> B+
A20: 2 | B20: 24.05.52.0003 | C20: ALFARIESSA GIFTHA ANDREA PITALOKA | D20: 91.67 | E20: 90.91 | F20: 90.82 | G20: =IFERROR((D20*($D$17/100))+(E20*($E$17/100))+(F20*($F$17/100)),"") -> 91.0027 | H20: =IFERROR(VLOOKUP(G20,[4]Sheet1!$AA$1:$AB$10,2),"") -> A
A21: 3 | B21: 24.05.52.0004 | C21: MAHARANI PUTRI RUSTIANTI | D21: 86.11 | E21: 83.33 | F21: 80.1 | G21: =IFERROR((D21*($D$17/100))+(E21*($E$17/100))+(F21*($F$17/100)),"") -> 82.2477 | H21: =IFERROR(VLOOKUP(G21,[4]Sheet1!$AA$1:$AB$10,2),"") -> B+
A22: 4 | B22: 24.05.52.0005 | C22: FLORA SUCI FERONIKA | D22: 85.11 | E22: 82.79 | F22: 90.33 | G22: =IFERROR((D22*($D$17/100))+(E22*($E$17/100))+(F22*($F$17/100)),"") -> 86.9022 | H22: =IFERROR(VLOOKUP(G22,[4]Sheet1!$AA$1:$AB$10,2),"") -> A-
A23: 5 | B23: 24.05.52.0006 | C23: AATHIRA AUFA AZ-ZAHRA | D23: 86.11 | E23: 83.33 | F23: 90.82 | G23: =IFERROR((D23*($D$17/100))+(E23*($E$17/100))+(F23*($F$17/100)),"") -> 87.5005 | H23: =IFERROR(VLOOKUP(G23,[4]Sheet1!$AA$1:$AB$10,2),"") -> A-
A24: 6 | B24: 24.05.52.0007 | C24: SHEILA MONA PUTRI IKSANTI | D24: 86.11 | E24: 83.33 | F24: 62.24 | G24: =IFERROR((D24*($D$17/100))+(E24*($E$17/100))+(F24*($F$17/100)),"") -> 73.4963 | H24: =IFERROR(VLOOKUP(G24,[4]Sheet1!$AA$1:$AB$10,2),"") -> B
A25: 7 | B25: 24.05.52.0008 | C25: RAIHAN RIFA MAHARADITYA | D25: 91.67 | E25: 90.91 | F25: 80.1 | G25: =IFERROR((D25*($D$17/100))+(E25*($E$17/100))+(F25*($F$17/100)),"") -> 85.7499 | H25: =IFERROR(VLOOKUP(G25,[4]Sheet1!$AA$1:$AB$10,2),"") -> A-
A26: 8 | B26: 24.05.52.0009 | C26: MARLINA DWI SAPUTRI | D26: 86.11 | E26: 83.33 | F26: 87.24 | G26: =IFERROR((D26*($D$17/100))+(E26*($E$17/100))+(F26*($F$17/100)),"") -> 85.7463 | H26: =IFERROR(VLOOKUP(G26,[4]Sheet1!$AA$1:$AB$10,2),"") -> A-
A27: 9 | B27: 24.05.52.0011 | C27: JONATHAN REXY FERDINAN | D27: 91.67 | E27: 90.91 | F27: 80.1 | G27: =IFERROR((D27*($D$17/100))+(E27*($E$17/100))+(F27*($F$17/100)),"") -> 85.7499 | H27: =IFERROR(VLOOKUP(G27,[4]Sheet1!$AA$1:$AB$10,2),"") -> A-
A28: 10 | B28: 24.05.52.0012 | C28: GITA TEONANDA ARELLIA | D28: 91.67 | E28: 90.91 | F28: 80.1 | G28: =IFERROR((D28*($D$17/100))+(E28*($E$17/100))+(F28*($F$17/100)),"") -> 85.7499 | H28: =IFERROR(VLOOKUP(G28,[4]Sheet1!$AA$1:$AB$10,2),"") -> A-
A29: 11 | B29: 24.05.52.0013 | C29: MUHAMMAD MAFTUF | D29: 86.11 | E29: 83.33 | F29: 26.53 | G29: =IFERROR((D29*($D$17/100))+(E29*($E$17/100))+(F29*($F$17/100)),"") -> 55.9984 | H29: =IFERROR(VLOOKUP(G29,[4]Sheet1!$AA$1:$AB$10,2),"") -> C
A30: 12 | B30: 24.05.52.0014 | C30: ARELIA SALSABILA SAFITRI | D30: 91.67 | E30: 90.91 | F30: 80.1 | G30: =IFERROR((D30*($D$17/100))+(E30*($E$17/100))+(F30*($F$17/100)),"") -> 85.7499 | H30: =IFERROR(VLOOKUP(G30,[4]Sheet1!$AA$1:$AB$10,2),"") -> A-
A31: 13 | B31: 24.05.52.0015 | C31: JULLER IBEL LAURENTIUS TURNIP | D31: 36.5 | E31: 19.91 | F31: 52.57 | G31: =IFERROR((D31*($D$17/100))+(E31*($E$17/100))+(F31*($F$17/100)),"") -> 38.8996 | H31: =IFERROR(VLOOKUP(G31,[4]Sheet1!$AA$1:$AB$10,2),"") -> E
... A52: 34 | B52: 24.05.52.3010 | C52: PUTRY MEINERS ELISABET FAHIK | D52: 83.89 | E52: 82.27 | F52: 87.24 | G52: =IFERROR((D52*($D$17/100))+(E52*($E$17/100))+(F52*($F$17/100)),"") -> 84.9969 | H52: =IFERROR(VLOOKUP(G52,[4]Sheet1!$AA$1:$AB$10,2),"") -> A-
A53: 35 | B53: 24.05.52.3011 | C53: AMINATUL AROFAH
A54: 36 | B54: 24.05.52.3012 | C54: RORO AYU SUKMAWATI
D56: =D16 -> CPMK23 | E56: =E16 -> CPMK24 | F56: =F16 -> CPMK25 | G56: =G12 -> Nilai Akhir MK
C57: Tidak KRS/Tidak Aktif | D57: =IFERROR(COUNTIF(D19:D54,""),"") -> 2 | E57: =IFERROR(COUNTIF(E19:E54,""),"") -> 2 | F57: =IFERROR(COUNTIF(F19:F54,""),"") -> 2 | G57: =IFERROR(COUNTIF(G19:G54,""),"") -> 2
C58: <=65 | D58: =IFERROR(COUNTIF(D19:D54,$C$58)+COUNTIF(D19:D54,""),"")-D57 -> 1 | E58: =IFERROR(COUNTIF(E19:E54,$C$58)+COUNTIF(E19:E54,""),"")-E57 -> 1 | F58: =IFERROR(COUNTIF(F19:F54,$C$58)+COUNTIF(F19:F54,""),"")-F57 -> 6 | G58: =IFERROR(COUNTIF(G19:G54,C58)+COUNTIF(G19:G54,""),"") -> 4
C59: <85 | D59: =IFERROR(COUNTIF(D19:D54,$C$59)-D58,"") -> 5 | E59: =IFERROR(COUNTIF(E19:E54,$C$59)-E58,"") -> 17 | F59: =IFERROR(COUNTIF(F19:F54,$C$59)-F58,"") -> 13 | G59: =IFERROR(COUNTIF(G19:G54,C59)-G58,"") -> 13
C60: >=85 | D60: =COUNTIF(D19:D54,$C$60) -> 28 | E60: =COUNTIF(E19:E54,$C$60) -> 16 | F60: =COUNTIF(F19:F54,$C$60) -> 15 | G60: =IFERROR(COUNTIF(G19:G54,C60),"") -> 17
C61: Total | D61: =SUM(D57:D60) -> 36 | E61: =SUM(E57:E60) -> 36 | F61: =SUM(F57:F60) -> 36 | G61: =SUM(G57:G60) -> 36
C63: Jumlah mhsw yg lulus CPMK | D63: =(D59+D60)/(D61-D57) -> 0.97058824 | F63: =(F59+F60)/(F61-F57) -> 0.82352941 | G63: =(G59+G60)/(G61-G57) -> 0.88235294
C65: Minimal | D65: =MIN(D19:D54) -> 36.5 | F65: =MIN(F19:F54) -> 26.53 | G65: =IFERROR(MIN(G19:G54),"") -> 38.8996
...

Sheet MK5-BP
A1: FORM MONITORING DAN EVALUASI
A2: KETERCAPAIAN CAPAIAN PEMBELAJARAN MATAKULIAH(CPMK) PADA SATU ANGKATAN
A4: Tahun Akademik | C4: : 2024/2025 | E4: Program Studi | F4: : Akuntansi
A5: Kode Matakuliah | C5: : P.24.05.52.2.10 | E5: Fakultas | F5: : Ekonomika dan Bisnis
A6: Nama Matakuliah | C6: : Akuntansi Biaya
A7: SKS Matakuliah | C7: : 3
A8: Semester/ Kelas | C8: : I / A1+DLC
A9: Dosen Pengampu | C9: : 1. Y.2.92.07.083 Dr. CEACILIA SRIMINDARTI, S.Pd, M.Si
C10: : 2. YU.2.01.10.038 IDA NURHAYATI , SE., M.Si
D12: MK13 | F12: Nilai Akhir MK | G12: Nilai Huruf
D13: =TRIM(MID(C5,2,20)) -> P.24.05.52.2.10
D14: =TRIM(MID(C6,2,100)) -> Akuntansi Biaya
D15: CPL04 | E15: CPL04
D16: CPMK41 | E16: CPMK42
D17: 50 | E17: 50
A18: No | B18: NIM | C18: Nama Mahasiswa
A19: 1 | B19: 24.05.52.0002 | C19: SNEHA JAYA BAIDURI | D19: 69.2 | E19: 68.2 | F19: =IFERROR((D19*($D$17/100))+(E19*($E$17/100)),"") -> 68.7 | G19: =IFERROR(VLOOKUP(F21,[4]Sheet1!$AA$1:$AB$10,2),"") -> B-
A20: 2 | B20: 24.05.52.0003 | C20: ALFARIESSA GIFTHA ANDREA PITALOKA | D20: 82 | E20: 82 | F20: =IFERROR((D20*($D$17/100))+(E20*($E$17/100)),"") -> 82 | G20: =IFERROR(VLOOKUP(F20,[5]Sheet1!$AA$1:$AB$10,2),"") -> B+
A21: 3 | B21: 24.05.52.0004 | C21: MAHARANI PUTRI RUSTIANTI | D21: 68.1 | E21: 67.6 | F21: =IFERROR((D21*($D$17/100))+(E21*($E$17/100)),"") -> 67.85 | G21: =IFERROR(VLOOKUP(F21,[5]Sheet1!$AA$1:$AB$10,2),"") -> B-
A22: 4 | B22: 24.05.52.0005 | C22: FLORA SUCI FERONIKA | D22: 66.2 | E22: 66.2 | F22: =IFERROR((D22*($D$17/100))+(E22*($E$17/100)),"") -> 66.2 | G22: =IFERROR(VLOOKUP(F22,[5]Sheet1!$AA$1:$AB$10,2),"") -> B-
A23: 5 | B23: 24.05.52.0006 | C23: AATHIRA AUFA AZ-ZAHRA | D23: 76.7 | E23: 75.5 | F23: =IFERROR((D23*($D$17/100))+(E23*($E$17/100)),"") -> 76.1 | G23: =IFERROR(VLOOKUP(F23,[5]Sheet1!$AA$1:$AB$10,2),"") -> B+
A24: 6 | B24: 24.05.52.0007 | C24: SHEILA MONA PUTRI IKSANTI | D24: 68.8 | E24: 67.5 | F24: =IFERROR((D24*($D$17/100))+(E24*($E$17/100)),"") -> 68.15 | G24: =IFERROR(VLOOKUP(F24,[5]Sheet1!$AA$1:$AB$10,2),"") -> B-
A25: 7 | B25: 24.05.52.0008 | C25: RAIHAN RIFA MAHARADITYA | D25: 88.9 | E25: 88.1 | F25: =IFERROR((D25*($D$17/100))+(E25*($E$17/100)),"") -> 88.5 | G25: =IFERROR(VLOOKUP(F25,[5]Sheet1!$AA$1:$AB$10,2),"") -> A-
A26: 8 | B26: 24.05.52.0009 | C26: MARLINA DWI SAPUTRI | D26: 71.6 | E26: 71.6 | F26: =IFERROR((D26*($D$17/100))+(E26*($E$17/100)),"") -> 71.6 | G26: =IFERROR(VLOOKUP(F26,[5]Sheet1!$AA$1:$AB$10,2),"") -> B
A27: 9 | B27: 24.05.52.0011 | C27: JONATHAN REXY FERDINAN | D27: 69.5 | E27: 68.7 | F27: =IFERROR((D27*($D$17/100))+(E27*($E$17/100)),"") -> 69.1 | G27: =IFERROR(VLOOKUP(F27,[5]Sheet1!$AA$1:$AB$10,2),"") -> B-
A28: 10 | B28: 24.05.52.0012 | C28: GITA TEONANDA ARELLIA | D28: 73.7 | E28: 73 | F28: =IFERROR((D28*($D$17/100))+(E28*($E$17/100)),"") -> 73.35 | G28: =IFERROR(VLOOKUP(F28,[5]Sheet1!$AA$1:$AB$10,2),"") -> B
A29: 11 | B29: 24.05.52.0013 | C29: MUHAMMAD MAFTUF | D29: 14.3 | E29: 6.3 | F29: =IFERROR((D29*($D$17/100))+(E29*($E$17/100)),"") -> 10.3 | G29: =IFERROR(VLOOKUP(F29,[5]Sheet1!$AA$1:$AB$10,2),"") -> E
A30: 12 | B30: 24.05.52.0014 | C30: ARELIA SALSABILA SAFITRI | D30: 82.9 | E30: 82.9 | F30: =IFERROR((D30*($D$17/100))+(E30*($E$17/100)),"") -> 82.9 | G30: =IFERROR(VLOOKUP(F30,[5]Sheet1!$AA$1:$AB$10,2),"") -> B+
A31: 13 | B31: 24.05.52.0015 | C31: JULLER IBEL LAURENTIUS TURNIP | D31: 50.6 | E31: 50.6 | F31: =IFERROR((D31*($D$17/100))+(E31*($E$17/100)),"") -> 50.6 | G31: =IFERROR(VLOOKUP(F31,[5]Sheet1!$AA$1:$AB$10,2),"") -> C-
... A52: 34 | B52: 24.05.52.3010 | C52: PUTRY MEINERS ELISABET FAHIK | D52: 84.9 | E52: 65.4 | F52: =IFERROR((D52*($D$17/100))+(E52*($E$17/100)),"") -> 75.15 | G52: =IFERROR(VLOOKUP(F52,[5]Sheet1!$AA$1:$AB$10,2),"") -> B
A53: 35 | B53: 24.05.52.3011 | C53: AMINATUL AROFAH
A54: 36 | B54: 24.05.52.3012 | C54: RORO AYU SUKMAWATI
D56: =D16 -> CPMK41 | E56: =E16 -> CPMK42 | F56: =F12 -> Nilai Akhir MK
C57: Tidak KRS/Tidak Aktif | D57: =IFERROR(COUNTIF(D19:D54,""),"") -> 2 | E57: =IFERROR(COUNTIF(E19:E54,""),"") -> 2 | F57: =IFERROR(COUNTIF(F19:F54,""),"") -> 2
C58: <=65 | D58: =IFERROR(COUNTIF(D19:D54,C58)+COUNTIF(D19:D54,""),"")-D57 -> 2 | E58: =COUNTIF(E19:E54,C58)+COUNTIF(E19:E54,"")-E57 -> 5 | F58: =IFERROR(COUNTIF(F19:F54,C58)+COUNTIF(F19:F54,""),"") -> 5
C59: <85 | D59: =IFERROR(COUNTIF(D19:D54,C59)-D58,"") -> 28 | E59: =COUNTIF(E19:E54,C59)-E58 -> 24 | F59: =IFERROR(COUNTIF(F19:F54,C59)-F58,"") -> 25
C60: >=85 | D60: =COUNTIF(D19:D54,C60) -> 4 | E60: =COUNTIF(E19:E54,C60) -> 5 | F60: =IFERROR(COUNTIF(F19:F54,C60),"") -> 4
C61: Total | D61: =SUM(D57:D60) -> 36 | E61: =SUM(E57:E60) -> 36 | F61: =SUM(F57:F60) -> 36
C63: Jumlah mhsw yg lulus CPMK | D63: =(D59+D60)/(D61-D57) -> 0.94117647 | E63: =(E59+E60)/(E61-E57) -> 0.85294118 | F63: =(F59+F60)/(F61-F57) -> 0.85294118
C65: Minimal | D65: =MIN(D19:D54) -> 14.3 | E65: =MIN(E19:E54) -> 6.3 | F65: =IFERROR(MIN(F19:F54),"") -> 10.3
...

Sheet MK7-MBD
A1: FORM MONITORING DAN EVALUASI
A2: KETERCAPAIAN CAPAIAN PEMBELAJARAN MATAKULIAH(CPMK) PADA SATU ANGKATAN
A4: Tahun Akademik | C4: : 2024/2025 | E4: Program Studi | F4: : Akuntansi
A5: Kode Matakuliah | C5: : U.24.05.52.2.04 | E5: Fakultas | F5: : Ekonomika dan Bisnis
A6: Nama Matakuliah | C6: : Pancasila
A7: SKS Matakuliah | C7: : 2
A8: Semester/ Kelas | C8: : I / A1+DLC
A9: Dosen Pengampu | C9: : 1. YU.2.03.07.063 R. SOELISTIJADI, S.SOS, M.Kom.
D11: MK14 | F11: Nilai Akhir MK | G11: Nilai Huruf
D12: =TRIM(MID(C5,2,20)) -> U.24.05.52.2.04
D13: =TRIM(MID(C6,2,100)) -> Pancasila
D14: CPL01 | E14: CPL1
D15: CPMK11 | E15: CPMK12
D16: 50 | E16: 50
A17: No | B17: NIM | C17: Nama Mahasiswa
A18: 1 | B18: 24.05.52.0002 | C18: SNEHA JAYA BAIDURI | D18: 82.55 | E18: 82.55 | F18: =IFERROR((D18*($D$16/100))+(E18*($E$16/100)),"") -> 82.55 | G18: =IFERROR(VLOOKUP(F20,[4]Sheet1!$AA$1:$AB$10,2),"") -> A
A19: 2 | B19: 24.05.52.0003 | C19: ALFARIESSA GIFTHA ANDREA PITALOKA | D19: 83.6 | E19: 83.6 | F19: =IFERROR((D19*($D$16/100))+(E19*($E$16/100)),"") -> 83.6 | G19: =IFERROR(VLOOKUP(F19,[6]Sheet1!$AA$1:$AB$10,2),"") -> B+
A20: 3 | B20: 24.05.52.0004 | C20: MAHARANI PUTRI RUSTIANTI | D20: 90.5 | E20: 90.5 | F20: =IFERROR((D20*($D$16/100))+(E20*($E$16/100)),"") -> 90.5 | G20: =IFERROR(VLOOKUP(F20,[6]Sheet1!$AA$1:$AB$10,2),"") -> A
A21: 4 | B21: 24.05.52.0005 | C21: FLORA SUCI FERONIKA | D21: 82.2 | E21: 82.2 | F21: =IFERROR((D21*($D$16/100))+(E21*($E$16/100)),"") -> 82.2 | G21: =IFERROR(VLOOKUP(F21,[6]Sheet1!$AA$1:$AB$10,2),"") -> B+
A22: 5 | B22: 24.05.52.0006 | C22: AATHIRA AUFA AZ-ZAHRA | D22: 83.25 | E22: 83.25 | F22: =IFERROR((D22*($D$16/100))+(E22*($E$16/100)),"") -> 83.25 | G22: =IFERROR(VLOOKUP(F22,[6]Sheet1!$AA$1:$AB$10,2),"") -> B+
A23: 6 | B23: 24.05.52.0007 | C23: SHEILA MONA PUTRI IKSANTI | D23: 83.15 | E23: 83.15 | F23: =IFERROR((D23*($D$16/100))+(E23*($E$16/100)),"") -> 83.15 | G23: =IFERROR(VLOOKUP(F23,[6]Sheet1!$AA$1:$AB$10,2),"") -> B+
A24: 7 | B24: 24.05.52.0008 | C24: RAIHAN RIFA MAHARADITYA | D24: 85.7 | E24: 85.7 | F24: =IFERROR((D24*($D$16/100))+(E24*($E$16/100)),"") -> 85.7 | G24: =IFERROR(VLOOKUP(F24,[6]Sheet1!$AA$1:$AB$10,2),"") -> A-
A25: 8 | B25: 24.05.52.0009 | C25: MARLINA DWI SAPUTRI | D25: 77.9 | E25: 77.9 | F25: =IFERROR((D25*($D$16/100))+(E25*($E$16/100)),"") -> 77.9 | G25: =IFERROR(VLOOKUP(F25,[6]Sheet1!$AA$1:$AB$10,2),"") -> B+
A26: 9 | B26: 24.05.52.0011 | C26: JONATHAN REXY FERDINAN | D26: 84.5 | E26: 84.5 | F26: =IFERROR((D26*($D$16/100))+(E26*($E$16/100)),"") -> 84.5 | G26: =IFERROR(VLOOKUP(F26,[6]Sheet1!$AA$1:$AB$10,2),"") -> A-
A27: 10 | B27: 24.05.52.0012 | C27: GITA TEONANDA ARELLIA | D27: 94.15 | E27: 94.15 | F27: =IFERROR((D27*($D$16/100))+(E27*($E$16/100)),"") -> 94.15 | G27: =IFERROR(VLOOKUP(F27,[6]Sheet1!$AA$1:$AB$10,2),"") -> A
A28: 11 | B28: 24.05.52.0013 | C28: MUHAMMAD MAFTUF | D28: 0 | E28: 0 | F28: =IFERROR((D28*($D$16/100))+(E28*($E$16/100)),"") -> 0 | G28: =IFERROR(VLOOKUP(F28,[6]Sheet1!$AA$1:$AB$10,2),"") -> E
A29: 12 | B29: 24.05.52.0014 | C29: ARELIA SALSABILA SAFITRI | D29: 94.15 | E29: 94.15 | F29: =IFERROR((D29*($D$16/100))+(E29*($E$16/100)),"") -> 94.15 | G29: =IFERROR(VLOOKUP(F29,[6]Sheet1!$AA$1:$AB$10,2),"") -> A
A30: 13 | B30: 24.05.52.0015 | C30: JULLER IBEL LAURENTIUS TURNIP | D30: 65.6 | E30: 65.6 | F30: =IFERROR((D30*($D$16/100))+(E30*($E$16/100)),"") -> 65.6 | G30: =IFERROR(VLOOKUP(F30,[6]Sheet1!$AA$1:$AB$10,2),"") -> B-
... A51: 34 | B51: 24.05.52.3010 | C51: PUTRY MEINERS ELISABET FAHIK | D51: 86.5 | E51: 86.5 | F51: =IFERROR((D51*($D$16/100))+(E51*($E$16/100)),"") -> 86.5 | G51: =IFERROR(VLOOKUP(F51,[6]Sheet1!$AA$1:$AB$10,2),"") -> A-
A52: 35 | B52: 24.05.52.3011 | C52: AMINATUL AROFAH
A53: 36 | B53: 24.05.52.3012 | C53: RORO AYU SUKMAWATI
D55: =D15 -> CPMK11 | E55: =E15 -> CPMK12 | F55: =F11 -> Nilai Akhir MK
C56: Tidak KRS/Tidak Aktif | D56: =IFERROR(COUNTIF(D18:D53,""),"") -> 2 | E56: =IFERROR(COUNTIF(E18:E53,""),"") -> 2 | F56: =IFERROR(COUNTIF(F18:F53,""),"") -> 2
C57: <=65 | D57: =IFERROR(COUNTIF(D18:D53,C57)+COUNTIF(D18:D53,""),"")-D56 -> 2 | E57: =COUNTIF(E18:E53,C57)+COUNTIF(E18:E53,"")-E56 -> 2 | F57: =IFERROR(COUNTIF(F18:F53,C57)+COUNTIF(F18:F53,""),"") -> 4
C58: <85 | D58: =IFERROR(COUNTIF(D18:D53,C58)-D57,"") -> 19 | E58: =COUNTIF(E18:E53,C58)-E57 -> 19 | F58: =IFERROR(COUNTIF(F18:F53,C58)-F57,"") -> 17
C59: >=85 | D59: =COUNTIF(D18:D53,C59) -> 13 | E59: =COUNTIF(E18:E53,C59) -> 13 | F59: =IFERROR(COUNTIF(F18:F53,C59),"") -> 13
C60: Total | D60: =SUM(D56:D59) -> 36 | E60: =SUM(E56:E59) -> 36 | F60: =SUM(F56:F59) -> 36
C62: Jumlah mhsw yg lulus CPMK | D62: =(D58+D59)/(D60-D56) -> 0.94117647 | E62: =(E58+E59)/(E60-E56) -> 0.94117647 | F62: =(F58+F59)/(F60-F56) -> 0.88235294
C64: Minimal | D64: =MIN(D18:D53) -> 0 | E64: =MIN(E18:E53) -> 0 | F64: =IFERROR(MIN(F18:F53),"") -> 0
C65: Maksimal | D65: =MAX(D18:D53) -> 94.75 | E65: =MAX(E18:E53) -> 94.75 | F65: =IFERROR(MAX(F18:F53),"") -> 94.75
...

Sheet MK8_BID
A1: FORM MONITORING DAN EVALUASI
A2: KETERCAPAIAN CAPAIAN PEMBELAJARAN MATAKULIAH(CPMK) PADA SATU ANGKATAN
A4: Tahun Akademik | C4: : 2024/2025 | D4: Program Studi | E4: : Akuntansi
A5: Kode Matakuliah | C5: : U.24.05.52.2.05 | D5: Fakultas | E5: : Ekonomika dan Bisnis
A6: Nama Matakuliah | C6: : Bahasa Indonesia
A7: SKS Matakuliah | C7: : 2
A8: Semester/ Kelas | C8: : I / A1+DLC
A9: Dosen Pengampu | C9: : 1.
C10: : 2.
D12: MK15 | E12: Nilai Akhir MK | F12: Nilai Huruf
D13: =TRIM(MID(C5,2,20)) -> U.24.05.52.2.05
D14: =TRIM(MID(C6,2,100)) -> Bahasa Indonesia
D15: CPL01
D16: CPMK12
D17: 100
A18: No | B18: NIM | C18: Nama Mahasiswa
A19: 1 | B19: 24.05.52.0002 | C19: SNEHA JAYA BAIDURI | D19: 81.4 | E19: =IFERROR((D19*($D$17/100)),"") -> 81.4 | F19: =IFERROR(VLOOKUP(E20,[7]Sheet1!$AA$1:$AB$10,2),"") -> B+
A20: 2 | B20: 24.05.52.0003 | C20: ALFARIESSA GIFTHA ANDREA PITALOKA | D20: 76.9 | E20: =IFERROR((D20*($D$17/100)),"") -> 76.9 | F20: =IFERROR(VLOOKUP(E20,[7]Sheet1!$AA$1:$AB$10,2),"") -> B+
A21: 3 | B21: 24.05.52.0004 | C21: MAHARANI PUTRI RUSTIANTI | D21: 76.9 | E21: =IFERROR((D21*($D$17/100)),"") -> 76.9 | F21: =IFERROR(VLOOKUP(E21,[7]Sheet1!$AA$1:$AB$10,2),"") -> B+
A22: 4 | B22: 24.05.52.0005 | C22: FLORA SUCI FERONIKA | D22: 81.4 | E22: =IFERROR((D22*($D$17/100)),"") -> 81.4 | F22: =IFERROR(VLOOKUP(E22,[7]Sheet1!$AA$1:$AB$10,2),"") -> B+
A23: 5 | B23: 24.05.52.0006 | C23: AATHIRA AUFA AZ-ZAHRA | D23: 76.9 | E23: =IFERROR((D23*($D$17/100)),"") -> 76.9 | F23: =IFERROR(VLOOKUP(E23,[7]Sheet1!$AA$1:$AB$10,2),"") -> B+
A24: 6 | B24: 24.05.52.0007 | C24: SHEILA MONA PUTRI IKSANTI | D24: 85.9 | E24: =IFERROR((D24*($D$17/100)),"") -> 85.9 | F24: =IFERROR(VLOOKUP(E24,[7]Sheet1!$AA$1:$AB$10,2),"") -> A-
A25: 7 | B25: 24.05.52.0008 | C25: RAIHAN RIFA MAHARADITYA | D25: 90.15 | E25: =IFERROR((D25*($D$17/100)),"") -> 90.15 | F25: =IFERROR(VLOOKUP(E25,[7]Sheet1!$AA$1:$AB$10,2),"") -> A-
A26: 8 | B26: 24.05.52.0009 | C26: MARLINA DWI SAPUTRI | D26: 81.4 | E26: =IFERROR((D26*($D$17/100)),"") -> 81.4 | F26: =IFERROR(VLOOKUP(E26,[7]Sheet1!$AA$1:$AB$10,2),"") -> B+
A27: 9 | B27: 24.05.52.0011 | C27: JONATHAN REXY FERDINAN | D27: 81.4 | E27: =IFERROR((D27*($D$17/100)),"") -> 81.4 | F27: =IFERROR(VLOOKUP(E27,[7]Sheet1!$AA$1:$AB$10,2),"") -> B+
A28: 10 | B28: 24.05.52.0012 | C28: GITA TEONANDA ARELLIA | D28: 88.5 | E28: =IFERROR((D28*($D$17/100)),"") -> 88.5 | F28: =IFERROR(VLOOKUP(E28,[7]Sheet1!$AA$1:$AB$10,2),"") -> A-
A29: 11 | B29: 24.05.52.0013 | C29: MUHAMMAD MAFTUF | D29: 81.4 | E29: =IFERROR((D29*($D$17/100)),"") -> 81.4 | F29: =IFERROR(VLOOKUP(E29,[7]Sheet1!$AA$1:$AB$10,2),"") -> B+
A30: 12 | B30: 24.05.52.0014 | C30: ARELIA SALSABILA SAFITRI | D30: 90.4 | E30: =IFERROR((D30*($D$17/100)),"") -> 90.4 | F30: =IFERROR(VLOOKUP(E30,[7]Sheet1!$AA$1:$AB$10,2),"") -> A
A31: 13 | B31: 24.05.52.0015 | C31: JULLER IBEL LAURENTIUS TURNIP | D31: 71.5 | E31: =IFERROR((D31*($D$17/100)),"") -> 71.5 | F31: =IFERROR(VLOOKUP(E31,[7]Sheet1!$AA$1:$AB$10,2),"") -> B
... A52: 34 | B52: 24.05.52.3010 | C52: PUTRY MEINERS ELISABET FAHIK | D52: 89.7 | E52: =IFERROR((D52*($D$17/100)),"") -> 89.7 | F52: =IFERROR(VLOOKUP(E52,[7]Sheet1!$AA$1:$AB$10,2),"") -> A-
A53: 35 | B53: 24.05.52.3011 | C53: AMINATUL AROFAH
A54: 36 | B54: 24.05.52.3012 | C54: RORO AYU SUKMAWATI
D56: =D16 -> CPMK12 | E56: =E12 -> Nilai Akhir MK
C57: Tidak KRS/Tidak Aktif | D57: =IFERROR(COUNTIF(D19:D54,""),"") -> 2 | E57: =IFERROR(COUNTIF(E19:E54,""),"") -> 2
C58: <=65 | D58: =IFERROR(COUNTIF(D19:D54,C58)+COUNTIF(D19:D54,""),"")-D57 -> 1 | E58: =IFERROR(COUNTIF(E19:E54,C58)+COUNTIF(E19:E54,""),"") -> 3
C59: <85 | D59: =IFERROR(COUNTIF(D19:D54,C59)-D58,"") -> 19 | E59: =IFERROR(COUNTIF(E19:E54,C59)-E58,"") -> 17
C60: >=85 | D60: =COUNTIF(D19:D54,C60) -> 14 | E60: =IFERROR(COUNTIF(E19:E54,C60),"") -> 14
C61: Total | D61: =SUM(D57:D60) -> 36 | E61: =SUM(E57:E60) -> 36
C63: Jumlah mhsw yg lulus CPMK | D63: =(D59+D60)/(D61-D57) -> 0.97058824 | E63: =(E59+E60)/(E61-E57) -> 0.91176471
C65: Minimal | D65: =MIN(D19:D54) -> 55.8 | E65: =IFERROR(MIN(E19:E54),"") -> 55.8
...

Sheet MK16-AGM
A1: FORM MONITORING DAN EVALUASI
A2: KETERCAPAIAN CAPAIAN PEMBELAJARAN MATAKULIAH(CPMK) PADA SATU ANGKATAN
A4: Tahun Akademik | C4: : 2024/2025 | E4: Program Studi | F4: : Akuntansi
A5: Kode Matakuliah | C5: : UU.24.05.52.1.03 | E5: Fakultas | F5: : Ekonomika dan Bisnis
A6: Nama Matakuliah | C6: : English for Business
A7: SKS Matakuliah | C7: : 2
A8: Semester/ Kelas | C8: : I / A1+DLC
A9: Dosen Pengampu | C9: : 1. L.0308 SARAH SUMPONOGATI, S.S, M.Li.
C10: : 2.
D12: MK8 | F12: =CONCATENATE("Nilai Akhir MK"," ",D17+E17) -> Nilai Akhir MK 100 | G12: Nilai Huruf
D13: =TRIM(MID(C5,3,100)) -> UU.24.05.52.1.03
D14: =TRIM(MID(C6,3,100)) -> English for Business
D15: CPL12 | E15: CPL12
D16: CPMK122 | E16: CPMK123
D17: 50 | E17: 50
A18: No | B18: NIM | C18: Nama Mahasiswa
A19: 1 | B19: 24.05.52.0002 | C19: SNEHA JAYA BAIDURI | D19: 93.2 | E19: 97.5 | F19: =IFERROR((D19*($D$17/100))+(E19*($E$17/100)),"") -> 95.35 | G19: =IFERROR(VLOOKUP(F20,[7]Sheet1!$AA$1:$AB$10,2),"") -> A
A20: 2 | B20: 24.05.52.0003 | C20: ALFARIESSA GIFTHA ANDREA PITALOKA | D20: 95.5 | E20: 93.4 | F20: =IFERROR((D20*($D$17/100))+(E20*($E$17/100)),"") -> 94.45 | G20: =IFERROR(VLOOKUP(F20,[8]Sheet1!$AA$1:$AB$10,2),"") -> A
A21: 3 | B21: 24.05.52.0004 | C21: MAHARANI PUTRI RUSTIANTI | D21: 94.7 | E21: 95.9 | F21: =IFERROR((D21*($D$17/100))+(E21*($E$17/100)),"") -> 95.3 | G21: =IFERROR(VLOOKUP(F21,[8]Sheet1!$AA$1:$AB$10,2),"") -> A
A22: 4 | B22: 24.05.52.0005 | C22: FLORA SUCI FERONIKA | D22: 70.5 | E22: 89 | F22: =IFERROR((D22*($D$17/100))+(E22*($E$17/100)),"") -> 79.75 | G22: =IFERROR(VLOOKUP(F22,[8]Sheet1!$AA$1:$AB$10,2),"") -> B+
A23: 5 | B23: 24.05.52.0006 | C23: AATHIRA AUFA AZ-ZAHRA | D23: 70.5 | E23: 89 | F23: =IFERROR((D23*($D$17/100))+(E23*($E$17/100)),"") -> 79.75 | G23: =IFERROR(VLOOKUP(F23,[8]Sheet1!$AA$1:$AB$10,2),"") -> B+
A24: 6 | B24: 24.05.52.0007 | C24: SHEILA MONA PUTRI IKSANTI | D24: 90.4 | E24: 97.5 | F24: =IFERROR((D24*($D$17/100))+(E24*($E$17/100)),"") -> 93.95 | G24: =IFERROR(VLOOKUP(F24,[8]Sheet1!$AA$1:$AB$10,2),"") -> A
A25: 7 | B25: 24.05.52.0008 | C25: RAIHAN RIFA MAHARADITYA | D25: 80.5 | E25: 82.6 | F25: =IFERROR((D25*($D$17/100))+(E25*($E$17/100)),"") -> 81.55 | G25: =IFERROR(VLOOKUP(F25,[8]Sheet1!$AA$1:$AB$10,2),"") -> B+
A26: 8 | B26: 24.05.52.0009 | C26: MARLINA DWI SAPUTRI | D26: 93.2 | E26: 91 | F26: =IFERROR((D26*($D$17/100))+(E26*($E$17/100)),"") -> 92.1 | G26: =IFERROR(VLOOKUP(F26,[8]Sheet1!$AA$1:$AB$10,2),"") -> A
A27: 9 | B27: 24.05.52.0011 | C27: JONATHAN REXY FERDINAN | D27: 91.4 | E27: 91 | F27: =IFERROR((D27*($D$17/100))+(E27*($E$17/100)),"") -> 91.2 | G27: =IFERROR(VLOOKUP(F27,[8]Sheet1!$AA$1:$AB$10,2),"") -> A
A28: 10 | B28: 24.05.52.0012 | C28: GITA TEONANDA ARELLIA | D28: 79.2 | E28: 82.6 | F28: =IFERROR((D28*($D$17/100))+(E28*($E$17/100)),"") -> 80.9 | G28: =IFERROR(VLOOKUP(F28,[8]Sheet1!$AA$1:$AB$10,2),"") -> B+
A29: 11 | B29: 24.05.52.0013 | C29: MUHAMMAD MAFTUF | D29: 92.2 | E29: 95.5 | F29: =IFERROR((D29*($D$17/100))+(E29*($E$17/100)),"") -> 93.85 | G29: =IFERROR(VLOOKUP(F29,[8]Sheet1!$AA$1:$AB$10,2),"") -> A
A30: 12 | B30: 24.05.52.0014 | C30: ARELIA SALSABILA SAFITRI | D30: 90.9 | E30: 95.9 | F30: =IFERROR((D30*($D$17/100))+(E30*($E$17/100)),"") -> 93.4 | G30: =IFERROR(VLOOKUP(F30,[8]Sheet1!$AA$1:$AB$10,2),"") -> A
A31: 13 | B31: 24.05.52.0015 | C31: JULLER IBEL LAURENTIUS TURNIP | D31: 67 | E31: 96 | F31: =IFERROR((D31*($D$17/100))+(E31*($E$17/100)),"") -> 81.5 | G31: =IFERROR(VLOOKUP(F31,[8]Sheet1!$AA$1:$AB$10,2),"") -> B+
... A52: 34 | B52: 24.05.52.3012 | C52: RORO AYU SUKMAWATI | D52: 67.5 | E52: 64 | F52: =IFERROR((D52*($D$17/100))+(E52*($E$17/100)),"") -> 65.75 | G52: =IFERROR(VLOOKUP(F52,[8]Sheet1!$AA$1:$AB$10,2),"") -> B-
D54: =D16 -> CPMK122 | E54: =E16 -> CPMK123 | F54: =F12 -> Nilai Akhir MK 100
C55: Tidak KRS/Tidak Aktif | D55: =IFERROR(COUNTIF(D19:D52,""),"") -> 0 | E55: =IFERROR(COUNTIF(E19:E52,""),"") -> 0 | F55: =IFERROR(COUNTIF(F19:F52,""),"") -> 0
C56: <=65 | D56: =IFERROR(COUNTIF(D19:D52,C56)+COUNTIF(D19:D52,""),"")-D55 -> 0 | E56: =COUNTIF(E19:E52,C56)+COUNTIF(E19:E52,"")-E55 -> 1 | F56: =IFERROR(COUNTIF(F19:F52,C56)+COUNTIF(F19:F52,""),"") -> 0
C57: <85 | D57: =IFERROR(COUNTIF(D19:D52,C57)-D56,"") -> 11 | E57: =COUNTIF(E19:E52,C57)-E56 -> 6 | F57: =IFERROR(COUNTIF(F19:F52,C57)-F56,"") -> 12
C58: >=85 | D58: =COUNTIF(D19:D52,C58) -> 23 | E58: =COUNTIF(E19:E52,C58) -> 27 | F58: =IFERROR(COUNTIF(F19:F52,C58),"") -> 22
C59: Total | D59: =SUM(D55:D58) -> 34 | E59: =SUM(E55:E58) -> 34 | F59: =SUM(F55:F58) -> 34
C61: Jumlah mhsw yg lulus CPMK | D61: =(D57+D58)/(D59-D55) -> 1 | E61: =(E57+E58)/(E59-E55) -> 0.97058824 | F61: =(F57+F58)/(F59-F55) -> 1
C63: Minimal | D63: =MIN(D19:D52) -> 67 | E63: =MIN(E19:E52) -> 64 | F63: =IFERROR(MIN(F19:F52),"") -> 65.75
C64: Maksimal | D64: =MAX(D19:D52) -> 95.5 | E64: =MAX(E19:E52) -> 100 | F64: =IFERROR(MAX(F19:F52),"") -> 95.5
C65: Rata-Rata | D65: =AVERAGE(D19:D52) -> 85.841176 | E65: =AVERAGE(E19:E52) -> 90.432353 | F65: =IFERROR(AVERAGE(F19:F52),"") -> 88.136765

Sheet MK59-KWN
A1: FORM MONITORING DAN EVALUASI
A2: KETERCAPAIAN CAPAIAN PEMBELAJARAN MATAKULIAH(CPMK) PADA SATU ANGKATAN
A4: Tahun Akademik | C4: : 2024/2025 | E4: Program Studi | F4: : Sistem Informasi
A5: Kode Matakuliah | C5: : U.24.01.55.1.03 | E5: Fakultas | F5: : Teknologi Informasi dan Industri
A6: Nama Matakuliah | C6: : KEWARGANEGARAAN
A7: SKS Matakuliah | C7: : 2
A8: Semester/ Kelas | C8: : I / A1+DLC
A9: Dosen Pengampu | C9: : 1.YU.2.03.07.063 - R. SOELISTIJADI, S.SOS, M.Kom.
C10: : 2.
D12: MK59 | G12: =CONCATENATE("Nilai Akhir MK"," ",D17+E17+F17) -> Nilai Akhir MK 100 | H12: Nilai Huruf
D13: =TRIM(MID(C5,3,100)) -> U.24.01.55.1.03
D14: =TRIM(MID(C6,3,100)) -> KEWARGANEGARAAN
D15: CPL10 | E15: CPL12 | F15: CPL14
D16: CPMK101 | E16: CPMK122 | F16: CPMK141
D17: 25 | E17: 45 | F17: 30
A18: No | B18: NIM | C18: Nama Mahasiswa
A19: 1 | B19: 24.01.55.0002 | C19: NADIA SALSABILLA PUTRI
A20: 2 | B20: 24.01.55.0003 | C20: LISA RAHMAWATI | D20: 93.86 | E20: 88.75 | F20: 85 | G20: =IFERROR((D20*($D$17/100))+(E20*($E$17/100))+(F20*($F$17/100)),"") -> 88.9025 | H20: =IFERROR(VLOOKUP(G20,[9]Sheet1!$AA$1:$AB$10,2),"") -> A-
A21: 3 | B21: 24.01.55.0004 | C21: NAZWA FITRI AULIA | D21: 88.21 | E21: 55 | F21: 70 | G21: =IFERROR((D21*($D$17/100))+(E21*($E$17/100))+(F21*($F$17/100)),"") -> 67.8025 | H21: =IFERROR(VLOOKUP(G21,[9]Sheet1!$AA$1:$AB$10,2),"") -> B-
A22: 4 | B22: 24.01.55.0005 | C22: RAFFAEL ANGGARA ARYA DEWA | D22: 87.64 | E22: 69.25 | F22: 59 | G22: =IFERROR((D22*($D$17/100))+(E22*($E$17/100))+(F22*($F$17/100)),"") -> 70.7725 | H22: =IFERROR(VLOOKUP(G22,[9]Sheet1!$AA$1:$AB$10,2),"") -> B
A23: 5 | B23: 24.01.55.0006 | C23: YUMROTUL MUKAROMAH | D23: 91 | E23: 79 | F23: 72 | G23: =IFERROR((D23*($D$17/100))+(E23*($E$17/100))+(F23*($F$17/100)),"") -> 79.9 | H23: =IFERROR(VLOOKUP(G23,[9]Sheet1!$AA$1:$AB$10,2),"") -> B+
A24: 6 | B24: 24.01.55.0007 | C24: USWATUN AULIA PANGESTIKA | D24: 84.64 | E24: 85 | F24: 80 | G24: =IFERROR((D24*($D$17/100))+(E24*($E$17/100))+(F24*($F$17/100)),"") -> 83.41 | H24: =IFERROR(VLOOKUP(G24,[9]Sheet1!$AA$1:$AB$10,2),"") -> B+
A25: 7 | B25: 24.01.55.0008 | C25: VINCENT LISTANEOF SANTOSO | D25: 53.86 | E25: 12.5 | F25: 0 | G25: =IFERROR((D25*($D$17/100))+(E25*($E$17/100))+(F25*($F$17/100)),"") -> 19.09 | H25: =IFERROR(VLOOKUP(G25,[9]Sheet1!$AA$1:$AB$10,2),"") -> E
A26: 8 | B26: 24.01.55.0009 | C26: RETNO AJENG PUSPITASARI | D26: 67.07 | E26: 62.75 | F26: 67 | G26: =IFERROR((D26*($D$17/100))+(E26*($E$17/100))+(F26*($F$17/100)),"") -> 65.105 | H26: =IFERROR(VLOOKUP(G26,[9]Sheet1!$AA$1:$AB$10,2),"") -> C+
A27: 9 | B27: 24.01.55.0010 | C27: IQBAL FAHAR | D27: 85.5 | E27: 86.5 | F27: 82 | G27: =IFERROR((D27*($D$17/100))+(E27*($E$17/100))+(F27*($F$17/100)),"") -> 84.9 | H27: =IFERROR(VLOOKUP(G27,[9]Sheet1!$AA$1:$AB$10,2),"") -> A-
A28: 10 | B28: 24.01.55.0011 | C28: SHABRINA AULIA PUTRI | D28: 78.86 | E28: 86.25 | F28: 85 | G28: =IFERROR((D28*($D$17/100))+(E28*($E$17/100))+(F28*($F$17/100)),"") -> 84.0275 | H28: =IFERROR(VLOOKUP(G28,[9]Sheet1!$AA$1:$AB$10,2),"") -> B+
A29: 11 | B29: 24.01.55.0012 | C29: ADELA PUTRI AJI | D29: 82.64 | E29: 82.5 | F29: 80 | G29: =IFERROR((D29*($D$17/100))+(E29*($E$17/100))+(F29*($F$17/100)),"") -> 81.785 | H29: =IFERROR(VLOOKUP(G29,[9]Sheet1!$AA$1:$AB$10,2),"") -> B+
A30: 12 | B30: 24.01.55.0013 | C30: AMELIA RISKI KURNIAWATI | D30: 75.5 | E30: 79 | F30: 82 | G30: =IFERROR((D30*($D$17/100))+(E30*($E$17/100))+(F30*($F$17/100)),"") -> 79.025 | H30: =IFERROR(VLOOKUP(G30,[9]Sheet1!$AA$1:$AB$10,2),"") -> B+
A31: 13 | B31: 24.01.55.0014 | C31: DAFFA IQBAL MAULANA | D31: 89.93 | E31: 86.5 | F31: 82 | G31: =IFERROR((D31*($D$17/100))+(E31*($E$17/100))+(F31*($F$17/100)),"") -> 86.0075 | H31: =IFERROR(VLOOKUP(G31,[9]Sheet1!$AA$1:$AB$10,2),"") -> A-
... A37: 19 | B37: 24.01.55.3004 | C37: RISTRAWAN WIRAWINELDA | D37: 77.5 | E37: 70.5 | F37: 74 | G37: =IFERROR((D37*($D$17/100))+(E37*($E$17/100))+(F37*($F$17/100)),"") -> 73.3 | H37: =IFERROR(VLOOKUP(G37,[9]Sheet1!$AA$1:$AB$10,2),"") -> B
D39: =D16 -> CPMK101 | E39: =E16 -> CPMK122 | F39: =F16 -> CPMK141 | G39: =G12 -> Nilai Akhir MK 100
C40: Tidak KRS/Tidak Aktif | D40: =IFERROR(COUNTIF(D19:D37,""),"") -> 1 | E40: =IFERROR(COUNTIF(E19:E37,""),"") -> 1 | F40: =IFERROR(COUNTIF(F19:F37,""),"") -> 1 | G40: =IFERROR(COUNTIF(G19:G37,""),"") -> 1
C41: <=65 | D41: =IFERROR(COUNTIF(D19:D37,C41)+COUNTIF(D19:D37,""),"")-D40 -> 1 | E41: =COUNTIF(E19:E37,C41)+COUNTIF(E19:E37,"")-E40 -> 3 | F41: =COUNTIF(F19:F37,C41)+COUNTIF(F19:F37,"")-F40 -> 2 | G41: =IFERROR(COUNTIF(G19:G37,C41)+COUNTIF(G19:G37,""),"") -> 2
C42: <85 | D42: =IFERROR(COUNTIF(D19:D37,C42)-D41,"") -> 11 | E42: =COUNTIF(E19:E37,C42)-E41 -> 10 | F42: =COUNTIF(F19:F37,C42)-F41 -> 14 | G42: =IFERROR(COUNTIF(G19:G37,C42)-G41,"") -> 14
C43: >=85 | D43: =COUNTIF(D19:D37,C43) -> 6 | E43: =COUNTIF(E19:E37,C43) -> 5 | F43: =COUNTIF(F19:F37,C43) -> 2 | G43: =IFERROR(COUNTIF(G19:G37,C43),"") -> 2
C44: Total | D44: =SUM(D40:D43) -> 19 | E44: =SUM(E40:E43) -> 19 | F44: =SUM(F40:F43) -> 19 | G44: =SUM(G40:G43) -> 19
C46: Jumlah mhsw yg lulus CPMK | D46: =(D42+D43)/(D44-D40) -> 0.94444444 | E46: =(E42+E43)/(E44-E40) -> 0.83333333 | F46: =(F42+F43)/(F44-F40) -> 0.88888889 | G46: =(G42+G43)/(G44-G40) -> 0.88888889
C48: Minimal | D48: =MIN(D19:D37) -> 53.86 | E48: =MIN(E19:E37) -> 12.5 | F48: =MIN(F19:F37) -> 0 | G48: =IFERROR(MIN(G19:G37),"") -> 19.09
C49: Maksimal | D49: =MAX(D19:D37) -> 93.86 | E49: =MAX(E19:E37) -> 88.75 | F49: =MAX(F19:F37) -> 85 | G49: =IFERROR(MAX(G19:G37),"") -> 88.9025
C50: Rata-Rata | D50: =AVERAGE(D19:D37) -> 80.412778 | E50: =AVERAGE(E19:E37) -> 73.652778 | F50: =AVERAGE(F19:F37) -> 71.722222 | G50: =IFERROR(AVERAGE(G19:G37),"") -> 74.763611

Sheet Penguk.CPMK-Smt1
A1: Pengukuran CPMK di tingkat mata kuliah pada satu angkatan (2024)
A2: [Mata Kuliah Semester 2]
D4: ='ListMKSmt-1'!B2 -> MK9 | I4: Nilai Akhir Matakuliah | J4: ='ListMKSmt-1'!B3 -> MK10 | M4: Nilai Akhir Matakuliah | N4: ='ListMKSmt-1'!B4 -> MK11 | Q4: Nilai Akhir Matakuliah | R4: ='ListMKSmt-1'!B5 -> MK12 | U4: Nilai Akhir Matakuliah | V4: ='ListMKSmt-1'!B6 -> MK13 | X4: Nilai Akhir Matakuliah | Y4: MK6 | AA4: Nilai Akhir Matakuliah | AB4: MK7 | AC4: Nilai Akhir Matakuliah | AE4: Nilai | AG4: Nilai | AI4: Nilai | AK4: Nilai | AM4: Nilai | AO4: Nilai | AQ4: Nilai | AS4: Nilai | AU4: Nilai | AW4: Nilai | AY4: Nilai | BA4: Nilai | BC4: Nilai | BE4: Nilai
D5: ='ListMKSmt-1'!D2 -> P.24.05.52.2.06 | J5: ='ListMKSmt-1'!D3 -> P.24.05.52.2.07 | N5: ='ListMKSmt-1'!D4 -> P.24.05.52.2.08 | R5: ='ListMKSmt-1'!D5 -> P.24.05.52.2.09 | V5: ='ListMKSmt-1'!D6 -> P.24.05.52.2.10 | Y5: ='ListMKSmt-1'!D7 -> U.24.05.52.2.04 | AB5: ='ListMKSmt-1'!D8 -> U.24.05.52.2.05
D6: ='ListMKSmt-1'!E2 -> Akuntansi Pengantar 2 | J6: ='ListMKSmt-1'!E3 -> Perpajakan 2 | N6: ='ListMKSmt-1'!E4 -> Akuntansi Sektor Publik | R6: ='ListMKSmt-1'!E5 -> Akuntansi Perbankan | V6: ='ListMKSmt-1'!E6 -> Akuntansi Biaya | Y6: ='ListMKSmt-1'!E7 -> Pancasila | AB6: ='ListMKSmt-1'!E8 -> Bahasa Indonesia | AE6: D,G,J,T | AG6: U | AI6: N,Q | AK6: K | AU6: O,R | AW6: X,AB,AF | BA6: Y,AC,AG | BC6: E,H, L,V | BE6: Z,AD,AH | BI6: Y,Z,AB | BO6: D,N,E,F,R,G,O,S,H,P,T | BY6: N,Q | CE6: K | DY6: O,R | EC6: J,K | EM6: L | EW6: Y,AC,AG | FG6: E,H,L,V | FK6: Z,AD,AH
D7: ='MK1-TM'!D15 -> CPL02 | E7: ='MK1-TM'!E15 -> CPL02 | F7: ='MK1-TM'!F15 -> CPL02 | G7: ='MK1-TM'!G15 -> CPL02 | H7: ='MK1-TM'!H15 -> CPL02 | J7: ='MK2-TO'!D15 -> CPL10 | K7: ='MK2-TO'!E15 -> CPL10 | L7: ='MK2-TO'!F15 -> CPL11 | N7: ='MK3-PSTI'!D15 -> CPL02 | O7: ='MK3-PSTI'!E15 -> CPL02 | P7: ='MK3-PSTI'!F15 -> CPL02 | R7: ='MK4-L&A'!D15 -> CPL02 | S7: ='MK4-L&A'!E15 -> CPL02 | T7: ='MK4-L&A'!F15 -> CPL02 | V7: ='MK5-BP'!D15 -> CPL04 | W7: ='MK5-BP'!E15 -> CPL04 | Y7: ='MK7-MBD'!D14 -> CPL01 | Z7: ='MK7-MBD'!E14 -> CPL1 | AB7: =MK8_BID!D15 -> CPL01 | AE7: CPL01 | AF7: Capaian (%) | AG7: CPL02 | AH7: Capaian (%) | AI7: CPL03 | AJ7: Capaian (%) | AK7: CPL04 | AL7: Capaian (%) | AM7: CPL05 | AN7: Capaian (%) | AO7: CPL06 | AP7: Capaian (%) | AQ7: CPL07 | AR7: Capaian (%) | AS7: CPL08 | AT7: Capaian (%) | AU7: CPL09 | AV7: Capaian (%) | AW7: CPL10 | AX7: Capaian (%) | AY7: CPL11 | AZ7: Capaian (%) | BA7: CPL12 | BB7: Capaian (%) | BC7: CPL13 | BD7: Capaian (%) | BE7: CPL14 | BF7: Capaian (%) | BI7: CPL01 | BO7: CPL02 | BY7: CPL03 | CE7: CPL04 | CI7: CPL05 | CY7: CPL06 | DG7: CPL07 | DS7: CPL08 | DY7: CPL09 | EC7: CPL10 | EM7: CPL11 | EW7: CPL12 | FG7: CPL13 | FK7: CPL14
D8: ='MK1-TM'!D16 -> CPMK021 | E8: ='MK1-TM'!E16 -> CPMK022 | F8: ='MK1-TM'!F16 -> CPMK023 | G8: ='MK1-TM'!G16 -> CPMK024 | H8: ='MK1-TM'!H16 -> CPMK025 | J8: ='MK2-TO'!D16 -> CPMK101 | K8: ='MK2-TO'!E16 -> CPMK104 | L8: ='MK2-TO'!F16 -> CPMK111 | N8: ='MK3-PSTI'!D16 -> CPMK21 | O8: ='MK3-PSTI'!E16 -> CPMK24 | P8: ='MK3-PSTI'!F16 -> CPMK25 | R8: ='MK4-L&A'!D16 -> CPMK23 | S8: ='MK4-L&A'!E16 -> CPMK24 | T8: ='MK4-L&A'!F16 -> CPMK25 | V8: ='MK5-BP'!D16 -> CPMK41 | W8: ='MK5-BP'!E16 -> CPMK42 | Y8: ='MK7-MBD'!D15 -> CPMK11 | Z8: ='MK7-MBD'!E15 -> CPMK12 | AB8: =MK8_BID!D16 -> CPMK12 | AD8: SMT-II | AE8: 215 | AG8: =#REF! -> #REF! | AI8: =R9+V9 -> 68 | AK8: =#REF! -> #REF! | AU8: =T9+W9 -> 99 | AW8: =AB9+#REF!+#REF! -> #REF! | BA8: =#REF!+#REF!+#REF! -> #REF! | BC8: =H9+L9+P9+Z9 -> 163 | BE8: =#REF!+#REF!+#REF! -> #REF! | BI8: CPMK011 | BJ8: % | BK8: CPMK012 | BL8: % | BM8: CPMK013 | BN8: % | BO8: CPMK021 | BP8: % | BQ8: CPMK022 | BR8: % | BS8: CPMK023 | BT8: % | BU8: CPMK024 | BV8: % | BW8: CPMK025 | BY8: CPMK031 | BZ8: % | CA8: CPMK032 | CB8: % | CC8: CPMK033 | CD8: % | CE8: CPMK041 | CF8: % | CG8: CPMK042 | CH8: % | CI8: CPMK051 | CJ8: % | CK8: CPMK052 | CL8: % | CM8: CPMK053 | CN8: % | CO8: CPMK054 | CP8: % | CQ8: CPMK055 | CR8: % | CS8: CPMK056 | CT8: % | CU8: CPMK057 | CV8: % | CW8: CPMK058 | CX8: % | CY8: CPMK061 | CZ8: % | DA8: CPMK062 | DB8: % | DC8: CPMK063 | DD8: % | DE8: CPMK064 | DF8: % | DG8: CPMK071 | DH8: % | DI8: CPMK072 | DJ8: % | DK8: CPMK073 | DL8: % | DM8: CPMK074 | DN8: % | DO8: CPMK075 | DP8: % | DQ8: CPMK076 | DR8: % | DS8: CPMK081 | DT8: % | DU8: CPMK082 | DV8: % | DW8: CPMK083 | DX8: % | DY8: CPMK091 | DZ8: % | EA8: CPMK092 | EB8: % | EC8: CPMK101 | ED8: % | EE8: CPMK102 | EF8: % | EG8: CPMK103 | EH8: % | EI8: CPMK104 | EJ8: % | EK8: CPMK105 | EL8: % | EM8: CPMK111 | EN8: % | EO8: CPMK112 | EP8: % | EQ8: CPMK113 | ER8: % | ES8: CPMK114 | ET8: % | EU8: CPMK115 | EV8: % | EW8: CPMK121 | EX8: % | EY8: CPMK122 | EZ8: % | FA8: CPMK123 | FB8: % | FC8: CPMK124 | FD8: % | FE8: CPMK125 | FF8: % | FG8: CPMK131 | FH8: % | FI8: CPMK132 | FJ8: % | FK8: CPMK141 | FL8: % | FM8: CPMK142 | FN8: %
C9: =SUM(D9,H9,J9,L9,N9,#REF!,P9,R9,T9,V9,W9,Y9,#REF!,Z9,AB9,#REF!,#REF!,#REF!,#REF!,#REF!,#REF!,#REF!,#REF!) -> #REF! | D9: ='MK1-TM'!D17 -> 21 | E9: ='MK1-TM'!E17 -> 22 | F9: ='MK1-TM'!F17 -> 23 | G9: ='MK1-TM'!G17 -> 24 | H9: ='MK1-TM'!H17 -> 25 | J9: ='MK2-TO'!D17 -> 16 | K9: ='MK2-TO'!E17 -> 45 | L9: ='MK2-TO'!F17 -> 39 | N9: ='MK3-PSTI'!D17 -> 17 | O9: ='MK3-PSTI'!E17 -> 34 | P9: ='MK3-PSTI'!F17 -> 49 | R9: ='MK4-L&A'!D17 -> 18 | S9: ='MK4-L&A'!E17 -> 33 | T9: ='MK4-L&A'!F17 -> 49 | V9: ='MK5-BP'!D17 -> 50 | W9: ='MK5-BP'!E17 -> 50 | Y9: ='MK7-MBD'!D16 -> 50 | Z9: ='MK7-MBD'!E16 -> 50 | AB9: =MK8_BID!D17 -> 100 | BI9: =Y9 -> 50 | BK9: =Z9+AB9 -> 150 | BO9: =D9+N9 -> 38 | BQ9: =E9 -> 22 | BS9: =F9+R9 -> 41 | BU9: =G9+O9+S9 -> 91 | BW9: =H9+P9+T9 -> 123 | CE9: =V9 -> 50 | CG9: =W9 -> 50 | CQ9: =R9 -> 18 | CS9: 50 | DS9: 50 | DY9: =T9 -> 49 | EC9: =J9 -> 16 | EE9: 16 | EI9: =K9 -> 45 | EM9: =L9 -> 39 | ES9: =V9 -> 50 | EU9: =W9 -> 50 | FA9: =#REF! -> #REF! | FG9: =H9+L9+P9+Z9 -> 163 | FK9: =#REF!+#REF! -> #REF! | FM9: =#REF! -> #REF! | FO9: =SUM(BI9:FM9) -> #REF!
A10: No | B10: NIM | C10: Nama Mahasiswa
