Workbook

Sheet Mhsw2024
A1: No | B1: NIM | C1: Nama Mahasiswa
A2: 1 | B2: 24.05.52.0002 | C2: SNEHA JAYA BAIDURI
A3: 2 | B3: 24.05.52.0003 | C3: ALFARIESSA GIFTHA ANDREA PITALOKA
A4: 3 | B4: 24.05.52.0004 | C4: MAHARANI PUTRI RUSTIANTI
A5: 4 | B5: 24.05.52.0005 | C5: FLORA SUCI FERONIKA
A6: 5 | B6: 24.05.52.0006 | C6: AATHIRA AUFA AZ-ZAHRA
A7: 6 | B7: 24.05.52.0007 | C7: SHEILA MONA PUTRI IKSANTI
A8: 7 | B8: 24.05.52.0008 | C8: RAIHAN RIFA MAHARADITYA
A9: 8 | B9: 24.05.52.0009 | C9: MARLINA DWI SAPUTRI
A10: 9 | B10: 24.05.52.0011 | C10: JONATHAN REXY FERDINAN
A11: 10 | B11: 24.05.52.0012 | C11: GITA TEONANDA ARELLIA
A12: 11 | B12: 24.05.52.0013 | C12: MUHAMMAD MAFTUF
A13: 12 | B13: 24.05.52.0014 | C13: ARELIA SALSABILA SAFITRI
... A37: 36 | B37: 24.05.52.3012 | C37: RORO AYU SUKMAWATI

Sheet ListMKSmt-1
A1: No | B1: ID | C1: Smtr | D1: Kode Matakuliah | E1: Nama Matakuliah | F1: Kategori | G1: SKS | H1: 1 | I1: 2 | J1: 3 | K1: 4 | L1: 5 | M1: 6 | N1: 7 | O1: 8 | AF1: No | AH1: Kode Matakuliah | AI1: Nama Matakuliah | AJ1: Kategori | AK1: SKS | AL1: 1 | AM1: 2 | AN1: 3 | AO1: 4 | AP1: 5 | AQ1: 6 | AR1: 7 | AS1: 8
A2: 1 | B2: MK16 | C2: I | D2: P.24.05.52.3.11 | E2: Akuntansi Keuangan Menengah 1 | F2: Wajib | G2: 3 | J2: V | AF2: 1 | AG2: MK1 | AH2: P.20.01.55.1.01 | AI2: TEORI MANAJEMEN | AJ2: Wajib | AK2: 2 | AL2: V
A3: 2 | B3: MK17 | C3: I | D3: P.24.05.52.3.12 | E3: Statistika 1 | F3: Wajib | G3: 3 | J3: V | AF3: 2 | AG3: MK2 | AH3: P.20.01.55.1.02 | AI3: TEORI ORGANISASI | AJ3: Wajib | AK3: 2 | AL3: V
A4: 3 | B4: MK18 | C4: I | D4: P.24.05.52.3.13 | E4: Pengauditan 1 | F4: Wajib | G4: 3 | J4: V | AF4: 3 | AG4: MK3 | AH4: P.20.01.55.1.03 | AI4: KONSEP SISTEM DAN TEKNOLOGI INFORMASI | AJ4: Wajib | AK4: 2 | AL4: V
A5: 4 | B5: MK19 | C5: I | D5: P.24.05.52.3.14 | E5: Akuntansi Pajak | F5: Wajib | G5: 2 | J5: V | AF5: 4 | AG5: MK4 | AH5: P.20.01.55.1.04 | AI5: LOGIKA DAN ALGORITMA | AJ5: Wajib | AK5: 3 | AL5: V
A6: 5 | B6: MK20 | C6: I | D6: P.24.05.52.3.15 | E6: Akuntansi Manajemen | F6: Wajib | G6: 3 | J6: V | AF6: 5 | AG6: MK5 | AH6: P.20.01.55.1.05 | AI6: BAHASA PEMROGRAMAN | AJ6: Wajib | AK6: 2 | AL6: V
A7: 6 | B7: MK21 | C7: I | D7: P.24.05.52.3.16 | E7: Manajemen Keuangan | F7: Wajib | G7: 3 | J7: V | AF7: 6 | AG7: MK6 | AH7: P.20.01.55.1.06 | AI7: LOGIKA MATEMATIKA | AJ7: Wajib | AK7: 3 | AL7: V
A8: 7 | B8: MK22 | C8: I | D8: U.24.05.52.3.06 | E8: Entrepreneurship for Start-up | F8: Wajib | G8: 3 | J8: V | AF8: 7 | AG8: MK7 | AH8: P.20.01.55.1.07 | AI8: MANAJEMEN BASIS DATA | AJ8: Wajib | AK8: 3 | AL8: V
A9: =SUM(G2:G8) -> 20 | AF9: 8 | AG9: MK8 | AH9: U.20.01.55.1.01 | AI9: BAHASA INGGRIS DASAR | AJ9: Wajib | AK9: 2 | AL9: V

Sheet MK1-TM
A1: FORM MONITORING DAN EVALUASI
A2: KETERCAPAIAN CAPAIAN PEMBELAJARAN MATAKULIAH(CPMK) PADA SATU ANGKATAN
A4: Tahun Akademik | C4: : 2025/2026 | E4: Program Studi | G4: : Akuntansi
A5: Kode Matakuliah | C5: : P.24.05.52.3.11 | E5: Fakultas | G5: : Ekonomika dan Bisnis
A6: Nama Matakuliah | C6: : Akuntansi Keuangan Menengah 1
A7: SKS Matakuliah | C7: : 3
A8: Semester/ Kelas | C8: : I / A1+DLC
A9: Dosen Pengampu | C9: : 1. Y.2.00.04.114 CAHYANI NUSWANDARI, SE., M.Si., Ak CA
D12: ='ListMKSmt-1'!B2 -> MK16 | G12: Nilai Akhir MK | H12: Nilai Huruf
D13: ='ListMKSmt-1'!D2 -> P.24.05.52.3.11
D14: ='ListMKSmt-1'!E2 -> Akuntansi Keuangan Menengah 1
D15: CPL02 | E15: CPL02 | F15: CPL02
D16: CPMK022 | E16: CPMK024 | F16: CPMK025
D17: 23 | E17: 42 | F17: 35
A18: No | B18: NIM | C18: Nama Mahasiswa
A19: 1 | B19: 24.05.52.0002 | C19: SNEHA JAYA BAIDURI | D19: 83.7 | E19: 82.26 | F19: 88.86 | G19: =IFERROR((D19*($D$17/100))+(E19*($E$17/100))+(F19*($F$17/100)),"") -> 84.9012 | H19: =IFERROR(VLOOKUP(G19,[1]Sheet1!$AA$1:$AB$10,2),"") -> A-
A20: 2 | B20: 24.05.52.0003 | C20: ALFARIESSA GIFTHA ANDREA P | D20: 79.13 | E20: 73.57 | F20: 84.71 | G20: =IFERROR((D20*($D$17/100))+(E20*($E$17/100))+(F20*($F$17/100)),"") -> 78.7478 | H20: =IFERROR(VLOOKUP(G20,[1]Sheet1!$AA$1:$AB$10,2),"") -> B+
A21: 3 | B21: 24.05.52.0004 | C21: MAHARANI PUTRI RUSTIANTI | D21: 78.91 | E21: 72.26 | F21: 74 | G21: =IFERROR((D21*($D$17/100))+(E21*($E$17/100))+(F21*($F$17/100)),"") -> 74.3985 | H21: =IFERROR(VLOOKUP(G21,[1]Sheet1!$AA$1:$AB$10,2),"") -> B
A22: 4 | B22: 24.05.52.0005 | C22: FLORA SUCI FERONIKA | D22: 66.74 | E22: 58.21 | F22: 72.14 | G22: =IFERROR((D22*($D$17/100))+(E22*($E$17/100))+(F22*($F$17/100)),"") -> 65.0474 | H22: =IFERROR(VLOOKUP(G22,[1]Sheet1!$AA$1:$AB$10,2),"") -> C+
A23: 5 | B23: 24.05.52.0006 | C23: AATHIRA AUFA AZ-ZAHRA | D23: 76.3 | E23: 69.64 | F23: 75 | G23: =IFERROR((D23*($D$17/100))+(E23*($E$17/100))+(F23*($F$17/100)),"") -> 73.0478 | H23: =IFERROR(VLOOKUP(G23,[1]Sheet1!$AA$1:$AB$10,2),"") -> B
A24: 6 | B24: 24.05.52.0007 | C24: SHEILA MONA PUTRI IKSANTI | D24: 64.13 | E24: 49.64 | F24: 55 | G24: =IFERROR((D24*($D$17/100))+(E24*($E$17/100))+(F24*($F$17/100)),"") -> 54.8487 | H24: =IFERROR(VLOOKUP(G24,[1]Sheet1!$AA$1:$AB$10,2),"") -> C-
A25: 7 | B25: 24.05.52.0008 | C25: RAIHAN RIFA MAHARADITYA | D25: 92.17 | E25: 80.24 | F25: 61.57 | G25: =IFERROR((D25*($D$17/100))+(E25*($E$17/100))+(F25*($F$17/100)),"") -> 76.4494 | H25: =IFERROR(VLOOKUP(G25,[1]Sheet1!$AA$1:$AB$10,2),"") -> B+
A26: 8 | B26: 24.05.52.0009 | C26: MARLINA DWI SAPUTRI | D26: 72.83 | E26: 67.74 | F26: 80.71 | G26: =IFERROR((D26*($D$17/100))+(E26*($E$17/100))+(F26*($F$17/100)),"") -> 73.4502 | H26: =IFERROR(VLOOKUP(G26,[1]Sheet1!$AA$1:$AB$10,2),"") -> B
A27: 9 | B27: 24.05.52.0011 | C27: JONATHAN REXY FERDINAN | D27: 70.96 | E27: 62.9 | F27: 77.03 | G27: =IFERROR((D27*($D$17/100))+(E27*($E$17/100))+(F27*($F$17/100)),"") -> 69.6993 | H27: =IFERROR(VLOOKUP(G27,[1]Sheet1!$AA$1:$AB$10,2),"") -> B-
A28: 10 | B28: 24.05.52.0012 | C28: GITA TEONANDA ARELLIA | D28: 89.13 | E28: 82.86 | F28: 84.86 | G28: =IFERROR((D28*($D$17/100))+(E28*($E$17/100))+(F28*($F$17/100)),"") -> 85.0021 | H28: =IFERROR(VLOOKUP(G28,[1]Sheet1!$AA$1:$AB$10,2),"") -> A-
A29: 11 | B29: 24.05.52.0014 | C29: ARELIA SALSABILA SAFITRI | D29: 87.91 | E29: 82.67 | F29: 86.31 | G29: =IFERROR((D29*($D$17/100))+(E29*($E$17/100))+(F29*($F$17/100)),"") -> 85.1492 | H29: =IFERROR(VLOOKUP(G29,[1]Sheet1!$AA$1:$AB$10,2),"") -> A-
A30: 12 | B30: 24.05.52.0015 | C30: JULLER IBEL LAURENTIUS TURNIP | D30: 0 | E30: 0 | F30: 0 | G30: =IFERROR((D30*($D$17/100))+(E30*($E$17/100))+(F30*($F$17/100)),"") -> 0 | H30: =IFERROR(VLOOKUP(G30,[1]Sheet1!$AA$1:$AB$10,2),"") -> E
... A50: 32 | B50: 24.05.52.3010 | C50: PUTRY MEINERS ELISABET FAHIK | D50: 90.52 | E50: 88.62 | F50: 84.6 | G50: =IFERROR((D50*($D$17/100))+(E50*($E$17/100))+(F50*($F$17/100)),"") -> 87.65 | H50: =IFERROR(VLOOKUP(G50,[1]Sheet1!$AA$1:$AB$10,2),"") -> A-
D52: =D16 -> CPMK022 | E52: =E16 -> CPMK024 | F52: =F16 -> CPMK025 | G52: =G12 -> Nilai Akhir MK
C53: Tidak KRS/ Tidak Aktif | D53: =IFERROR(COUNTIF(D19:D50,""),"") -> 0 | E53: =IFERROR(COUNTIF(E19:E50,""),"") -> 0 | F53: =IFERROR(COUNTIF(F19:F50,""),"") -> 0 | G53: =IFERROR(COUNTIF(G19:G50,""),"") -> 0
C54: <=65 | D54: =IFERROR(COUNTIF(D19:D50,C54)+COUNTIF(D19:D50,""),"")-D53 -> 3 | E54: =IFERROR(COUNTIF(E19:E50,C54)+COUNTIF(E19:E50,""),"")-E53 -> 6 | F54: =IFERROR(COUNTIF(F19:F50,C54)+COUNTIF(F19:F50,""),"")-F53 -> 6 | G54: =IFERROR(COUNTIF(G19:G50,C54)+COUNTIF(G19:G50,""),"")-G53 -> 4
C55: <85 | D55: =IFERROR(COUNTIF(D19:D50,C55)-D54,"") -> 19 | E55: =IFERROR(COUNTIF(E19:E50,$C$55)-E54,"") -> 21 | F55: =IFERROR(COUNTIF(F19:F50,$C$55)-F54,"") -> 19 | G55: =IFERROR(COUNTIF(G19:G50,C55)-G54,"") -> 21
C56: >=85 | D56: =COUNTIF(D19:D50,$C$56) -> 10 | E56: =COUNTIF(E19:E50,$C$56) -> 5 | F56: =COUNTIF(F19:F50,$C$56) -> 7 | G56: =IFERROR(COUNTIF(G19:G50,C56),"") -> 7
C57: Total | D57: =SUM(D53:D56) -> 32 | E57: =SUM(E53:E56) -> 32 | F57: =SUM(F53:F56) -> 32 | G57: =SUM(G53:G56) -> 32
C59: Jumlah mhsw yg lulus CPMK | D59: =(D55+D56)/(D57-D53) -> 0.90625 | F59: =(F55+F56)/(F57-F53) -> 0.8125 | G59: =(G55+G56)/(G57-G53) -> 0.875
C61: Minimal | D61: =MIN(D19:D50) -> 0 | F61: =MIN(F19:F50) -> 0 | G61: =IFERROR(MIN(G19:G50),"") -> 0
C62: Maksimal | D62: =MAX(D19:D36) -> 93.91 | F62: =MAX(F19:F50) -> 98.29 | G62: =IFERROR(MAX(G19:G50),"") -> 96.5486
C63: Rata-Rata | D63: =AVERAGE(D19:D50) -> 78.403437 | F63: =AVERAGE(F19:F50) -> 74.110938 | G63: =IFERROR(AVERAGE(G19:G50),"") -> 74.513494

Sheet MK2-TO
A1: FORM MONITORING DAN EVALUASI
A2: KETERCAPAIAN CAPAIAN PEMBELAJARAN MATAKULIAH(CPMK) PADA SATU ANGKATAN
A4: Tahun Akademik | C4: : 2025/2026 | E4: Program Studi | F4: : Akuntansi
A5: Kode Matakuliah | C5: : P.24.05.52.3.12 | E5: Fakultas | F5: : Ekonomika dan Bisnis
A6: Nama Matakuliah | C6: : Statistika 1
A7: SKS Matakuliah | C7: : 3
A8: Semester/ Kelas | C8: : I / A1+DLC
A9: Dosen Pengampu | C9: : 1. Y.3.00.05.074 - BATARA DANIEL BAGANA, SE, MM
C10: : 2. Y.2.88.07.047 - GREGORIUS ANGGANA LISIANTARA, SPd, M.M
D12: MK17 | F12: Nilai Akhir MK | G12: Nilai Huruf
D13: ='ListMKSmt-1'!D3 -> P.24.05.52.3.12
D14: =TRIM(MID(C6,3,100)) -> Statistika 1
D15: CPL04 | E15: CPL04
D16: CPMK44 | E16: CPMK46
D17: 50 | E17: 50
A18: No | B18: NIM | C18: Nama Mahasiswa
A19: 1 | B19: 24.05.52.0002 | C19: SNEHA JAYA BAIDURI | D19: 86.5 | E19: 86.5 | F19: =IFERROR((D19*($D$17/100))+(E19*($E$17/100)),"") -> 86.5 | G19: =IFERROR(VLOOKUP(F19,[2]Sheet1!$AA$1:$AB$10,2),"") -> A-
A20: 2 | B20: 24.05.52.0003 | C20: ALFARIESSA GIFTHA ANDREA PITALOKA | D20: 75.7 | E20: 75.7 | F20: =IFERROR((D20*($D$17/100))+(E20*($E$17/100)),"") -> 75.7 | G20: =IFERROR(VLOOKUP(F20,[2]Sheet1!$AA$1:$AB$10,2),"") -> B+
A21: 3 | B21: 24.05.52.0004 | C21: MAHARANI PUTRI RUSTIANTI | D21: 81.3 | E21: 81.3 | F21: =IFERROR((D21*($D$17/100))+(E21*($E$17/100)),"") -> 81.3 | G21: =IFERROR(VLOOKUP(F21,[2]Sheet1!$AA$1:$AB$10,2),"") -> B+
A22: 4 | B22: 24.05.52.0005 | C22: FLORA SUCI FERONIKA | D22: 82 | E22: 70.1 | F22: =IFERROR((D22*($D$17/100))+(E22*($E$17/100)),"") -> 76.05 | G22: =IFERROR(VLOOKUP(F22,[2]Sheet1!$AA$1:$AB$10,2),"") -> B+
A23: 5 | B23: 24.05.52.0006 | C23: AATHIRA AUFA AZ-ZAHRA | D23: 82 | E23: 70.1 | F23: =IFERROR((D23*($D$17/100))+(E23*($E$17/100)),"") -> 76.05 | G23: =IFERROR(VLOOKUP(F23,[2]Sheet1!$AA$1:$AB$10,2),"") -> B+
A24: 6 | B24: 24.05.52.0007 | C24: SHEILA MONA PUTRI IKSANTI | D24: 57.5 | E24: 73.6 | F24: =IFERROR((D24*($D$17/100))+(E24*($E$17/100)),"") -> 65.55 | G24: =IFERROR(VLOOKUP(F24,[2]Sheet1!$AA$1:$AB$10,2),"") -> B-
A25: 7 | B25: 24.05.52.0008 | C25: RAIHAN RIFA MAHARADITYA | D25: 81.3 | E25: 81.3 | F25: =IFERROR((D25*($D$17/100))+(E25*($E$17/100)),"") -> 81.3 | G25: =IFERROR(VLOOKUP(F25,[2]Sheet1!$AA$1:$AB$10,2),"") -> B+
A26: 8 | B26: 24.05.52.0009 | C26: MARLINA DWI SAPUTRI | D26: 73.6 | E26: 68.7 | F26: =IFERROR((D26*($D$17/100))+(E26*($E$17/100)),"") -> 71.15 | G26: =IFERROR(VLOOKUP(F26,[2]Sheet1!$AA$1:$AB$10,2),"") -> B
A27: 9 | B27: 24.05.52.0011 | C27: JONATHAN REXY FERDINAN | D27: 63.1 | E27: 59.6 | F27: =IFERROR((D27*($D$17/100))+(E27*($E$17/100)),"") -> 61.35 | G27: =IFERROR(VLOOKUP(F27,[2]Sheet1!$AA$1:$AB$10,2),"") -> C+
A28: 10 | B28: 24.05.52.0012 | C28: GITA TEONANDA ARELLIA | D28: 77.1 | E28: 74.3 | F28: =IFERROR((D28*($D$17/100))+(E28*($E$17/100)),"") -> 75.7 | G28: =IFERROR(VLOOKUP(F28,[2]Sheet1!$AA$1:$AB$10,2),"") -> B+
A29: 12 | B29: 24.05.52.0014 | C29: ARELIA SALSABILA SAFITRI | D29: 86 | E29: 86 | F29: =IFERROR((D29*($D$17/100))+(E29*($E$17/100)),"") -> 86 | G29: =IFERROR(VLOOKUP(F29,[2]Sheet1!$AA$1:$AB$10,2),"") -> A-
A30: 13 | B30: 24.05.52.0015 | C30: JULLER IBEL LAURENTIUS TURNIP | D30: 0 | E30: 0 | F30: =IFERROR((D30*($D$17/100))+(E30*($E$17/100)),"") -> 0 | G30: =IFERROR(VLOOKUP(F30,[2]Sheet1!$AA$1:$AB$10,2),"") -> E
... A50: 34 | B50: 24.05.52.3010 | C50: PUTRY MEINERS ELISABET FAHIK | D50: 89.3 | E50: 88.4 | F50: =IFERROR((D50*($D$17/100))+(E50*($E$17/100)),"") -> 88.85 | G50: =IFERROR(VLOOKUP(F50,[2]Sheet1!$AA$1:$AB$10,2),"") -> A-
D53: =D16 -> CPMK44 | E53: =E16 -> CPMK46 | F53: Nilai Akhir
C54: Tidak KRS/ Tidak Aktif | D54: =IFERROR(COUNTIF(D19:D50,""),"") -> 0 | E54: =IFERROR(COUNTIF(E19:E50,""),"") -> 0 | F54: =IFERROR(COUNTIF(F19:F50,""),"") -> 0
C55: <=65 | D55: =IFERROR(COUNTIF(D19:D50,C55)+COUNTIF(D19:D50,""),"")-E54 -> 4 | E55: =IFERROR(COUNTIF(E19:E50,C55)+COUNTIF(E19:E50,""),"")-E54 -> 3 | F55: =IFERROR(COUNTIF(F19:F50,C55)+COUNTIF(F19:F50,""),"")-F54 -> 3
C56: <85 | D56: =IFERROR(COUNTIF(D19:D50,C56)-D55,"") -> 17 | E56: =IFERROR(COUNTIF(E19:E50,C56)-E55,"") -> 20 | F56: =IFERROR(COUNTIF(F19:F50,C56)-F55,"") -> 20
C57: >=85 | D57: =COUNTIF(D19:D50,C57) -> 11 | E57: =IFERROR(COUNTIF(E19:E50,C57),"") -> 9 | F57: =IFERROR(COUNTIF(F19:F50,C57),"") -> 9
C58: Total | D58: =SUM(D54:D57) -> 32 | E58: =SUM(E54:E57) -> 32 | F58: =SUM(F54:F57) -> 32
C60: Jumlah mhsw yg lulus CPMK | D60: =(D56+D57)/(D58-D54) -> 0.875 | E60: =(E56+E57)/(E58-E54) -> 0.90625 | F60: =(F56+F57)/(F58-F54) -> 0.90625
C62: Minimal | D62: =MIN(D19:D50) -> 0 | E62: =MIN(E19:E50) -> 0 | F62: =IFERROR(MIN(F19:F50),"") -> 0
C63: Maksimal | D63: =MAX(D19:D50) -> 92.7 | E63: =MAX(E19:E50) -> 92.1 | F63: =IFERROR(MAX(F19:F50),"") -> 92
C64: Rata-Rata | D64: =AVERAGE(D19:D50) -> 77.040625 | E64: =AVERAGE(E19:E50) -> 75.878125 | F64: =IFERROR(AVERAGE(F19:F50),"") -> 76.459375

Sheet MK3-PSTI
A1: FORM MONITORING DAN EVALUASI
A2: KETERCAPAIAN CAPAIAN PEMBELAJARAN MATAKULIAH(CPMK) PADA SATU ANGKATAN
A4: Tahun Akademik | C4: : 2025/2026 | E4: Program Studi | F4: : Akuntansi
A5: Kode Matakuliah | C5: : P.24.05.52.3.13 | E5: Fakultas | F5: : Ekonomika dan Bisnis
A6: Nama Matakuliah | C6: : Pengauditan 1
A7: SKS Matakuliah | C7: : 3
A8: Semester/ Kelas | C8: : I / A1+DLC
A9: Dosen Pengampu | C9: : 1.Y.2.00.02.115 - ACHMAD BADJURI, SE., M.Si, A.kt
D12: ='ListMKSmt-1'!B4 -> MK18 | F12: Nilai Akhir MK | G12: Nilai Huruf
D13: =TRIM(MID(C5,2,20)) -> P.24.05.52.3.13
D14: ='ListMKSmt-1'!E4 -> Pengauditan 1
D15: CPL08 | E15: CPL09
D16: CPMK81 | E16: CPMK91
D17: 50 | E17: 50
A18: No | B18: NIM | C18: Nama Mahasiswa
A19: 1 | B19: 24.05.52.0002 | C19: SNEHA JAYA BAIDURI | D19: 80.59 | E19: 78.06 | F19: =IFERROR((D19*($D$17/100))+(E19*($E$17/100)),"") -> 79.325 | G19: =IFERROR(VLOOKUP(F19,[3]Sheet1!$AA$1:$AB$10,2),"") -> B+
A20: 2 | B20: 24.05.52.0003 | C20: ALFARIESSA GIFTHA ANDREA PITALOKA | D20: 77.06 | E20: 79.18 | F20: =IFERROR((D20*($D$17/100))+(E20*($E$17/100)),"") -> 78.12 | G20: =IFERROR(VLOOKUP(F20,[2]Sheet1!$AA$1:$AB$10,2),"") -> B+
A21: 3 | B21: 24.05.52.0004 | C21: MAHARANI PUTRI RUSTIANTI | D21: 76.47 | E21: 74.08 | F21: =IFERROR((D21*($D$17/100))+(E21*($E$17/100)),"") -> 75.275 | G21: =IFERROR(VLOOKUP(F21,[2]Sheet1!$AA$1:$AB$10,2),"") -> B
A22: 4 | B22: 24.05.52.0005 | C22: FLORA SUCI FERONIKA | D22: 64.47 | E22: 73.47 | F22: =IFERROR((D22*($D$17/100))+(E22*($E$17/100)),"") -> 68.97 | G22: =IFERROR(VLOOKUP(F22,[2]Sheet1!$AA$1:$AB$10,2),"") -> B-
A23: 5 | B23: 24.05.52.0006 | C23: AATHIRA AUFA AZ-ZAHRA | D23: 70.59 | E23: 79.39 | F23: =IFERROR((D23*($D$17/100))+(E23*($E$17/100)),"") -> 74.99 | G23: =IFERROR(VLOOKUP(F23,[2]Sheet1!$AA$1:$AB$10,2),"") -> B
A24: 6 | B24: 24.05.52.0007 | C24: SHEILA MONA PUTRI IKSANTI | D24: 74.12 | E24: 75.1 | F24: =IFERROR((D24*($D$17/100))+(E24*($E$17/100)),"") -> 74.61 | G24: =IFERROR(VLOOKUP(F24,[2]Sheet1!$AA$1:$AB$10,2),"") -> B
A25: 7 | B25: 24.05.52.0008 | C25: RAIHAN RIFA MAHARADITYA | D25: 86.71 | E25: 82.35 | F25: =IFERROR((D25*($D$17/100))+(E25*($E$17/100)),"") -> 84.53 | G25: =IFERROR(VLOOKUP(F25,[2]Sheet1!$AA$1:$AB$10,2),"") -> A-
A26: 8 | B26: 24.05.52.0009 | C26: MARLINA DWI SAPUTRI | D26: 80.94 | E26: 74.59 | F26: =IFERROR((D26*($D$17/100))+(E26*($E$17/100)),"") -> 77.765 | G26: =IFERROR(VLOOKUP(F26,[2]Sheet1!$AA$1:$AB$10,2),"") -> B+
A27: 9 | B27: 24.05.52.0011 | C27: JONATHAN REXY FERDINAN | D27: 78.47 | E27: 74.18 | F27: =IFERROR((D27*($D$17/100))+(E27*($E$17/100)),"") -> 76.325 | G27: =IFERROR(VLOOKUP(F27,[2]Sheet1!$AA$1:$AB$10,2),"") -> B+
A28: 10 | B28: 24.05.52.0012 | C28: GITA TEONANDA ARELLIA | D28: 86.12 | E28: 80.92 | F28: =IFERROR((D28*($D$17/100))+(E28*($E$17/100)),"") -> 83.52 | G28: =IFERROR(VLOOKUP(F28,[2]Sheet1!$AA$1:$AB$10,2),"") -> B+
A29: 12 | B29: 24.05.52.0014 | C29: ARELIA SALSABILA SAFITRI | D29: 89.06 | E29: 87.35 | F29: =IFERROR((D29*($D$17/100))+(E29*($E$17/100)),"") -> 88.205 | G29: =IFERROR(VLOOKUP(F29,[2]Sheet1!$AA$1:$AB$10,2),"") -> A-
A30: 13 | B30: 24.05.52.0015 | C30: JULLER IBEL LAURENTIUS TURNIP | D30: 63.76 | E30: 43.88 | F30: =IFERROR((D30*($D$17/100))+(E30*($E$17/100)),"") -> 53.82 | G30: =IFERROR(VLOOKUP(F30,[2]Sheet1!$AA$1:$AB$10,2),"") -> C-
A31: 14 | B31: 24.05.52.0016 | C31: GADING BINTANG WICAKSONO | D31: 80.24 | E31: 74.69 | F31: =IFERROR((D31*($D$17/100))+(E31*($E$17/100)),"") -> 77.465 | G31: =IFERROR(VLOOKUP(F31,[2]Sheet1!$AA$1:$AB$10,2),"") -> B+
... A51: 34 | B51: 24.05.52.3010 | C51: PUTRY MEINERS ELISABET FAHIK | D51: 90 | E51: 82.69 | F51: =IFERROR((D51*($D$17/100))+(E51*($E$17/100)),"") -> 86.345 | G51: =IFERROR(VLOOKUP(F51,[2]Sheet1!$AA$1:$AB$10,2),"") -> A-
D53: =D16 -> CPMK81 | E53: =E16 -> CPMK91 | F53: =F12 -> Nilai Akhir MK
C54: Tidak KRS/ Tidak Aktif | D54: =IFERROR(COUNTIF(D19:D51,""),"") -> 0 | E54: =IFERROR(COUNTIF(E19:E51,""),"") -> 0 | F54: =IFERROR(COUNTIF(F19:F51,""),"") -> 0
C55: <=65 | D55: =IFERROR(COUNTIF(D19:D51,$C$55)+COUNTIF(D19:D51,""),"")-D54 -> 2 | E55: =IFERROR(COUNTIF(E19:E51,$C$55)+COUNTIF(E19:E51,""),"")-E54 -> 3 | F55: =IFERROR(COUNTIF(F19:F51,C55)+COUNTIF(F19:F51,""),"")-F54 -> 2
C56: <85 | D56: =IFERROR(COUNTIF(D19:D51,$C$56)-D55,"") -> 20 | E56: =IFERROR(COUNTIF(E19:E51,$C$56)-E55,"") -> 28 | F56: =IFERROR(COUNTIF(F19:F51,C56)-F55,"") -> 23
C57: >=85 | D57: =COUNTIF(D19:D51,$C$57) -> 11 | E57: =COUNTIF(E19:E51,$C$57) -> 2 | F57: =IFERROR(COUNTIF(F19:F51,C57),"") -> 8
C58: Total | D58: =SUM(D54:D57) -> 33 | E58: =SUM(E54:E57) -> 33 | F58: =SUM(F54:F57) -> 33
C60: Jumlah mhsw yg lulus CPMK | D60: =(D56+D57)/(D58-D54) -> 0.93939394 | E60: =(E56+E57)/(E58-E54) -> 0.90909091 | F60: =(F56+F57)/(F58-F54) -> 0.93939394
C62: Minimal | D62: =MIN(D19:D51) -> 63.76 | E62: =MIN(E19:E51) -> 31.41 | F62: =IFERROR(MIN(F19:F51),"") -> 53.82
C63: Maksimal | D63: =MAX(D19:D36) -> 89.06 | E63: =MAX(E19:E51) -> 87.35 | F63: =IFERROR(MAX(F19:F51),"") -> 88.205
C64: Rata-Rata | D64: =AVERAGE(D19:D51) -> 80.53697 | E64: =AVERAGE(E19:E51) -> 75.233333 | F64: =IFERROR(AVERAGE(F19:F51),"") -> 77.885152

Sheet MK4-L&A
A1: FORM MONITORING DAN EVALUASI
A2: KETERCAPAIAN CAPAIAN PEMBELAJARAN MATAKULIAH(CPMK) PADA SATU ANGKATAN
A4: Tahun Akademik | C4: : 2025/20256 | F4: Program Studi | G4: : Akuntansi
A5: Kode Matakuliah | C5: : P.24.05.52.3.14 | F5: Fakultas | G5: : Ekonomika dan Bisnis
A6: Nama Matakuliah | C6: : Akuntansi Pajak
A7: SKS Matakuliah | C7: : 2
A8: Semester/ Kelas | C8: : I / A1+DLC
A9: Dosen Pengampu | C9: : 1. YU.2.16.05.101 SARTIKA WULANDARI, S.Pd., M.Si
C10: : 2. Y.3.00.10.075 RACHMAWATI MEITA OKTAVIANI, S.E.,M.Si., Ak. CA
D12: MK19 | G12: Nilai Akhir MK | H12: Nilai Huruf
D13: =TRIM(MID(C5,2,20)) -> P.24.05.52.3.14
D14: =TRIM(MID(C6,2,100)) -> Akuntansi Pajak
D15: CPL10 | E15: CPL11 | F15: CPL11
D16: CPMK104 | E16: CPMK111 | F16: CPMK112
D17: 37 | E17: 33 | F17: 30
A18: No | B18: NIM | C18: Nama Mahasiswa
A19: 1 | B19: 24.05.52.0002 | C19: SNEHA JAYA BAIDURI | D19: 72.65 | E19: 70.06 | F19: 85.5 | G19: =IFERROR((D19*($D$17/100))+(E19*($E$17/100))+(F19*($F$17/100)),"") -> 75.6503 | H19: =IFERROR(VLOOKUP(G21,[4]Sheet1!$AA$1:$AB$10,2),"") -> B-
A20: 2 | B20: 24.05.52.0003 | C20: ALFARIESSA GIFTHA ANDREA PITALOKA | D20: 79.05 | E20: 78.94 | F20: 85.67 | G20: =IFERROR((D20*($D$17/100))+(E20*($E$17/100))+(F20*($F$17/100)),"") -> 80.9997 | H20: =IFERROR(VLOOKUP(G20,[4]Sheet1!$AA$1:$AB$10,2),"") -> B+
A21: 3 | B21: 24.05.52.0004 | C21: MAHARANI PUTRI RUSTIANTI | D21: 68.95 | E21: 68 | F21: 67 | G21: =IFERROR((D21*($D$17/100))+(E21*($E$17/100))+(F21*($F$17/100)),"") -> 68.0515 | H21: =IFERROR(VLOOKUP(G21,[4]Sheet1!$AA$1:$AB$10,2),"") -> B-
A22: 4 | B22: 24.05.52.0005 | C22: FLORA SUCI FERONIKA | D22: 70.27 | E22: 72.58 | F22: 69.33 | G22: =IFERROR((D22*($D$17/100))+(E22*($E$17/100))+(F22*($F$17/100)),"") -> 70.7503 | H22: =IFERROR(VLOOKUP(G22,[4]Sheet1!$AA$1:$AB$10,2),"") -> B
A23: 5 | B23: 24.05.52.0006 | C23: AATHIRA AUFA AZ-ZAHRA | D23: 78.41 | E23: 80.88 | F23: 78.67 | G23: =IFERROR((D23*($D$17/100))+(E23*($E$17/100))+(F23*($F$17/100)),"") -> 79.3031 | H23: =IFERROR(VLOOKUP(G23,[4]Sheet1!$AA$1:$AB$10,2),"") -> B+
A24: 6 | B24: 24.05.52.0007 | C24: SHEILA MONA PUTRI IKSANTI | D24: 65.54 | E24: 62.27 | F24: 76.5 | G24: =IFERROR((D24*($D$17/100))+(E24*($E$17/100))+(F24*($F$17/100)),"") -> 67.7489 | H24: =IFERROR(VLOOKUP(G24,[4]Sheet1!$AA$1:$AB$10,2),"") -> B-
A25: 7 | B25: 24.05.52.0008 | C25: RAIHAN RIFA MAHARADITYA | D25: 85.14 | E25: 86.82 | F25: 79.5 | G25: =IFERROR((D25*($D$17/100))+(E25*($E$17/100))+(F25*($F$17/100)),"") -> 84.0024 | H25: =IFERROR(VLOOKUP(G25,[4]Sheet1!$AA$1:$AB$10,2),"") -> B+
A26: 8 | B26: 24.05.52.0009 | C26: MARLINA DWI SAPUTRI | D26: 66.22 | E26: 67.27 | F26: 70.17 | G26: =IFERROR((D26*($D$17/100))+(E26*($E$17/100))+(F26*($F$17/100)),"") -> 67.7515 | H26: =IFERROR(VLOOKUP(G26,[4]Sheet1!$AA$1:$AB$10,2),"") -> B-
A27: 9 | B27: 24.05.52.0011 | C27: JONATHAN REXY FERDINAN | D27: 60.81 | E27: 58.48 | F27: 62.33 | G27: =IFERROR((D27*($D$17/100))+(E27*($E$17/100))+(F27*($F$17/100)),"") -> 60.4971 | H27: =IFERROR(VLOOKUP(G27,[4]Sheet1!$AA$1:$AB$10,2),"") -> C+
A28: 10 | B28: 24.05.52.0012 | C28: GITA TEONANDA ARELLIA | D28: 76.49 | E28: 76.36 | F28: 77.33 | G28: =IFERROR((D28*($D$17/100))+(E28*($E$17/100))+(F28*($F$17/100)),"") -> 76.6991 | H28: =IFERROR(VLOOKUP(G28,[4]Sheet1!$AA$1:$AB$10,2),"") -> B+
A29: 12 | B29: 24.05.52.0014 | C29: ARELIA SALSABILA SAFITRI | D29: 75.68 | E29: 75.45 | F29: 80.33 | G29: =IFERROR((D29*($D$17/100))+(E29*($E$17/100))+(F29*($F$17/100)),"") -> 76.9991 | H29: =IFERROR(VLOOKUP(G29,[4]Sheet1!$AA$1:$AB$10,2),"") -> B+
A30: 13 | B30: 24.05.52.0015 | C30: JULLER IBEL LAURENTIUS TURNIP | D30: 0 | E30: 0 | F30: 0 | G30: =IFERROR((D30*($D$17/100))+(E30*($E$17/100))+(F30*($F$17/100)),"") -> 0 | H30: =IFERROR(VLOOKUP(G30,[4]Sheet1!$AA$1:$AB$10,2),"") -> E
A31: 14 | B31: 24.05.52.0016 | C31: GADING BINTANG WICAKSONO | D31: 70.27 | E31: 72.12 | F31: 69 | G31: =IFERROR((D31*($D$17/100))+(E31*($E$17/100))+(F31*($F$17/100)),"") -> 70.4995 | H31: =IFERROR(VLOOKUP(G31,[4]Sheet1!$AA$1:$AB$10,2),"") -> B
... A50: 34 | B50: 24.05.52.3010 | C50: PUTRY MEINERS ELISABET FAHIK | D50: 83.92 | E50: 84.55 | F50: 85.83 | G50: =IFERROR((D50*($D$17/100))+(E50*($E$17/100))+(F50*($F$17/100)),"") -> 84.7009 | H50: =IFERROR(VLOOKUP(G50,[4]Sheet1!$AA$1:$AB$10,2),"") -> A-
D52: =D16 -> CPMK104 | E52: =E16 -> CPMK111 | F52: =F16 -> CPMK112 | G52: =G12 -> Nilai Akhir MK
C53: Tidak KRS/Tidak Aktif | D53: =IFERROR(COUNTIF(D19:D50,""),"") -> 0 | E53: =IFERROR(COUNTIF(E19:E50,""),"") -> 0 | F53: =IFERROR(COUNTIF(F19:F50,""),"") -> 0 | G53: =IFERROR(COUNTIF(G19:G50,""),"") -> 0
C54: <=65 | D54: =IFERROR(COUNTIF(D19:D50,$C$54)+COUNTIF(D19:D50,""),"")-D53 -> 3 | E54: =IFERROR(COUNTIF(E19:E50,$C$54)+COUNTIF(E19:E50,""),"")-E53 -> 5 | F54: =IFERROR(COUNTIF(F19:F50,$C$54)+COUNTIF(F19:F50,""),"")-F53 -> 4 | G54: =IFERROR(COUNTIF(G19:G50,C54)+COUNTIF(G19:G50,""),"") -> 4
C55: <85 | D55: =IFERROR(COUNTIF(D19:D50,$C$55)-D54,"") -> 24 | E55: =IFERROR(COUNTIF(E19:E50,$C$55)-E54,"") -> 21 | F55: =IFERROR(COUNTIF(F19:F50,$C$55)-F54,"") -> 18 | G55: =IFERROR(COUNTIF(G19:G50,C55)-G54,"") -> 23
C56: >=85 | D56: =COUNTIF(D19:D50,$C$56) -> 5 | E56: =COUNTIF(E19:E50,$C$56) -> 6 | F56: =COUNTIF(F19:F50,$C$56) -> 10 | G56: =IFERROR(COUNTIF(G19:G50,C56),"") -> 5
C57: Total | D57: =SUM(D53:D56) -> 32 | E57: =SUM(E53:E56) -> 32 | F57: =SUM(F53:F56) -> 32 | G57: =SUM(G53:G56) -> 32
C59: Jumlah mhsw yg lulus CPMK | D59: =(D55+D56)/(D57-D53) -> 0.90625 | F59: =(F55+F56)/(F57-F53) -> 0.875 | G59: =(G55+G56)/(G57-G53) -> 0.875
C61: Minimal | D61: =MIN(D19:D50) -> 0 | F61: =MIN(F19:F50) -> 0 | G61: =IFERROR(MIN(G19:G50),"") -> 0
C62: Maksimal | D62: =MAX(D19:D50) -> 86.76 | F62: =MAX(F19:F50) -> 88.33 | G62: =IFERROR(MAX(G19:G50),"") -> 87.3993
C63: Rata-Rata | D63: =AVERAGE(D19:D50) -> 72.535625 | F63: =AVERAGE(F19:F50) -> 74.541875 | G63: =IFERROR(AVERAGE(G19:G50),"") -> 73.130178

Sheet MK5-BP
A1: FORM MONITORING DAN EVALUASI
A2: KETERCAPAIAN CAPAIAN PEMBELAJARAN MATAKULIAH(CPMK) PADA SATU ANGKATAN
A4: Tahun Akademik | C4: : 2025/2026 | E4: Program Studi | F4: : Akuntansi
A5: Kode Matakuliah | C5: : P.24.05.52.3.15 | E5: Fakultas | F5: : Ekonomika dan Bisnis
A6: Nama Matakuliah | C6: : Akuntansi Manajemen
A7: SKS Matakuliah | C7: : 3
A8: Semester/ Kelas | C8: : I / A1+DLC
A9: Dosen Pengampu | C9: : 1. Y.2.92.07.083 Dr. CEACILIA SRIMINDARTI, S.Pd, M.Si
C10: : 2. YU.2.01.10.038 IDA NURHAYATI , SE., M.Si
D12: MK20 | F12: Nilai Akhir MK | G12: Nilai Huruf
D13: =TRIM(MID(C5,2,20)) -> P.24.05.52.3.15
D14: =TRIM(MID(C6,2,100)) -> Akuntansi Manajemen
D15: CPL04 | E15: CPL04
D16: CPMK41 | E16: CPMK42
D17: 50 | E17: 50
A18: No | B18: NIM | C18: Nama Mahasiswa
A19: 1 | B19: 24.05.52.0002 | C19: SNEHA JAYA BAIDURI | D19: 76.3 | E19: 76.3 | F19: =IFERROR((D19*($D$17/100))+(E19*($E$17/100)),"") -> 76.3 | G19: =IFERROR(VLOOKUP(F21,[4]Sheet1!$AA$1:$AB$10,2),"") -> A
A20: 2 | B20: 24.05.52.0003 | C20: ALFARIESSA GIFTHA ANDREA PITALOKA | D20: 81.4 | E20: 81.4 | F20: =IFERROR((D20*($D$17/100))+(E20*($E$17/100)),"") -> 81.4 | G20: =IFERROR(VLOOKUP(F20,[5]Sheet1!$AA$1:$AB$10,2),"") -> B+
A21: 3 | B21: 24.05.52.0004 | C21: MAHARANI PUTRI RUSTIANTI | D21: 92.6 | E21: 92.6 | F21: =IFERROR((D21*($D$17/100))+(E21*($E$17/100)),"") -> 92.6 | G21: =IFERROR(VLOOKUP(F21,[5]Sheet1!$AA$1:$AB$10,2),"") -> A
A22: 4 | B22: 24.05.52.0005 | C22: FLORA SUCI FERONIKA | D22: 93.9 | E22: 93.9 | F22: =IFERROR((D22*($D$17/100))+(E22*($E$17/100)),"") -> 93.9 | G22: =IFERROR(VLOOKUP(F22,[5]Sheet1!$AA$1:$AB$10,2),"") -> A
A23: 5 | B23: 24.05.52.0006 | C23: AATHIRA AUFA AZ-ZAHRA | D23: 92.6 | E23: 92.6 | F23: =IFERROR((D23*($D$17/100))+(E23*($E$17/100)),"") -> 92.6 | G23: =IFERROR(VLOOKUP(F23,[5]Sheet1!$AA$1:$AB$10,2),"") -> A
A24: 6 | B24: 24.05.52.0007 | C24: SHEILA MONA PUTRI IKSANTI | D24: 93.9 | E24: 93.9 | F24: =IFERROR((D24*($D$17/100))+(E24*($E$17/100)),"") -> 93.9 | G24: =IFERROR(VLOOKUP(F24,[5]Sheet1!$AA$1:$AB$10,2),"") -> A
A25: 7 | B25: 24.05.52.0008 | C25: RAIHAN RIFA MAHARADITYA | D25: 81.4 | E25: 81.4 | F25: =IFERROR((D25*($D$17/100))+(E25*($E$17/100)),"") -> 81.4 | G25: =IFERROR(VLOOKUP(F25,[5]Sheet1!$AA$1:$AB$10,2),"") -> B+
A26: 8 | B26: 24.05.52.0009 | C26: MARLINA DWI SAPUTRI | D26: 81.4 | E26: 81.4 | F26: =IFERROR((D26*($D$17/100))+(E26*($E$17/100)),"") -> 81.4 | G26: =IFERROR(VLOOKUP(F26,[5]Sheet1!$AA$1:$AB$10,2),"") -> B+
A27: 9 | B27: 24.05.52.0011 | C27: JONATHAN REXY FERDINAN | D27: 81.4 | E27: 81.4 | F27: =IFERROR((D27*($D$17/100))+(E27*($E$17/100)),"") -> 81.4 | G27: =IFERROR(VLOOKUP(F27,[5]Sheet1!$AA$1:$AB$10,2),"") -> B+
A28: 10 | B28: 24.05.52.0012 | C28: GITA TEONANDA ARELLIA | D28: 93.9 | E28: 93.9 | F28: =IFERROR((D28*($D$17/100))+(E28*($E$17/100)),"") -> 93.9 | G28: =IFERROR(VLOOKUP(F28,[5]Sheet1!$AA$1:$AB$10,2),"") -> A
A29: 12 | B29: 24.05.52.0014 | C29: ARELIA SALSABILA SAFITRI | D29: 93.9 | E29: 93.9 | F29: =IFERROR((D29*($D$17/100))+(E29*($E$17/100)),"") -> 93.9 | G29: =IFERROR(VLOOKUP(F29,[5]Sheet1!$AA$1:$AB$10,2),"") -> A
A30: 13 | B30: 24.05.52.0015 | C30: JULLER IBEL LAURENTIUS TURNIP | D30: 9.4 | E30: 9.4 | F30: =IFERROR((D30*($D$17/100))+(E30*($E$17/100)),"") -> 9.4 | G30: =IFERROR(VLOOKUP(F30,[5]Sheet1!$AA$1:$AB$10,2),"") -> E
A31: 14 | B31: 24.05.52.0016 | C31: GADING BINTANG WICAKSONO | D31: 76.9 | E31: 76.9 | F31: =IFERROR((D31*($D$17/100))+(E31*($E$17/100)),"") -> 76.9 | G31: =IFERROR(VLOOKUP(F31,[5]Sheet1!$AA$1:$AB$10,2),"") -> B+
... A51: 34 | B51: 24.05.52.3010 | C51: PUTRY MEINERS ELISABET FAHIK | D51: 84.9 | E51: 65.4 | F51: =IFERROR((D51*($D$17/100))+(E51*($E$17/100)),"") -> 75.15 | G51: =IFERROR(VLOOKUP(F51,[5]Sheet1!$AA$1:$AB$10,2),"") -> B
A52: 35 | B52: 24.05.52.3011 | C52: AMINATUL AROFAH
A53: 36 | B53: 24.05.52.3012 | C53: RORO AYU SUKMAWATI
D55: =D16 -> CPMK41 | E55: =E16 -> CPMK42 | F55: =F12 -> Nilai Akhir MK
C56: Tidak KRS/Tidak Aktif | D56: =IFERROR(COUNTIF(D19:D53,""),"") -> 2 | E56: =IFERROR(COUNTIF(E19:E53,""),"") -> 2 | F56: =IFERROR(COUNTIF(F19:F53,""),"") -> 2
C57: <=65 | D57: =IFERROR(COUNTIF(D19:D53,C57)+COUNTIF(D19:D53,""),"")-D56 -> 1 | E57: =COUNTIF(E19:E53,C57)+COUNTIF(E19:E53,"")-E56 -> 1 | F57: =IFERROR(COUNTIF(F19:F53,C57)+COUNTIF(F19:F53,""),"") -> 3
C58: <85 | D58: =IFERROR(COUNTIF(D19:D53,C58)-D57,"") -> 19 | E58: =COUNTIF(E19:E53,C58)-E57 -> 21 | F58: =IFERROR(COUNTIF(F19:F53,C58)-F57,"") -> 17
C59: >=85 | D59: =COUNTIF(D19:D53,C59) -> 13 | E59: =COUNTIF(E19:E53,C59) -> 11 | F59: =IFERROR(COUNTIF(F19:F53,C59),"") -> 13
C60: Total | D60: =SUM(D56:D59) -> 35 | E60: =SUM(E56:E59) -> 35 | F60: =SUM(F56:F59) -> 35
C62: Jumlah mhsw yg lulus CPMK | D62: =(D58+D59)/(D60-D56) -> 0.96969697 | E62: =(E58+E59)/(E60-E56) -> 0.96969697 | F62: =(F58+F59)/(F60-F56) -> 0.90909091
C64: Minimal | D64: =MIN(D19:D53) -> 9.4 | E64: =MIN(E19:E53) -> 9.4 | F64: =IFERROR(MIN(F19:F53),"") -> 9.4
...

Sheet MK7-MBD
A1: FORM MONITORING DAN EVALUASI
A2: KETERCAPAIAN CAPAIAN PEMBELAJARAN MATAKULIAH(CPMK) PADA SATU ANGKATAN
A4: Tahun Akademik | C4: : 2025/2026 | E4: Program Studi | F4: : Akuntansi
A5: Kode Matakuliah | C5: : P.24.05.52.3.16 | E5: Fakultas | F5: : Ekonomika dan Bisnis
A6: Nama Matakuliah | C6: : Manajemen Keuangan
A7: SKS Matakuliah | C7: : 3
A8: Semester/ Kelas | C8: : I / A1+DLC
A9: Dosen Pengampu | C9: : 1. Y.2.92.07.078 SRI SUDARSI, SE., M.Si
C10: : 2. Y.3.00.05.074 BATARA DANIEL BAGANA, SE, MM
D11: MK21 | F11: Nilai Akhir MK | G11: Nilai Huruf
D12: =TRIM(MID(C5,2,20)) -> P.24.05.52.3.16
D13: =TRIM(MID(C6,2,100)) -> Manajemen Keuangan
D14: CPL06 | E14: CPL06
D15: CPMK61 | E15: CPMK62
D16: 50 | E16: 50
A17: No | B17: NIM | C17: Nama Mahasiswa
A18: 1 | B18: 24.05.52.0002 | C18: SNEHA JAYA BAIDURI | D18: 75.5 | E18: 96.5 | F18: =IFERROR((D18*($D$16/100))+(E18*($E$16/100)),"") -> 86 | G18: =IFERROR(VLOOKUP(F20,[4]Sheet1!$AA$1:$AB$10,2),"") -> B+
A19: 2 | B19: 24.05.52.0003 | C19: ALFARIESSA GIFTHA ANDREA PITALOKA | D19: 72 | E19: 82.5 | F19: =IFERROR((D19*($D$16/100))+(E19*($E$16/100)),"") -> 77.25 | G19: =IFERROR(VLOOKUP(F19,[6]Sheet1!$AA$1:$AB$10,2),"") -> B+
A20: 3 | B20: 24.05.52.0004 | C20: MAHARANI PUTRI RUSTIANTI | D20: 78.4 | E20: 85.4 | F20: =IFERROR((D20*($D$16/100))+(E20*($E$16/100)),"") -> 81.9 | G20: =IFERROR(VLOOKUP(F20,[6]Sheet1!$AA$1:$AB$10,2),"") -> B+
A21: 4 | B21: 24.05.52.0005 | C21: FLORA SUCI FERONIKA | D21: 74.9 | E21: 78.4 | F21: =IFERROR((D21*($D$16/100))+(E21*($E$16/100)),"") -> 76.65 | G21: =IFERROR(VLOOKUP(F21,[6]Sheet1!$AA$1:$AB$10,2),"") -> B+
A22: 5 | B22: 24.05.52.0006 | C22: AATHIRA AUFA AZ-ZAHRA | D22: 81.9 | E22: 81.9 | F22: =IFERROR((D22*($D$16/100))+(E22*($E$16/100)),"") -> 81.9 | G22: =IFERROR(VLOOKUP(F22,[6]Sheet1!$AA$1:$AB$10,2),"") -> B+
A23: 6 | B23: 24.05.52.0007 | C23: SHEILA MONA PUTRI IKSANTI | D23: 66.5 | E23: 77 | F23: =IFERROR((D23*($D$16/100))+(E23*($E$16/100)),"") -> 71.75 | G23: =IFERROR(VLOOKUP(F23,[6]Sheet1!$AA$1:$AB$10,2),"") -> B
A24: 7 | B24: 24.05.52.0008 | C24: RAIHAN RIFA MAHARADITYA | D24: 75.5 | E24: 75.5 | F24: =IFERROR((D24*($D$16/100))+(E24*($E$16/100)),"") -> 75.5 | G24: =IFERROR(VLOOKUP(F24,[6]Sheet1!$AA$1:$AB$10,2),"") -> B+
A25: 8 | B25: 24.05.52.0009 | C25: MARLINA DWI SAPUTRI | D25: 58 | E25: 93 | F25: =IFERROR((D25*($D$16/100))+(E25*($E$16/100)),"") -> 75.5 | G25: =IFERROR(VLOOKUP(F25,[6]Sheet1!$AA$1:$AB$10,2),"") -> B+
A26: 9 | B26: 24.05.52.0011 | C26: JONATHAN REXY FERDINAN | D26: 64.4 | E26: 78.4 | F26: =IFERROR((D26*($D$16/100))+(E26*($E$16/100)),"") -> 71.4 | G26: =IFERROR(VLOOKUP(F26,[6]Sheet1!$AA$1:$AB$10,2),"") -> B
A27: 10 | B27: 24.05.52.0012 | C27: GITA TEONANDA ARELLIA | D27: 75.5 | E27: 93 | F27: =IFERROR((D27*($D$16/100))+(E27*($E$16/100)),"") -> 84.25 | G27: =IFERROR(VLOOKUP(F27,[6]Sheet1!$AA$1:$AB$10,2),"") -> B+
A28: 12 | B28: 24.05.52.0014 | C28: ARELIA SALSABILA SAFITRI | D28: 82.5 | E28: 89.5 | F28: =IFERROR((D28*($D$16/100))+(E28*($E$16/100)),"") -> 86 | G28: =IFERROR(VLOOKUP(F28,[6]Sheet1!$AA$1:$AB$10,2),"") -> A-
A29: 13 | B29: 24.05.52.0015 | C29: JULLER IBEL LAURENTIUS TURNIP | D29: 0.6 | E29: 0.6 | F29: =IFERROR((D29*($D$16/100))+(E29*($E$16/100)),"") -> 0.6 | G29: =IFERROR(VLOOKUP(F29,[6]Sheet1!$AA$1:$AB$10,2),"") -> E
A30: 14 | B30: 24.05.52.0016 | C30: GADING BINTANG WICAKSONO | D30: 58 | E30: 89.5 | F30: =IFERROR((D30*($D$16/100))+(E30*($E$16/100)),"") -> 73.75 | G30: =IFERROR(VLOOKUP(F30,[6]Sheet1!$AA$1:$AB$10,2),"") -> B
... A49: 34 | B49: 24.05.52.3010 | C49: PUTRY MEINERS ELISABET FAHIK | D49: 79.2 | E49: 79.2 | F49: =IFERROR((D49*($D$16/100))+(E49*($E$16/100)),"") -> 79.2 | G49: =IFERROR(VLOOKUP(F49,[6]Sheet1!$AA$1:$AB$10,2),"") -> B+
D51: =D15 -> CPMK61 | E51: =E15 -> CPMK62 | F51: =F11 -> Nilai Akhir MK
C52: Tidak KRS/Tidak Aktif | D52: =IFERROR(COUNTIF(D18:D49,""),"") -> 0 | E52: =IFERROR(COUNTIF(E18:E49,""),"") -> 0 | F52: =IFERROR(COUNTIF(F18:F49,""),"") -> 0
C53: <=65 | D53: =IFERROR(COUNTIF(D18:D49,C53)+COUNTIF(D18:D49,""),"")-D52 -> 6 | E53: =COUNTIF(E18:E49,C53)+COUNTIF(E18:E49,"")-E52 -> 1 | F53: =IFERROR(COUNTIF(F18:F49,C53)+COUNTIF(F18:F49,""),"") -> 1
C54: <85 | D54: =IFERROR(COUNTIF(D18:D49,C54)-D53,"") -> 24 | E54: =COUNTIF(E18:E49,C54)-E53 -> 17 | F54: =IFERROR(COUNTIF(F18:F49,C54)-F53,"") -> 25
C55: >=85 | D55: =COUNTIF(D18:D49,C55) -> 2 | E55: =COUNTIF(E18:E49,C55) -> 14 | F55: =IFERROR(COUNTIF(F18:F49,C55),"") -> 6
C56: Total | D56: =SUM(D52:D55) -> 32 | E56: =SUM(E52:E55) -> 32 | F56: =SUM(F52:F55) -> 32
C58: Jumlah mhsw yg lulus CPMK | D58: =(D54+D55)/(D56-D52) -> 0.8125 | E58: =(E54+E55)/(E56-E52) -> 0.96875 | F58: =(F54+F55)/(F56-F52) -> 0.96875
C60: Minimal | D60: =MIN(D18:D49) -> 0.6 | E60: =MIN(E18:E49) -> 0.6 | F60: =IFERROR(MIN(F18:F49),"") -> 0.6
C61: Maksimal | D61: =MAX(D18:D49) -> 86.3 | E61: =MAX(E18:E49) -> 96.5 | F61: =IFERROR(MAX(F18:F49),"") -> 89.5
C62: Rata-Rata | D62: =AVERAGE(D18:D49) -> 72.70625 | E62: =AVERAGE(E18:E49) -> 81.565625 | F62: =IFERROR(AVERAGE(F18:F49),"") -> 77.135938

Sheet MK8_BID
A1: FORM MONITORING DAN EVALUASI
A2: KETERCAPAIAN CAPAIAN PEMBELAJARAN MATAKULIAH(CPMK) PADA SATU ANGKATAN
A4: Tahun Akademik | C4: : 2025/2026 | E4: : Akuntansi
A5: Kode Matakuliah | C5: : U.24.05.52.3.06 | E5: : Ekonomika dan Bisnis
A6: Nama Matakuliah | C6: : Entrepreneurship for Start-up
A7: SKS Matakuliah | C7: : 3
A8: Semester/ Kelas | C8: : I / A1+DLC
A9: Dosen Pengampu | C9: : 1. YU.2.18.09.114 KRISTINA ANINDITA HAYUNINGTIAS, S.E., M.M.
C10: : 2.
D12: MK22 | F12: Nilai Akhir MK | G12: Nilai Huruf
D13: Entrepreneurship for Start-up
D14: =TRIM(MID(C5,2,100)) -> U.24.05.52.3.06
D15: CPL12 | E15: CPL12
D16: CPMK121 | E16: CPMK122
D17: 50 | E17: 50
A18: No | B18: NIM | C18: Nama Mahasiswa
A19: 1 | B19: 24.05.52.0002 | C19: SNEHA JAYA BAIDURI | D19: 75.5 | E19: 96.5 | F19: =IFERROR((D19*($D$17/100))+(E19*($E$17/100)),"") -> 86 | G19: =IFERROR(VLOOKUP(F21,[4]Sheet1!$AA$1:$AB$10,2),"") -> B+
A20: 2 | B20: 24.05.52.0003 | C20: ALFARIESSA GIFTHA ANDREA PITALOKA | D20: 72 | E20: 82.5 | F20: =IFERROR((D20*($D$17/100))+(E20*($E$17/100)),"") -> 77.25 | G20: =IFERROR(VLOOKUP(F20,[6]Sheet1!$AA$1:$AB$10,2),"") -> B+
A21: 3 | B21: 24.05.52.0004 | C21: MAHARANI PUTRI RUSTIANTI | D21: 78.4 | E21: 85.4 | F21: =IFERROR((D21*($D$17/100))+(E21*($E$17/100)),"") -> 81.9 | G21: =IFERROR(VLOOKUP(F21,[6]Sheet1!$AA$1:$AB$10,2),"") -> B+
A22: 4 | B22: 24.05.52.0005 | C22: FLORA SUCI FERONIKA | D22: 74.9 | E22: 78.4 | F22: =IFERROR((D22*($D$17/100))+(E22*($E$17/100)),"") -> 76.65 | G22: =IFERROR(VLOOKUP(F22,[6]Sheet1!$AA$1:$AB$10,2),"") -> B+
A23: 5 | B23: 24.05.52.0006 | C23: AATHIRA AUFA AZ-ZAHRA | D23: 81.9 | E23: 81.9 | F23: =IFERROR((D23*($D$17/100))+(E23*($E$17/100)),"") -> 81.9 | G23: =IFERROR(VLOOKUP(F23,[6]Sheet1!$AA$1:$AB$10,2),"") -> B+
A24: 6 | B24: 24.05.52.0007 | C24: SHEILA MONA PUTRI IKSANTI | D24: 66.5 | E24: 77 | F24: =IFERROR((D24*($D$17/100))+(E24*($E$17/100)),"") -> 71.75 | G24: =IFERROR(VLOOKUP(F24,[6]Sheet1!$AA$1:$AB$10,2),"") -> B
A25: 7 | B25: 24.05.52.0008 | C25: RAIHAN RIFA MAHARADITYA | D25: 75.5 | E25: 75.5 | F25: =IFERROR((D25*($D$17/100))+(E25*($E$17/100)),"") -> 75.5 | G25: =IFERROR(VLOOKUP(F25,[6]Sheet1!$AA$1:$AB$10,2),"") -> B+
A26: 8 | B26: 24.05.52.0009 | C26: MARLINA DWI SAPUTRI | D26: 58 | E26: 93 | F26: =IFERROR((D26*($D$17/100))+(E26*($E$17/100)),"") -> 75.5 | G26: =IFERROR(VLOOKUP(F26,[6]Sheet1!$AA$1:$AB$10,2),"") -> B+
A27: 9 | B27: 24.05.52.0011 | C27: JONATHAN REXY FERDINAN | D27: 64.4 | E27: 78.4 | F27: =IFERROR((D27*($D$17/100))+(E27*($E$17/100)),"") -> 71.4 | G27: =IFERROR(VLOOKUP(F27,[6]Sheet1!$AA$1:$AB$10,2),"") -> B
A28: 10 | B28: 24.05.52.0012 | C28: GITA TEONANDA ARELLIA | D28: 75.5 | E28: 93 | F28: =IFERROR((D28*($D$17/100))+(E28*($E$17/100)),"") -> 84.25 | G28: =IFERROR(VLOOKUP(F28,[6]Sheet1!$AA$1:$AB$10,2),"") -> B+
A29: 12 | B29: 24.05.52.0014 | C29: ARELIA SALSABILA SAFITRI | D29: 82.5 | E29: 89.5 | F29: =IFERROR((D29*($D$17/100))+(E29*($E$17/100)),"") -> 86 | G29: =IFERROR(VLOOKUP(F29,[6]Sheet1!$AA$1:$AB$10,2),"") -> A-
A30: 13 | B30: 24.05.52.0015 | C30: JULLER IBEL LAURENTIUS TURNIP | D30: 0.6 | E30: 0.6 | F30: =IFERROR((D30*($D$17/100))+(E30*($E$17/100)),"") -> 0.6 | G30: =IFERROR(VLOOKUP(F30,[6]Sheet1!$AA$1:$AB$10,2),"") -> E
A31: 14 | B31: 24.05.52.0016 | C31: GADING BINTANG WICAKSONO | D31: 58 | E31: 89.5 | F31: =IFERROR((D31*($D$17/100))+(E31*($E$17/100)),"") -> 73.75 | G31: =IFERROR(VLOOKUP(F31,[6]Sheet1!$AA$1:$AB$10,2),"") -> B
... A50: 33 | B50: 24.05.52.3009 | C50: DEBY KARUNIA ANGGRAENI | D50: 79.2 | E50: 79.2 | F50: =IFERROR((D50*($D$17/100))+(E50*($E$17/100)),"") -> 79.2 | G50: =IFERROR(VLOOKUP(F50,[6]Sheet1!$AA$1:$AB$10,2),"") -> B+
A51: 34 | B51: 24.05.52.3010 | C51: PUTRY MEINERS ELISABET FAHIK | D51: 89.7 | E51: =IFERROR((D51*($D$17/100)),"") -> 44.85 | F51: =IFERROR((D51*($D$17/100))+(E51*($E$17/100)),"") -> 67.275 | G51: =IFERROR(VLOOKUP(F51,[6]Sheet1!$AA$1:$AB$10,2),"") -> B-
D53: =D16 -> CPMK121 | E53: =E16 -> CPMK122 | F53: Total
C54: Tidak KRS/Tidak Aktif | D54: =IFERROR(COUNTIF(D20:D51,""),"") -> 0 | E54: =IFERROR(COUNTIF(E20:E51,""),"") -> 0 | F54: =IFERROR(COUNTIF(F20:F51,""),"") -> 0
C55: <=65 | D55: =IFERROR(COUNTIF(D20:D51,C55)+COUNTIF(D20:D51,""),"")-D54 -> 6 | E55: =COUNTIF(E20:E51,C55)+COUNTIF(E20:E51,"")-E54 -> 2 | F55: =IFERROR(COUNTIF(F20:F51,C55)+COUNTIF(F20:F51,""),"") -> 1
C56: <85 | D56: =IFERROR(COUNTIF(D20:D51,C56)-D55,"") -> 23 | E56: =COUNTIF(E20:E51,C56)-E55 -> 17 | F56: =IFERROR(COUNTIF(F20:F51,C56)-F55,"") -> 26
C57: >=85 | D57: =COUNTIF(D20:D51,C57) -> 3 | E57: =COUNTIF(E20:E51,C57) -> 13 | F57: =IFERROR(COUNTIF(F20:F51,C57),"") -> 5
C58: Total | D58: =SUM(D54:D57) -> 32 | E58: =SUM(E54:E57) -> 32 | F58: =SUM(F54:F57) -> 32
C60: Jumlah mhsw yg lulus CPMK | D60: =(D56+D57)/(D58-D54) -> 0.8125 | E60: =(E56+E57)/(E58-E54) -> 0.9375 | F60: =(F56+F57)/(F58-F54) -> 0.96875
C62: Minimal | D62: =MIN(D20:D51) -> 0.6 | E62: =MIN(E20:E51) -> 0.6 | F62: =IFERROR(MIN(F20:F51),"") -> 0.6
C63: Maksimal | D63: =MAX(D20:D51) -> 89.7 | E63: =MAX(E20:E51) -> 96.5 | F63: =IFERROR(MAX(F20:F51),"") -> 89.5
...

Sheet MK16-AGM
A1: FORM MONITORING DAN EVALUASI
A2: KETERCAPAIAN CAPAIAN PEMBELAJARAN MATAKULIAH(CPMK) PADA SATU ANGKATAN
A4: Tahun Akademik | C4: : 2024/2025 | E4: Program Studi | F4: : Akuntansi
A5: Kode Matakuliah | C5: : UU.24.05.52.1.03 | E5: Fakultas | F5: : Ekonomika dan Bisnis
A6: Nama Matakuliah | C6: : English for Business
A7: SKS Matakuliah | C7: : 2
A8: Semester/ Kelas | C8: : I / A1+DLC
A9: Dosen Pengampu | C9: : 1. L.0308 SARAH SUMPONOGATI, S.S, M.Li.
C10: : 2.
D12: MK8 | F12: =CONCATENATE("Nilai Akhir MK"," ",D17+E17) -> Nilai Akhir MK 100 | G12: Nilai Huruf
D13: =TRIM(MID(C5,3,100)) -> UU.24.05.52.1.03
D14: =TRIM(MID(C6,3,100)) -> English for Business
D15: CPL12 | E15: CPL12
D16: CPMK122 | E16: CPMK123
D17: 50 | E17: 50
A18: No | B18: NIM | C18: Nama Mahasiswa
A19: 1 | B19: 24.05.52.0002 | C19: SNEHA JAYA BAIDURI | D19: 93.2 | E19: 97.5 | F19: =IFERROR((D19*($D$17/100))+(E19*($E$17/100)),"") -> 95.35 | G19: =IFERROR(VLOOKUP(F20,[7]Sheet1!$AA$1:$AB$10,2),"") -> A
A20: 2 | B20: 24.05.52.0003 | C20: ALFARIESSA GIFTHA ANDREA PITALOKA | D20: 95.5 | E20: 93.4 | F20: =IFERROR((D20*($D$17/100))+(E20*($E$17/100)),"") -> 94.45 | G20: =IFERROR(VLOOKUP(F20,[8]Sheet1!$AA$1:$AB$10,2),"") -> A
A21: 3 | B21: 24.05.52.0004 | C21: MAHARANI PUTRI RUSTIANTI | D21: 94.7 | E21: 95.9 | F21: =IFERROR((D21*($D$17/100))+(E21*($E$17/100)),"") -> 95.3 | G21: =IFERROR(VLOOKUP(F21,[8]Sheet1!$AA$1:$AB$10,2),"") -> A
A22: 4 | B22: 24.05.52.0005 | C22: FLORA SUCI FERONIKA | D22: 70.5 | E22: 89 | F22: =IFERROR((D22*($D$17/100))+(E22*($E$17/100)),"") -> 79.75 | G22: =IFERROR(VLOOKUP(F22,[8]Sheet1!$AA$1:$AB$10,2),"") -> B+
A23: 5 | B23: 24.05.52.0006 | C23: AATHIRA AUFA AZ-ZAHRA | D23: 70.5 | E23: 89 | F23: =IFERROR((D23*($D$17/100))+(E23*($E$17/100)),"") -> 79.75 | G23: =IFERROR(VLOOKUP(F23,[8]Sheet1!$AA$1:$AB$10,2),"") -> B+
A24: 6 | B24: 24.05.52.0007 | C24: SHEILA MONA PUTRI IKSANTI | D24: 90.4 | E24: 97.5 | F24: =IFERROR((D24*($D$17/100))+(E24*($E$17/100)),"") -> 93.95 | G24: =IFERROR(VLOOKUP(F24,[8]Sheet1!$AA$1:$AB$10,2),"") -> A
A25: 7 | B25: 24.05.52.0008 | C25: RAIHAN RIFA MAHARADITYA | D25: 80.5 | E25: 82.6 | F25: =IFERROR((D25*($D$17/100))+(E25*($E$17/100)),"") -> 81.55 | G25: =IFERROR(VLOOKUP(F25,[8]Sheet1!$AA$1:$AB$10,2),"") -> B+
A26: 8 | B26: 24.05.52.0009 | C26: MARLINA DWI SAPUTRI | D26: 93.2 | E26: 91 | F26: =IFERROR((D26*($D$17/100))+(E26*($E$17/100)),"") -> 92.1 | G26: =IFERROR(VLOOKUP(F26,[8]Sheet1!$AA$1:$AB$10,2),"") -> A
A27: 9 | B27: 24.05.52.0011 | C27: JONATHAN REXY FERDINAN | D27: 91.4 | E27: 91 | F27: =IFERROR((D27*($D$17/100))+(E27*($E$17/100)),"") -> 91.2 | G27: =IFERROR(VLOOKUP(F27,[8]Sheet1!$AA$1:$AB$10,2),"") -> A
A28: 10 | B28: 24.05.52.0012 | C28: GITA TEONANDA ARELLIA | D28: 79.2 | E28: 82.6 | F28: =IFERROR((D28*($D$17/100))+(E28*($E$17/100)),"") -> 80.9 | G28: =IFERROR(VLOOKUP(F28,[8]Sheet1!$AA$1:$AB$10,2),"") -> B+
A29: 12 | B29: 24.05.52.0014 | C29: ARELIA SALSABILA SAFITRI | D29: 90.9 | E29: 95.9 | F29: =IFERROR((D29*($D$17/100))+(E29*($E$17/100)),"") -> 93.4 | G29: =IFERROR(VLOOKUP(F29,[8]Sheet1!$AA$1:$AB$10,2),"") -> A
A30: 13 | B30: 24.05.52.0015 | C30: JULLER IBEL LAURENTIUS TURNIP | D30: 67 | E30: 96 | F30: =IFERROR((D30*($D$17/100))+(E30*($E$17/100)),"") -> 81.5 | G30: =IFERROR(VLOOKUP(F30,[8]Sheet1!$AA$1:$AB$10,2),"") -> B+
A31: 14 | B31: 24.05.52.0016 | C31: GADING BINTANG WICAKSONO | D31: 93.2 | E31: 94.9 | F31: =IFERROR((D31*($D$17/100))+(E31*($E$17/100)),"") -> 94.05 | G31: =IFERROR(VLOOKUP(F31,[8]Sheet1!$AA$1:$AB$10,2),"") -> A
... A51: 34 | B51: 24.05.52.3012 | C51: RORO AYU SUKMAWATI | D51: 67.5 | E51: 64 | F51: =IFERROR((D51*($D$17/100))+(E51*($E$17/100)),"") -> 65.75 | G51: =IFERROR(VLOOKUP(F51,[8]Sheet1!$AA$1:$AB$10,2),"") -> B-
D53: =D16 -> CPMK122 | E53: =E16 -> CPMK123 | F53: =F12 -> Nilai Akhir MK 100
C54: Tidak KRS/Tidak Aktif | D54: =IFERROR(COUNTIF(D19:D51,""),"") -> 0 | E54: =IFERROR(COUNTIF(E19:E51,""),"") -> 0 | F54: =IFERROR(COUNTIF(F19:F51,""),"") -> 0
C55: <=65 | D55: =IFERROR(COUNTIF(D19:D51,C55)+COUNTIF(D19:D51,""),"")-D54 -> 0 | E55: =COUNTIF(E19:E51,C55)+COUNTIF(E19:E51,"")-E54 -> 1 | F55: =IFERROR(COUNTIF(F19:F51,C55)+COUNTIF(F19:F51,""),"") -> 0
C56: <85 | D56: =IFERROR(COUNTIF(D19:D51,C56)-D55,"") -> 11 | E56: =COUNTIF(E19:E51,C56)-E55 -> 6 | F56: =IFERROR(COUNTIF(F19:F51,C56)-F55,"") -> 12
C57: >=85 | D57: =COUNTIF(D19:D51,C57) -> 22 | E57: =COUNTIF(E19:E51,C57) -> 26 | F57: =IFERROR(COUNTIF(F19:F51,C57),"") -> 21
C58: Total | D58: =SUM(D54:D57) -> 33 | E58: =SUM(E54:E57) -> 33 | F58: =SUM(F54:F57) -> 33
C60: Jumlah mhsw yg lulus CPMK | D60: =(D56+D57)/(D58-D54) -> 1 | E60: =(E56+E57)/(E58-E54) -> 0.96969697 | F60: =(F56+F57)/(F58-F54) -> 1
C62: Minimal | D62: =MIN(D19:D51) -> 67 | E62: =MIN(E19:E51) -> 64 | F62: =IFERROR(MIN(F19:F51),"") -> 65.75
C63: Maksimal | D63: =MAX(D19:D51) -> 95.5 | E63: =MAX(E19:E51) -> 100 | F63: =IFERROR(MAX(F19:F51),"") -> 95.5
C64: Rata-Rata | D64: =AVERAGE(D19:D51) -> 85.648485 | E64: =AVERAGE(E19:E51) -> 90.278788 | F64: =IFERROR(AVERAGE(F19:F51),"") -> 87.963636

Sheet MK59-KWN
A1: FORM MONITORING DAN EVALUASI
A2: KETERCAPAIAN CAPAIAN PEMBELAJARAN MATAKULIAH(CPMK) PADA SATU ANGKATAN
A4: Tahun Akademik | C4: : 2024/2025 | E4: Program Studi | F4: : Sistem Informasi
A5: Kode Matakuliah | C5: : U.24.01.55.1.03 | E5: Fakultas | F5: : Teknologi Informasi dan Industri
A6: Nama Matakuliah | C6: : KEWARGANEGARAAN
A7: SKS Matakuliah | C7: : 2
A8: Semester/ Kelas | C8: : I / A1+DLC
A9: Dosen Pengampu | C9: : 1.YU.2.03.07.063 - R. SOELISTIJADI, S.SOS, M.Kom.
C10: : 2.
D12: MK59 | G12: =CONCATENATE("Nilai Akhir MK"," ",D17+E17+F17) -> Nilai Akhir MK 100 | H12: Nilai Huruf
D13: =TRIM(MID(C5,3,100)) -> U.24.01.55.1.03
D14: =TRIM(MID(C6,3,100)) -> KEWARGANEGARAAN
D15: CPL10 | E15: CPL12 | F15: CPL14
D16: CPMK101 | E16: CPMK122 | F16: CPMK141
D17: 25 | E17: 45 | F17: 30
A18: No | B18: NIM | C18: Nama Mahasiswa
A19: 1 | B19: 24.01.55.0002 | C19: NADIA SALSABILLA PUTRI
A20: 2 | B20: 24.01.55.0003 | C20: LISA RAHMAWATI | D20: 93.86 | E20: 88.75 | F20: 85 | G20: =IFERROR((D20*($D$17/100))+(E20*($E$17/100))+(F20*($F$17/100)),"") -> 88.9025 | H20: =IFERROR(VLOOKUP(G20,[9]Sheet1!$AA$1:$AB$10,2),"") -> A-
A21: 3 | B21: 24.01.55.0004 | C21: NAZWA FITRI AULIA | D21: 88.21 | E21: 55 | F21: 70 | G21: =IFERROR((D21*($D$17/100))+(E21*($E$17/100))+(F21*($F$17/100)),"") -> 67.8025 | H21: =IFERROR(VLOOKUP(G21,[9]Sheet1!$AA$1:$AB$10,2),"") -> B-
A22: 4 | B22: 24.01.55.0005 | C22: RAFFAEL ANGGARA ARYA DEWA | D22: 87.64 | E22: 69.25 | F22: 59 | G22: =IFERROR((D22*($D$17/100))+(E22*($E$17/100))+(F22*($F$17/100)),"") -> 70.7725 | H22: =IFERROR(VLOOKUP(G22,[9]Sheet1!$AA$1:$AB$10,2),"") -> B
A23: 5 | B23: 24.01.55.0006 | C23: YUMROTUL MUKAROMAH | D23: 91 | E23: 79 | F23: 72 | G23: =IFERROR((D23*($D$17/100))+(E23*($E$17/100))+(F23*($F$17/100)),"") -> 79.9 | H23: =IFERROR(VLOOKUP(G23,[9]Sheet1!$AA$1:$AB$10,2),"") -> B+
A24: 6 | B24: 24.01.55.0007 | C24: USWATUN AULIA PANGESTIKA | D24: 84.64 | E24: 85 | F24: 80 | G24: =IFERROR((D24*($D$17/100))+(E24*($E$17/100))+(F24*($F$17/100)),"") -> 83.41 | H24: =IFERROR(VLOOKUP(G24,[9]Sheet1!$AA$1:$AB$10,2),"") -> B+
A25: 7 | B25: 24.01.55.0008 | C25: VINCENT LISTANEOF SANTOSO | D25: 53.86 | E25: 12.5 | F25: 0 | G25: =IFERROR((D25*($D$17/100))+(E25*($E$17/100))+(F25*($F$17/100)),"") -> 19.09 | H25: =IFERROR(VLOOKUP(G25,[9]Sheet1!$AA$1:$AB$10,2),"") -> E
A26: 8 | B26: 24.01.55.0009 | C26: RETNO AJENG PUSPITASARI | D26: 67.07 | E26: 62.75 | F26: 67 | G26: =IFERROR((D26*($D$17/100))+(E26*($E$17/100))+(F26*($F$17/100)),"") -> 65.105 | H26: =IFERROR(VLOOKUP(G26,[9]Sheet1!$AA$1:$AB$10,2),"") -> C+
A27: 9 | B27: 24.01.55.0010 | C27: IQBAL FAHAR | D27: 85.5 | E27: 86.5 | F27: 82 | G27: =IFERROR((D27*($D$17/100))+(E27*($E$17/100))+(F27*($F$17/100)),"") -> 84.9 | H27: =IFERROR(VLOOKUP(G27,[9]Sheet1!$AA$1:$AB$10,2),"") -> A-
A28: 10 | B28: 24.01.55.0011 | C28: SHABRINA AULIA PUTRI | D28: 78.86 | E28: 86.25 | F28: 85 | G28: =IFERROR((D28*($D$17/100))+(E28*($E$17/100))+(F28*($F$17/100)),"") -> 84.0275 | H28: =IFERROR(VLOOKUP(G28,[9]Sheet1!$AA$1:$AB$10,2),"") -> B+
A29: 11 | B29: 24.01.55.0012 | C29: ADELA PUTRI AJI | D29: 82.64 | E29: 82.5 | F29: 80 | G29: =IFERROR((D29*($D$17/100))+(E29*($E$17/100))+(F29*($F$17/100)),"") -> 81.785 | H29: =IFERROR(VLOOKUP(G29,[9]Sheet1!$AA$1:$AB$10,2),"") -> B+
A30: 12 | B30: 24.01.55.0013 | C30: AMELIA RISKI KURNIAWATI | D30: 75.5 | E30: 79 | F30: 82 | G30: =IFERROR((D30*($D$17/100))+(E30*($E$17/100))+(F30*($F$17/100)),"") -> 79.025 | H30: =IFERROR(VLOOKUP(G30,[9]Sheet1!$AA$1:$AB$10,2),"") -> B+
A31: 13 | B31: 24.01.55.0014 | C31: DAFFA IQBAL MAULANA | D31: 89.93 | E31: 86.5 | F31: 82 | G31: =IFERROR((D31*($D$17/100))+(E31*($E$17/100))+(F31*($F$17/100)),"") -> 86.0075 | H31: =IFERROR(VLOOKUP(G31,[9]Sheet1!$AA$1:$AB$10,2),"") -> A-
... A37: 19 | B37: 24.01.55.3004 | C37: RISTRAWAN WIRAWINELDA | D37: 77.5 | E37: 70.5 | F37: 74 | G37: =IFERROR((D37*($D$17/100))+(E37*($E$17/100))+(F37*($F$17/100)),"") -> 73.3 | H37: =IFERROR(VLOOKUP(G37,[9]Sheet1!$AA$1:$AB$10,2),"") -> B
D39: =D16 -> CPMK101 | E39: =E16 -> CPMK122 | F39: =F16 -> CPMK141 | G39: =G12 -> Nilai Akhir MK 100
C40: Tidak KRS/Tidak Aktif | D40: =IFERROR(COUNTIF(D19:D37,""),"") -> 1 | E40: =IFERROR(COUNTIF(E19:E37,""),"") -> 1 | F40: =IFERROR(COUNTIF(F19:F37,""),"") -> 1 | G40: =IFERROR(COUNTIF(G19:G37,""),"") -> 1
C41: <=65 | D41: =IFERROR(COUNTIF(D19:D37,C41)+COUNTIF(D19:D37,""),"")-D40 -> 1 | E41: =COUNTIF(E19:E37,C41)+COUNTIF(E19:E37,"")-E40 -> 3 | F41: =COUNTIF(F19:F37,C41)+COUNTIF(F19:F37,"")-F40 -> 2 | G41: =IFERROR(COUNTIF(G19:G37,C41)+COUNTIF(G19:G37,""),"") -> 2
C42: <85 | D42: =IFERROR(COUNTIF(D19:D37,C42)-D41,"") -> 11 | E42: =COUNTIF(E19:E37,C42)-E41 -> 10 | F42: =COUNTIF(F19:F37,C42)-F41 -> 14 | G42: =IFERROR(COUNTIF(G19:G37,C42)-G41,"") -> 14
C43: >=85 | D43: =COUNTIF(D19:D37,C43) -> 6 | E43: =COUNTIF(E19:E37,C43) -> 5 | F43: =COUNTIF(F19:F37,C43) -> 2 | G43: =IFERROR(COUNTIF(G19:G37,C43),"") -> 2
C44: Total | D44: =SUM(D40:D43) -> 19 | E44: =SUM(E40:E43) -> 19 | F44: =SUM(F40:F43) -> 19 | G44: =SUM(G40:G43) -> 19
C46: Jumlah mhsw yg lulus CPMK | D46: =(D42+D43)/(D44-D40) -> 0.94444444 | E46: =(E42+E43)/(E44-E40) -> 0.83333333 | F46: =(F42+F43)/(F44-F40) -> 0.88888889 | G46: =(G42+G43)/(G44-G40) -> 0.88888889
C48: Minimal | D48: =MIN(D19:D37) -> 53.86 | E48: =MIN(E19:E37) -> 12.5 | F48: =MIN(F19:F37) -> 0 | G48: =IFERROR(MIN(G19:G37),"") -> 19.09
C49: Maksimal | D49: =MAX(D19:D37) -> 93.86 | E49: =MAX(E19:E37) -> 88.75 | F49: =MAX(F19:F37) -> 85 | G49: =IFERROR(MAX(G19:G37),"") -> 88.9025
C50: Rata-Rata | D50: =AVERAGE(D19:D37) -> 80.412778 | E50: =AVERAGE(E19:E37) -> 73.652778 | F50: =AVERAGE(F19:F37) -> 71.722222 | G50: =IFERROR(AVERAGE(G19:G37),"") -> 74.763611

Sheet Penguk.CPMK-Smt1
A1: Pengukuran CPMK di tingkat mata kuliah pada satu angkatan (2024)
A2: [Mata Kuliah Semester 3]
D4: ='ListMKSmt-1'!B2 -> MK16 | G4: Nilai Akhir Matakuliah | H4: ='ListMKSmt-1'!B3 -> MK17 | J4: Nilai Akhir Matakuliah | K4: ='ListMKSmt-1'!B4 -> MK18 | M4: Nilai Akhir Matakuliah | N4: ='ListMKSmt-1'!B5 -> MK19 | Q4: Nilai Akhir Matakuliah | R4: ='ListMKSmt-1'!B6 -> MK20 | T4: Nilai Akhir Matakuliah | U4: MK6 | W4: Nilai Akhir Matakuliah | X4: MK7 | Z4: Nilai Akhir Matakuliah | AB4: Nilai | AD4: Nilai | AF4: Nilai | AH4: Nilai | AJ4: Nilai | AL4: Nilai | AN4: Nilai | AP4: Nilai | AR4: Nilai | AT4: Nilai | AV4: Nilai | AX4: Nilai | AZ4: Nilai | BB4: Nilai
D5: ='ListMKSmt-1'!D2 -> P.24.05.52.3.11 | H5: ='ListMKSmt-1'!D3 -> P.24.05.52.3.12 | K5: ='ListMKSmt-1'!D4 -> P.24.05.52.3.13 | N5: ='ListMKSmt-1'!D5 -> P.24.05.52.3.14 | R5: ='ListMKSmt-1'!D6 -> P.24.05.52.3.15 | U5: ='ListMKSmt-1'!D7 -> P.24.05.52.3.16 | X5: ='ListMKSmt-1'!D8 -> U.24.05.52.3.06
D6: ='ListMKSmt-1'!E2 -> Akuntansi Keuangan Menengah 1 | H6: ='ListMKSmt-1'!E3 -> Statistika 1 | K6: ='ListMKSmt-1'!E4 -> Pengauditan 1 | N6: ='ListMKSmt-1'!E5 -> Akuntansi Pajak | R6: ='ListMKSmt-1'!E6 -> Akuntansi Manajemen | U6: ='ListMKSmt-1'!E7 -> Manajemen Keuangan | X6: ='ListMKSmt-1'!E8 -> Entrepreneurship for Start-up | AB6: D,G,J,T | AD6: U | AF6: N,Q | AH6: K | AR6: O,R | AT6: X,AB,AF | AX6: Y,AC,AG | AZ6: E,H, L,V | BB6: Z,AD,AH | BL6: D,E,F | BV6: N,Q | CB6: R,S,H,I | DD6: U,V | DX6: K | ED6: L | EH6: N | ER6: O,P | FB6: X,Y | FL6: E,H,L,V | FP6: Z,AD,AH
D7: ='MK1-TM'!D15 -> CPL02 | E7: ='MK1-TM'!E15 -> CPL02 | F7: ='MK1-TM'!F15 -> CPL02 | H7: ='MK2-TO'!D15 -> CPL04 | I7: ='MK2-TO'!E15 -> CPL04 | K7: ='MK3-PSTI'!D15 -> CPL08 | L7: ='MK3-PSTI'!E15 -> CPL09 | N7: ='MK4-L&A'!D15 -> CPL10 | O7: ='MK4-L&A'!E15 -> CPL11 | P7: ='MK4-L&A'!F15 -> CPL11 | R7: ='MK5-BP'!D15 -> CPL04 | S7: ='MK5-BP'!E15 -> CPL04 | U7: ='MK7-MBD'!D14 -> CPL06 | V7: ='MK7-MBD'!E14 -> CPL06 | X7: =MK8_BID!D15 -> CPL12 | Y7: =MK8_BID!E15 -> CPL12 | AB7: CPL01 | AC7: Capaian (%) | AD7: CPL02 | AE7: Capaian (%) | AF7: CPL03 | AG7: Capaian (%) | AH7: CPL04 | AI7: Capaian (%) | AJ7: CPL05 | AK7: Capaian (%) | AL7: CPL06 | AM7: Capaian (%) | AN7: CPL07 | AO7: Capaian (%) | AP7: CPL08 | AQ7: Capaian (%) | AR7: CPL09 | AS7: Capaian (%) | AT7: CPL10 | AU7: Capaian (%) | AV7: CPL11 | AW7: Capaian (%) | AX7: CPL12 | AY7: Capaian (%) | AZ7: CPL13 | BA7: Capaian (%) | BB7: CPL14 | BC7: Capaian (%) | BF7: CPL01 | BL7: CPL02 | BV7: CPL03 | CB7: CPL04 | CN7: CPL05 | DD7: CPL06 | DL7: CPL07 | DX7: CPL08 | ED7: CPL09 | EH7: CPL10 | ER7: CPL11 | FB7: CPL12 | FL7: CPL13 | FP7: CPL14
D8: ='MK1-TM'!D16 -> CPMK022 | E8: ='MK1-TM'!E16 -> CPMK024 | F8: ='MK1-TM'!F16 -> CPMK025 | H8: ='MK2-TO'!D16 -> CPMK44 | I8: ='MK2-TO'!E16 -> CPMK46 | K8: ='MK3-PSTI'!D16 -> CPMK81 | L8: ='MK3-PSTI'!E16 -> CPMK91 | N8: ='MK4-L&A'!D16 -> CPMK104 | O8: ='MK4-L&A'!E16 -> CPMK111 | P8: ='MK4-L&A'!F16 -> CPMK112 | R8: ='MK5-BP'!D16 -> CPMK41 | S8: ='MK5-BP'!E16 -> CPMK42 | U8: ='MK7-MBD'!D15 -> CPMK61 | V8: ='MK7-MBD'!E15 -> CPMK62 | X8: =MK8_BID!D16 -> CPMK121 | Y8: =MK8_BID!E16 -> CPMK122 | AA8: SMT-III | AB8: 215 | AD8: =#REF! -> #REF! | AF8: =N9+R9 -> 87 | AH8: =#REF! -> #REF! | AR8: =P9+S9 -> 80 | AT8: =X9+#REF!+#REF! -> #REF! | AX8: =#REF!+#REF!+#REF! -> #REF! | AZ8: =F9+I9+L9+V9 -> 185 | BB8: =#REF!+#REF!+#REF! -> #REF! | BF8: CPMK011 | BG8: % | BH8: CPMK012 | BI8: % | BJ8: CPMK013 | BK8: % | BL8: CPMK021 | BM8: % | BN8: CPMK022 | BO8: % | BP8: CPMK023 | BQ8: % | BR8: CPMK024 | BS8: % | BT8: CPMK025 | BV8: CPMK031 | BW8: % | BX8: CPMK032 | BY8: % | BZ8: CPMK033 | CA8: % | CB8: CPMK041 | CC8: % | CD8: CPMK042 | CE8: % | CF8: CPMK043 | CH8: CPMK044 | CJ8: CPMK045 | CL8: CPMK046 | CM8: % | CN8: CPMK051 | CO8: % | CP8: CPMK052 | CQ8: % | CR8: CPMK053 | CS8: % | CT8: CPMK054 | CU8: % | CV8: CPMK055 | CW8: % | CX8: CPMK056 | CY8: % | CZ8: CPMK057 | DA8: % | DB8: CPMK058 | DC8: % | DD8: CPMK061 | DE8: % | DF8: CPMK062 | DG8: % | DH8: CPMK063 | DI8: % | DJ8: CPMK064 | DK8: % | DL8: CPMK071 | DM8: % | DN8: CPMK072 | DO8: % | DP8: CPMK073 | DQ8: % | DR8: CPMK074 | DS8: % | DT8: CPMK075 | DU8: % | DV8: CPMK076 | DW8: % | DX8: CPMK081 | DY8: % | DZ8: CPMK082 | EA8: % | EB8: CPMK083 | EC8: % | ED8: CPMK091 | EE8: % | EF8: CPMK092 | EG8: % | EH8: CPMK101 | EI8: % | EJ8: CPMK102 | EK8: % | EL8: CPMK103 | EM8: % | EN8: CPMK104 | EO8: % | EP8: CPMK105 | EQ8: % | ER8: CPMK111 | ES8: % | ET8: CPMK112 | EU8: % | EV8: CPMK113 | EW8: % | EX8: CPMK114 | EY8: % | EZ8: CPMK115 | FA8: % | FB8: CPMK121 | FC8: % | FD8: CPMK122 | FE8: % | FF8: CPMK123 | FG8: % | FH8: CPMK124 | FI8: % | FJ8: CPMK125 | FK8: % | FL8: CPMK131 | FM8: % | FN8: CPMK132 | FO8: % | FP8: CPMK141 | FQ8: % | FR8: CPMK142 | FS8: %
C9: =SUM(D9,F9,H9,I9,K9,#REF!,L9,N9,P9,R9,S9,U9,#REF!,V9,X9,#REF!,#REF!,#REF!,#REF!,#REF!,#REF!,#REF!,#REF!) -> #REF! | D9: ='MK1-TM'!D17 -> 23 | E9: ='MK1-TM'!E17 -> 42 | F9: ='MK1-TM'!F17 -> 35 | H9: ='MK2-TO'!D17 -> 50 | I9: ='MK2-TO'!E17 -> 50 | K9: ='MK3-PSTI'!D17 -> 50 | L9: ='MK3-PSTI'!E17 -> 50 | N9: ='MK4-L&A'!D17 -> 37 | O9: ='MK4-L&A'!E17 -> 33 | P9: ='MK4-L&A'!F17 -> 30 | R9: ='MK5-BP'!D17 -> 50 | S9: ='MK5-BP'!E17 -> 50 | U9: ='MK7-MBD'!D16 -> 50 | V9: ='MK7-MBD'!E16 -> 50 | X9: =MK8_BID!D17 -> 50 | Y9: ='MK7-MBD'!E16 -> 50 | BN9: =D9 -> 23 | BR9: =E9 -> 42 | BT9: =F9 -> 35 | CB9: =R9 -> 50 | CD9: =K9 -> 50 | CH9: =H9 -> 50 | CL9: =I9 -> 50 | CV9: =N9 -> 37 | CX9: 50 | DD9: =U9 -> 50 | DF9: =V9 -> 50 | DX9: =K9 -> 50 | ED9: =L9 -> 50 | EN9: =N9 -> 37 | ER9: =O9 -> 33 | ET9: =P9 -> 30 | EX9: =R9 -> 50 | EZ9: =S9 -> 50 | FB9: =X9 -> 50 | FD9: =Y9 -> 50 | FL9: =F9+I9+L9+V9 -> 185 | FP9: =#REF!+#REF! -> #REF! | FR9: =#REF! -> #REF! | FT9: =SUM(BF9:FR9) -> #REF!
A10: No | B10: NIM | C10: Nama Mahasiswa
